Workbook

Sheet 新幕シーズン10-2
A1: カードID | B1: メガミ | C1: アナザーID | D1: 置換元カード | E1: 名前 | F1: ふりがな | G1: 名前（中国語） | H1: 名前（中国語G1） | I1: ふりがな（中国語） | J1: 名前（韓国語） | K1: 名前（英語） | L1: ふりがな（英語） | M1: 種別 | N1: 追加札 | O1: 追加元カード | P1: 交換先 | Q1: 毒 | R1: タイプ | S1: サブタイプ | T1: 適正距離 | U1: （開） | V1: ダメージ | W1: （開） | X1: 納 | Y1: 生育 | Z1: 消費 | AA1: 偽証 | AB1: 封印 | AC1: 取り除く | AD1: 投資券 | AE1: テキスト | AF1: テキスト補足 | AG1: テキスト（中国語） | AH1: テキスト補足（中国語） | AI1: テキスト（中国語G1） | AJ1: テキスト補足（中国語G1） | AK1: テキスト（韓国語） | AL1: テキスト補足（韓国語） | AM1: テキスト（英語） | AN1: テキスト補足（英語） | AO1: （開） | AP1: （開）（中国語） | AQ1: （開）（中国語G1） | AR1: （開）（韓国語） | AS1: （開）（英語）
A2: 17-hatsumi-o-s-1 | B2: hatsumi | E2: イサナ海域 | F2: いさなかいいき | G2: 鲸鱼海域 | H2: 鲸鱼海域 | J2: 이사나 해역 | K2: Cetacean Ocean | M2: 切札 | R2: 攻撃 | T2: 3-5 | V2: 2/1 | Z2: 3 | AE2: 【常時】順風ならば、この《攻撃》は+1/+2となる。 【攻撃後】逆風ならば、 ダスト→間合：2 を行い、このカードを未使用に戻す。 | AG2: 【常时】若顺风，此《攻击》得+1/+2。 【攻击后】若逆风，则：虚→2→距。 然后将此牌变为未使用的状态。 | AK2: 【상시】순풍이라면, 이 《공격》은 +1/+2된다. 【공격시】역풍이라면, 더스트→간격：2 을 하고, 이 카드를 미사용으로 되돌린다. | AM2: Forced: If there is a tailwind, this attack gains +1/+2. After Attack: If there is a headwind, Shadow (2)→ Distance, then turn this card face-down. | AT2: =IF(A2="", "","'"&A2&"': {megami: '"&B2&"'"&IF(C2<>"",", anotherID: '"&C2&"', replace: '"&D2&"'","")&", name: '"&SUBSTITUTE(E2,"'","\'")&"', nameEn: '"&SUBSTITUTE(K2,"'","\'")&"', nameZh: '"&SUBSTITUTE(G2,"'","\'")&"', nameZhG1: '"&SUBSTITUTE(H2,"'","\'")&"', nameKo: '"&SUBSTITUTE(J2,"'","\'")&"', ruby: '"&F2&"', rubyEn: '"&L2&IF(I2<>"", "', rubyZh: '"&I2, "")&"', baseType: '"&VLOOKUP(M2,マスタ!$A$1:$B$99,2,0)&"'"&IF(N2="○",", extra: true","")&IF(O2<>"",", extraFrom: '"&O2&"'","")&IF(P2<>"",", exchangableTo: '"&P2&"'","")&IF(Q2="○",", poison: true","")&IF(R2<>"", ", type: '"&VLOOKUP(R2,マスタ!$D$1:$E$99,2,0)&"'", "")&IF(S2<>"",", subType: '"&VLOOKUP(S2,マスタ!$D$1:$E$99,2,0)&"'","")&""&IF(T2<>"",", range: '"&T2&"'","")&IF(V2<>"",", damage: '"&V2&"'","")&IF(X2<>"",", capacity: '"&X2&"'","")&IF(Y2<>"",", growth: "&Y2&"","")&IF(Z2<>"",", cost: '"&Z2&"'","")&", text: '"&SUBSTITUTE(SUBSTITUTE(AE2, CHAR(13), ""),CHAR(10),"\n")&IF(AF2<>"", "', textAdditional: '"&SUBSTITUTE(SUBSTITUTE(AF2, CHAR(13), ""),CHAR(10),"\n"), "")&"', textZh: '"&SUBSTITUTE(SUBSTITUTE(SUBSTITUTE(AG2, CHAR(13), ""),CHAR(10),"\n"),"'","\'")&"', textZhG1: '"&SUBSTITUTE(SUBSTITUTE(SUBSTITUTE(AI2, CHAR(13), ""),CHAR(10),"\n"),"'","\'")&IF(AH2<>"", "', textZhAdditional: '"&SUBSTITUTE(SUBSTITUTE(AH2, CHAR(13), ""),CHAR(10),"\n"), "")&IF(AJ2<>"", "', textZhG1Additional: '"&SUBSTITUTE(SUBSTITUTE(AJ2, CHAR(13), ""),CHAR(10),"\n"), "")&"', textKo: '"&SUBSTITUTE(SUBSTITUTE(SUBSTITUTE(AK2, CHAR(13), ""),CHAR(10),"\n"),"'","\'")&IF(AL2<>"", "', textKoAdditional: '"&SUBSTITUTE(SUBSTITUTE(AL2, CHAR(13), ""),CHAR(10),"\n"), "")&"', textEn: '"&SUBSTITUTE(SUBSTITUTE(SUBSTITUTE(AM2, CHAR(13), ""),CHAR(10),"\n"),"'","\'")&IF(AN2<>"", "', textEnAdditional: '"&SUBSTITUTE(SUBSTITUTE(AN2, CHAR(13), ""),CHAR(10),"\n"), "")&"'"&IF(AB2="○",", sealable: true","")&IF(AC2="○",", removable: true","")&IF(AA2="○",", lie: true","")&IF(AD2="○",", investable: true","")&"},") -> '17-hatsumi-o-s-1': {megami: 'hatsumi', name: 'イサナ海域', nameEn: 'Cetacean Ocean', nameZh: '鲸鱼海域', nameZhG1: '鲸鱼海域', nameKo: '이사나 해역', ruby: 'いさなかいいき', rubyEn: '', baseType: 'special', type: 'attack', range: '3-5', damage: '2/1', cost: '3', text: '【常時】順風ならば、この《攻撃》は+1/+2となる。\n【攻撃後】逆風ならば、\nダスト→間合：2\nを行い、このカードを未使用に戻す。', textZh: '【常时】若顺风，此《攻击》得+1/+2。\n【攻击后】若逆风，则：虚→2→距。\n然后将此牌变为未使用的状态。', textZhG1: '', textKo: '【상시】순풍이라면, 이 《공격》은 +1/+2된다.\n【공격시】역풍이라면,\n더스트→간격：2\n을 하고, 이 카드를 미사용으로 되돌린다.', textEn: 'Forced: If there is a tailwind, this attack gains +1/+2.\n\nAfter Attack: If there is a headwind, Shadow (2)→ Distance, then turn this card face-down.'}, | AU2: =IF($A2<>"", " /** 《"&$E2&"》 */ export const "&SUBSTITUTE(UPPER(IF(MID($A2, 3, 1)="-", RIGHT($A2,LEN($A2)-3), $A2)), "-", "_")&": TCardId = '"&$A2&"';", "") -> /** 《イサナ海域》 */ export const HATSUMI_O_S_1: TCardId = '17-hatsumi-o-s-1'; | AV2: =IF($A2<>"", " | '"&$A2&"'", "") -> | '17-hatsumi-o-s-1'
A3: 20-kanawe-o-n-2 | B3: kanawe | E3: 脚本化 | F3: きゃくほんか | G3: 剧本化 | H3: 脚本化 | J3: 각본화 | K3: Composition | M3: 通常札 | R3: 攻撃 | T3: 3-5 | V3: 1/1 | AE3: 【攻撃後】追加札から構想カードを1枚準備してもよい。 【常時】あなたの終了フェイズにこのカードを捨て札から山札の底に置いてもよい。そうした場合、相手は集中力を1得る。 | AG3: 【攻击后】你可以从追加牌区的构想牌中准备1张构想。 【常时】在你的结束阶段你可以将此牌从弃牌放到牌库底。若如此做，对手获得1集中力。 | AK3: 【공격후】추가패에서 구상 카드를 1장 준비해도 좋다. 【상시】당신의 종료 페이즈에 이 카드가 버림패에 있다면 패산의 아래에 두어도 좋다. 그렇게 했다면, 상대는 집중력 1을 얻는다. | AM3: After Attack: You may prepare one of your set aside Plot cards. Forced: At the end of your turn, you may move this card from your played pile to the bottom of your deck. If you do, your opponent gains 1 Vigor. | AT3: =IF(A3="", "","'"&A3&"': {megami: '"&B3&"'"&IF(C3<>"",", anotherID: '"&C3&"', replace: '"&D3&"'","")&", name: '"&SUBSTITUTE(E3,"'","\'")&"', nameEn: '"&SUBSTITUTE(K3,"'","\'")&"', nameZh: '"&SUBSTITUTE(G3,"'","\'")&"', nameZhG1: '"&SUBSTITUTE(H3,"'","\'")&"', nameKo: '"&SUBSTITUTE(J3,"'","\'")&"', ruby: '"&F3&"', rubyEn: '"&L3&IF(I3<>"", "', rubyZh: '"&I3, "")&"', baseType: '"&VLOOKUP(M3,マスタ!$A$1:$B$99,2,0)&"'"&IF(N3="○",", extra: true","")&IF(O3<>"",", extraFrom: '"&O3&"'","")&IF(P3<>"",", exchangableTo: '"&P3&"'","")&IF(Q3="○",", poison: true","")&IF(R3<>"", ", type: '"&VLOOKUP(R3,マスタ!$D$1:$E$99,2,0)&"'", "")&IF(S3<>"",", subType: '"&VLOOKUP(S3,マスタ!$D$1:$E$99,2,0)&"'","")&""&IF(T3<>"",", range: '"&T3&"'","")&IF(V3<>"",", damage: '"&V3&"'","")&IF(X3<>"",", capacity: '"&X3&"'","")&IF(Y3<>"",", growth: "&Y3&"","")&IF(Z3<>"",", cost: '"&Z3&"'","")&", text: '"&SUBSTITUTE(SUBSTITUTE(AE3, CHAR(13), ""),CHAR(10),"\n")&IF(AF3<>"", "', textAdditional: '"&SUBSTITUTE(SUBSTITUTE(AF3, CHAR(13), ""),CHAR(10),"\n"), "")&"', textZh: '"&SUBSTITUTE(SUBSTITUTE(SUBSTITUTE(AG3, CHAR(13), ""),CHAR(10),"\n"),"'","\'")&"', textZhG1: '"&SUBSTITUTE(SUBSTITUTE(SUBSTITUTE(AI3, CHAR(13), ""),CHAR(10),"\n"),"'","\'")&IF(AH3<>"", "', textZhAdditional: '"&SUBSTITUTE(SUBSTITUTE(AH3, CHAR(13), ""),CHAR(10),"\n"), "")&IF(AJ3<>"", "', textZhG1Additional: '"&SUBSTITUTE(SUBSTITUTE(AJ3, CHAR(13), ""),CHAR(10),"\n"), "")&"', textKo: '"&SUBSTITUTE(SUBSTITUTE(SUBSTITUTE(AK3, CHAR(13), ""),CHAR(10),"\n"),"'","\'")&IF(AL3<>"", "', textKoAdditional: '"&SUBSTITUTE(SUBSTITUTE(AL3, CHAR(13), ""),CHAR(10),"\n"), "")&"', textEn: '"&SUBSTITUTE(SUBSTITUTE(SUBSTITUTE(AM3, CHAR(13), ""),CHAR(10),"\n"),"'","\'")&IF(AN3<>"", "', textEnAdditional: '"&SUBSTITUTE(SUBSTITUTE(AN3, CHAR(13), ""),CHAR(10),"\n"), "")&"'"&IF(AB3="○",", sealable: true","")&IF(AC3="○",", removable: true","")&IF(AA3="○",", lie: true","")&IF(AD3="○",", investable: true","")&"},") -> '20-kanawe-o-n-2': {megami: 'kanawe', name: '脚本化', nameEn: 'Composition', nameZh: '剧本化', nameZhG1: '脚本化', nameKo: '각본화', ruby: 'きゃくほんか', rubyEn: '', baseType: 'normal', type: 'attack', range: '3-5', damage: '1/1', text: '【攻撃後】追加札から構想カードを1枚準備してもよい。\n【常時】あなたの終了フェイズにこのカードを捨て札から山札の底に置いてもよい。そうした場合、相手は集中力を1得る。', textZh: '【攻击后】你可以从追加牌区的构想牌中准备1张构想。 \n【常时】在你的结束阶段你可以将此牌从弃牌放到牌库底。若如此做，对手获得1集中力。', textZhG1: '', textKo: '【공격후】추가패에서 구상 카드를 1장 준비해도 좋다.\n【상시】당신의 종료 페이즈에 이 카드가 버림패에 있다면 패산의 아래에 두어도 좋다. 그렇게 했다면, 상대는 집중력 1을 얻는다.', textEn: 'After Attack: You may prepare one of your set aside Plot cards.\n\nForced: At the end of your turn, you may move this card from your played pile to the bottom of your deck. If you do, your opponent gains 1 Vigor.'}, | AU3: =IF($A3<>"", " /** 《"&$E3&"》 */ export const "&SUBSTITUTE(UPPER(IF(MID($A3, 3, 1)="-", RIGHT($A3,LEN($A3)-3), $A3)), "-", "_")&": TCardId = '"&$A3&"';", "") -> /** 《脚本化》 */ export const KANAWE_O_N_2: TCardId = '20-kanawe-o-n-2'; | AV3: =IF($A3<>"", " | '"&$A3&"'", "") -> | '20-kanawe-o-n-2'
A4: 21-kamuwi-o-s-1 | B4: kamuwi | E4: 灯 | F4: ともしび | G4: 灯 | H4: 灯 | J4: 등불 | K4: Kindle | M4: 切札 | R4: 行動 | Z4: 5 | AE4: (+4) あなたのフレアにある桜花結晶全てをダストに送る。追加札から「暁」を未使用で得る。 | AG4: (+3) 将自气的樱花结晶全部移至虚，并给予自命1点伤害。 从追加牌区以未使用的状态获得『晓』。 | AK4: (+4) 당신의 플레어에 있는 벚꽃결정을 전부 더스트로 보낸다. 추가패에서 「새벽」을 미사용 상태로 얻는다. | AM4: (+3): Move all Sakura tokens on your Flare to Shadow. Deal 1 damage to your Life. Add your set aside "Daybreak" to your Special cards, face-down. ---------- | AT4: =IF(A4="", "","'"&A4&"': {megami: '"&B4&"'"&IF(C4<>"",", anotherID: '"&C4&"', replace: '"&D4&"'","")&", name: '"&SUBSTITUTE(E4,"'","\'")&"', nameEn: '"&SUBSTITUTE(K4,"'","\'")&"', nameZh: '"&SUBSTITUTE(G4,"'","\'")&"', nameZhG1: '"&SUBSTITUTE(H4,"'","\'")&"', nameKo: '"&SUBSTITUTE(J4,"'","\'")&"', ruby: '"&F4&"', rubyEn: '"&L4&IF(I4<>"", "', rubyZh: '"&I4, "")&"', baseType: '"&VLOOKUP(M4,マスタ!$A$1:$B$99,2,0)&"'"&IF(N4="○",", extra: true","")&IF(O4<>"",", extraFrom: '"&O4&"'","")&IF(P4<>"",", exchangableTo: '"&P4&"'","")&IF(Q4="○",", poison: true","")&IF(R4<>"", ", type: '"&VLOOKUP(R4,マスタ!$D$1:$E$99,2,0)&"'", "")&IF(S4<>"",", subType: '"&VLOOKUP(S4,マスタ!$D$1:$E$99,2,0)&"'","")&""&IF(T4<>"",", range: '"&T4&"'","")&IF(V4<>"",", damage: '"&V4&"'","")&IF(X4<>"",", capacity: '"&X4&"'","")&IF(Y4<>"",", growth: "&Y4&"","")&IF(Z4<>"",", cost: '"&Z4&"'","")&", text: '"&SUBSTITUTE(SUBSTITUTE(AE4, CHAR(13), ""),CHAR(10),"\n")&IF(AF4<>"", "', textAdditional: '"&SUBSTITUTE(SUBSTITUTE(AF4, CHAR(13), ""),CHAR(10),"\n"), "")&"', textZh: '"&SUBSTITUTE(SUBSTITUTE(SUBSTITUTE(AG4, CHAR(13), ""),CHAR(10),"\n"),"'","\'")&"', textZhG1: '"&SUBSTITUTE(SUBSTITUTE(SUBSTITUTE(AI4, CHAR(13), ""),CHAR(10),"\n"),"'","\'")&IF(AH4<>"", "', textZhAdditional: '"&SUBSTITUTE(SUBSTITUTE(AH4, CHAR(13), ""),CHAR(10),"\n"), "")&IF(AJ4<>"", "', textZhG1Additional: '"&SUBSTITUTE(SUBSTITUTE(AJ4, CHAR(13), ""),CHAR(10),"\n"), "")&"', textKo: '"&SUBSTITUTE(SUBSTITUTE(SUBSTITUTE(AK4, CHAR(13), ""),CHAR(10),"\n"),"'","\'")&IF(AL4<>"", "', textKoAdditional: '"&SUBSTITUTE(SUBSTITUTE(AL4, CHAR(13), ""),CHAR(10),"\n"), "")&"', textEn: '"&SUBSTITUTE(SUBSTITUTE(SUBSTITUTE(AM4, CHAR(13), ""),CHAR(10),"\n"),"'","\'")&IF(AN4<>"", "', textEnAdditional: '"&SUBSTITUTE(SUBSTITUTE(AN4, CHAR(13), ""),CHAR(10),"\n"), "")&"'"&IF(AB4="○",", sealable: true","")&IF(AC4="○",", removable: true","")&IF(AA4="○",", lie: true","")&IF(AD4="○",", investable: true","")&"},") -> '21-kamuwi-o-s-1': {megami: 'kamuwi', name: '灯', nameEn: 'Kindle', nameZh: '灯', nameZhG1: '灯', nameKo: '등불', ruby: 'ともしび', rubyEn: '', baseType: 'special', type: 'action', cost: '5', text: '(+4) あなたのフレアにある桜花結晶全てをダストに送る。追加札から「暁」を未使用で得る。', textZh: '(+3) 将自气的樱花结晶全部移至虚，并给予自命1点伤害。 \n从追加牌区以未使用的状态获得『晓』。', textZhG1: '', textKo: '(+4) 당신의 플레어에 있는 벚꽃결정을 전부 더스트로 보낸다. 추가패에서 「새벽」을 미사용 상태로 얻는다.', textEn: '(+3): Move all Sakura tokens on your Flare to Shadow. Deal 1 damage to your Life.\n\nAdd your set aside "Daybreak" to your Special cards, face-down.\n\n----------'}, | AU4: =IF($A4<>"", " /** 《"&$E4&"》 */ export const "&SUBSTITUTE(UPPER(IF(MID($A4, 3, 1)="-", RIGHT($A4,LEN($A4)-3), $A4)), "-", "_")&": TCardId = '"&$A4&"';", "") -> /** 《灯》 */ export const KAMUWI_O_S_1: TCardId = '21-kamuwi-o-s-1'; | AV4: =IF($A4<>"", " | '"&$A4&"'", "") -> | '21-kamuwi-o-s-1'
A5: 23-akina-o-n-2 | B5: akina | E5: 恫喝 | F5: どうかつ | G5: 恫吓 | H5: 恫吓 | J5: 공갈 | K5: Browbeat | M5: 通常札 | R5: 攻撃 | T5: 4 | V5: -/0 | AD5: ○ | AE5: 投資券 【常時】あなたの資本が相手の資本より大きいならば、この《攻撃》は+0/+1となる。 【攻撃後】あなたの資本が相手の資本以下ならば、このカードを伏せ札にする。 | AG5: 投资券 【常时】你的资本比对手的资本更多的话，此攻击得+0/+1。 【攻击后】你的资本不比对手的资本多的话，盖伏此卡。 | AK5: 투자권 【상시】 당신의 자본이 상대의 자본보다 크다면, 이 《공격》은 +0/+1 된다. 【공격후】당신의 자본이 상대의 자본 이하라면, 이 카드를 덮음패로 만든다. | AT5: =IF(A5="", "","'"&A5&"': {megami: '"&B5&"'"&IF(C5<>"",", anotherID: '"&C5&"', replace: '"&D5&"'","")&", name: '"&SUBSTITUTE(E5,"'","\'")&"', nameEn: '"&SUBSTITUTE(K5,"'","\'")&"', nameZh: '"&SUBSTITUTE(G5,"'","\'")&"', nameZhG1: '"&SUBSTITUTE(H5,"'","\'")&"', nameKo: '"&SUBSTITUTE(J5,"'","\'")&"', ruby: '"&F5&"', rubyEn: '"&L5&IF(I5<>"", "', rubyZh: '"&I5, "")&"', baseType: '"&VLOOKUP(M5,マスタ!$A$1:$B$99,2,0)&"'"&IF(N5="○",", extra: true","")&IF(O5<>"",", extraFrom: '"&O5&"'","")&IF(P5<>"",", exchangableTo: '"&P5&"'","")&IF(Q5="○",", poison: true","")&IF(R5<>"", ", type: '"&VLOOKUP(R5,マスタ!$D$1:$E$99,2,0)&"'", "")&IF(S5<>"",", subType: '"&VLOOKUP(S5,マスタ!$D$1:$E$99,2,0)&"'","")&""&IF(T5<>"",", range: '"&T5&"'","")&IF(V5<>"",", damage: '"&V5&"'","")&IF(X5<>"",", capacity: '"&X5&"'","")&IF(Y5<>"",", growth: "&Y5&"","")&IF(Z5<>"",", cost: '"&Z5&"'","")&", text: '"&SUBSTITUTE(SUBSTITUTE(AE5, CHAR(13), ""),CHAR(10),"\n")&IF(AF5<>"", "', textAdditional: '"&SUBSTITUTE(SUBSTITUTE(AF5, CHAR(13), ""),CHAR(10),"\n"), "")&"', textZh: '"&SUBSTITUTE(SUBSTITUTE(SUBSTITUTE(AG5, CHAR(13), ""),CHAR(10),"\n"),"'","\'")&"', textZhG1: '"&SUBSTITUTE(SUBSTITUTE(SUBSTITUTE(AI5, CHAR(13), ""),CHAR(10),"\n"),"'","\'")&IF(AH5<>"", "', textZhAdditional: '"&SUBSTITUTE(SUBSTITUTE(AH5, CHAR(13), ""),CHAR(10),"\n"), "")&IF(AJ5<>"", "', textZhG1Additional: '"&SUBSTITUTE(SUBSTITUTE(AJ5, CHAR(13), ""),CHAR(10),"\n"), "")&"', textKo: '"&SUBSTITUTE(SUBSTITUTE(SUBSTITUTE(AK5, CHAR(13), ""),CHAR(10),"\n"),"'","\'")&IF(AL5<>"", "', textKoAdditional: '"&SUBSTITUTE(SUBSTITUTE(AL5, CHAR(13), ""),CHAR(10),"\n"), "")&"', textEn: '"&SUBSTITUTE(SUBSTITUTE(SUBSTITUTE(AM5, CHAR(13), ""),CHAR(10),"\n"),"'","\'")&IF(AN5<>"", "', textEnAdditional: '"&SUBSTITUTE(SUBSTITUTE(AN5, CHAR(13), ""),CHAR(10),"\n"), "")&"'"&IF(AB5="○",", sealable: true","")&IF(AC5="○",", removable: true","")&IF(AA5="○",", lie: true","")&IF(AD5="○",", investable: true","")&"},") -> '23-akina-o-n-2': {megami: 'akina', name: '恫喝', nameEn: 'Browbeat', nameZh: '恫吓', nameZhG1: '恫吓', nameKo: '공갈', ruby: 'どうかつ', rubyEn: '', baseType: 'normal', type: 'attack', range: '4', damage: '-/0', text: '投資券\n【常時】あなたの資本が相手の資本より大きいならば、この《攻撃》は+0/+1となる。\n【攻撃後】あなたの資本が相手の資本以下ならば、このカードを伏せ札にする。', textZh: '投资券\n【常时】你的资本比对手的资本更多的话，此攻击得+0/+1。\n【攻击后】你的资本不比对手的资本多的话，盖伏此卡。', textZhG1: '', textKo: '투자권\n【상시】 당신의 자본이 상대의 자본보다 크다면, 이 《공격》은 +0/+1 된다.\n【공격후】당신의 자본이 상대의 자본 이하라면, 이 카드를 덮음패로 만든다.', textEn: '', investable: true}, | AU5: =IF($A5<>"", " /** 《"&$E5&"》 */ export const "&SUBSTITUTE(UPPER(IF(MID($A5, 3, 1)="-", RIGHT($A5,LEN($A5)-3), $A5)), "-", "_")&": TCardId = '"&$A5&"';", "") -> /** 《恫喝》 */ export const AKINA_O_N_2: TCardId = '23-akina-o-n-2'; | AV5: =IF($A5<>"", " | '"&$A5&"'", "") -> | '23-akina-o-n-2'
A6: 26-innealra-o3-n-6 | B6: innealra | C6: O3 | D6: 26-innealra-o-n-6 | E6: 儚き意志 | F6: はかなきいし | G6: 缥缈意志 | J6: 덧없는 의지 | M6: 通常札 | R6: 付与 | X6: 2 | AE6: 【展開時/破棄時】過去の運命をまだ見ぬ運命へと動かしてもよい。 【常時】この付与札の上の桜花結晶がダストへと送られるならば、代わりにロストへと移動する。 | AG6: 【展开时】可以将过去的命运移去未知的命运。 【展开中】达人距离的数值减少1。 | AK6: 【전개시/파기시】과거의 운명을 아직 보지 않은 운명으로 이동시켜도 된다. 【상시】이 부여패 위의 벚꽃결정이 더스트로 보내진다면, 대신 로스트로 이동한다. | AT6: =IF(A6="", "","'"&A6&"': {megami: '"&B6&"'"&IF(C6<>"",", anotherID: '"&C6&"', replace: '"&D6&"'","")&", name: '"&SUBSTITUTE(E6,"'","\'")&"', nameEn: '"&SUBSTITUTE(K6,"'","\'")&"', nameZh: '"&SUBSTITUTE(G6,"'","\'")&"', nameZhG1: '"&SUBSTITUTE(H6,"'","\'")&"', nameKo: '"&SUBSTITUTE(J6,"'","\'")&"', ruby: '"&F6&"', rubyEn: '"&L6&IF(I6<>"", "', rubyZh: '"&I6, "")&"', baseType: '"&VLOOKUP(M6,マスタ!$A$1:$B$99,2,0)&"'"&IF(N6="○",", extra: true","")&IF(O6<>"",", extraFrom: '"&O6&"'","")&IF(P6<>"",", exchangableTo: '"&P6&"'","")&IF(Q6="○",", poison: true","")&IF(R6<>"", ", type: '"&VLOOKUP(R6,マスタ!$D$1:$E$99,2,0)&"'", "")&IF(S6<>"",", subType: '"&VLOOKUP(S6,マスタ!$D$1:$E$99,2,0)&"'","")&""&IF(T6<>"",", range: '"&T6&"'","")&IF(V6<>"",", damage: '"&V6&"'","")&IF(X6<>"",", capacity: '"&X6&"'","")&IF(Y6<>"",", growth: "&Y6&"","")&IF(Z6<>"",", cost: '"&Z6&"'","")&", text: '"&SUBSTITUTE(SUBSTITUTE(AE6, CHAR(13), ""),CHAR(10),"\n")&IF(AF6<>"", "', textAdditional: '"&SUBSTITUTE(SUBSTITUTE(AF6, CHAR(13), ""),CHAR(10),"\n"), "")&"', textZh: '"&SUBSTITUTE(SUBSTITUTE(SUBSTITUTE(AG6, CHAR(13), ""),CHAR(10),"\n"),"'","\'")&"', textZhG1: '"&SUBSTITUTE(SUBSTITUTE(SUBSTITUTE(AI6, CHAR(13), ""),CHAR(10),"\n"),"'","\'")&IF(AH6<>"", "', textZhAdditional: '"&SUBSTITUTE(SUBSTITUTE(AH6, CHAR(13), ""),CHAR(10),"\n"), "")&IF(AJ6<>"", "', textZhG1Additional: '"&SUBSTITUTE(SUBSTITUTE(AJ6, CHAR(13), ""),CHAR(10),"\n"), "")&"', textKo: '"&SUBSTITUTE(SUBSTITUTE(SUBSTITUTE(AK6, CHAR(13), ""),CHAR(10),"\n"),"'","\'")&IF(AL6<>"", "', textKoAdditional: '"&SUBSTITUTE(SUBSTITUTE(AL6, CHAR(13), ""),CHAR(10),"\n"), "")&"', textEn: '"&SUBSTITUTE(SUBSTITUTE(SUBSTITUTE(AM6, CHAR(13), ""),CHAR(10),"\n"),"'","\'")&IF(AN6<>"", "', textEnAdditional: '"&SUBSTITUTE(SUBSTITUTE(AN6, CHAR(13), ""),CHAR(10),"\n"), "")&"'"&IF(AB6="○",", sealable: true","")&IF(AC6="○",", removable: true","")&IF(AA6="○",", lie: true","")&IF(AD6="○",", investable: true","")&"},") -> '26-innealra-o3-n-6': {megami: 'innealra', anotherID: 'O3', replace: '26-innealra-o-n-6', name: '儚き意志', nameEn: '', nameZh: '缥缈意志', nameZhG1: '', nameKo: '덧없는 의지', ruby: 'はかなきいし', rubyEn: '', baseType: 'normal', type: 'enhance', capacity: '2', text: '【展開時/破棄時】過去の運命をまだ見ぬ運命へと動かしてもよい。\n【常時】この付与札の上の桜花結晶がダストへと送られるならば、代わりにロストへと移動する。', textZh: '【展开时】可以将过去的命运移去未知的命运。\n 【展开中】达人距离的数值减少1。', textZhG1: '', textKo: '【전개시/파기시】과거의 운명을 아직 보지 않은 운명으로 이동시켜도 된다.\n【상시】이 부여패 위의 벚꽃결정이 더스트로 보내진다면, 대신 로스트로 이동한다.', textEn: ''}, | AU6: =IF($A6<>"", " /** 《"&$E6&"》 */ export const "&SUBSTITUTE(UPPER(IF(MID($A6, 3, 1)="-", RIGHT($A6,LEN($A6)-3), $A6)), "-", "_")&": TCardId = '"&$A6&"';", "") -> /** 《儚き意志》 */ export const INNEALRA_O3_N_6: TCardId = '26-innealra-o3-n-6'; | AV6: =IF($A6<>"", " | '"&$A6&"'", "") -> | '26-innealra-o3-n-6'
A7: 26-innealra-o3-s-3 | B7: innealra | C7: O3 | D7: 26-innealra-o-s-3 | E7: クレーニャ・アンニャ | G7: ‌宙宇·玄奥无明 | I7: cruinne | J7: 크레냐·안냐 | M7: 切札 | R7: 行動 | S7: 対応 | Z7: 0 | AC7: ○ | AE7: 過去の運命をまだ見ぬ運命へと動かしてもよい。 自オーラ⇔ロスト：1 【使用済】各ターンの開始フェイズの開始時に攻撃『適正距離0-10、1/1、【常時】この《攻撃》のダメージにより移動する桜花結晶はダストやフレアではなくロストに動かす』を行う。その後、このカードを取り除く。 | AG7: 可以将过去的命运移去未知的命运。 【已使用】你的准备步骤开始时，可以进行一次“攻击距离X 伤害2/1 不可避 【常时】X等于迷失的值”的攻击。若如此做，将此卡移出游戏。 | AK7: 과거의 운명을 보지 못한 운명으로 이동시켜도 된다. 오라(자신)⇔로스트：1 【사용됨】당신의 개시 페이지의 시작시에 공격『적정거리 0-10, 1/1, 【상시】이 공격으로 이동하는 벚꽃결정은 더스트나 플레어로 이동하지 않고 로스트로 이동한다.』를 수행한다. 그 후, 이 카드를 게임에서 제외한다. | AT7: =IF(A7="", "","'"&A7&"': {megami: '"&B7&"'"&IF(C7<>"",", anotherID: '"&C7&"', replace: '"&D7&"'","")&", name: '"&SUBSTITUTE(E7,"'","\'")&"', nameEn: '"&SUBSTITUTE(K7,"'","\'")&"', nameZh: '"&SUBSTITUTE(G7,"'","\'")&"', nameZhG1: '"&SUBSTITUTE(H7,"'","\'")&"', nameKo: '"&SUBSTITUTE(J7,"'","\'")&"', ruby: '"&F7&"', rubyEn: '"&L7&IF(I7<>"", "', rubyZh: '"&I7, "")&"', baseType: '"&VLOOKUP(M7,マスタ!$A$1:$B$99,2,0)&"'"&IF(N7="○",", extra: true","")&IF(O7<>"",", extraFrom: '"&O7&"'","")&IF(P7<>"",", exchangableTo: '"&P7&"'","")&IF(Q7="○",", poison: true","")&IF(R7<>"", ", type: '"&VLOOKUP(R7,マスタ!$D$1:$E$99,2,0)&"'", "")&IF(S7<>"",", subType: '"&VLOOKUP(S7,マスタ!$D$1:$E$99,2,0)&"'","")&""&IF(T7<>"",", range: '"&T7&"'","")&IF(V7<>"",", damage: '"&V7&"'","")&IF(X7<>"",", capacity: '"&X7&"'","")&IF(Y7<>"",", growth: "&Y7&"","")&IF(Z7<>"",", cost: '"&Z7&"'","")&", text: '"&SUBSTITUTE(SUBSTITUTE(AE7, CHAR(13), ""),CHAR(10),"\n")&IF(AF7<>"", "', textAdditional: '"&SUBSTITUTE(SUBSTITUTE(AF7, CHAR(13), ""),CHAR(10),"\n"), "")&"', textZh: '"&SUBSTITUTE(SUBSTITUTE(SUBSTITUTE(AG7, CHAR(13), ""),CHAR(10),"\n"),"'","\'")&"', textZhG1: '"&SUBSTITUTE(SUBSTITUTE(SUBSTITUTE(AI7, CHAR(13), ""),CHAR(10),"\n"),"'","\'")&IF(AH7<>"", "', textZhAdditional: '"&SUBSTITUTE(SUBSTITUTE(AH7, CHAR(13), ""),CHAR(10),"\n"), "")&IF(AJ7<>"", "', textZhG1Additional: '"&SUBSTITUTE(SUBSTITUTE(AJ7, CHAR(13), ""),CHAR(10),"\n"), "")&"', textKo: '"&SUBSTITUTE(SUBSTITUTE(SUBSTITUTE(AK7, CHAR(13), ""),CHAR(10),"\n"),"'","\'")&IF(AL7<>"", "', textKoAdditional: '"&SUBSTITUTE(SUBSTITUTE(AL7, CHAR(13), ""),CHAR(10),"\n"), "")&"', textEn: '"&SUBSTITUTE(SUBSTITUTE(SUBSTITUTE(AM7, CHAR(13), ""),CHAR(10),"\n"),"'","\'")&IF(AN7<>"", "', textEnAdditional: '"&SUBSTITUTE(SUBSTITUTE(AN7, CHAR(13), ""),CHAR(10),"\n"), "")&"'"&IF(AB7="○",", sealable: true","")&IF(AC7="○",", removable: true","")&IF(AA7="○",", lie: true","")&IF(AD7="○",", investable: true","")&"},") -> '26-innealra-o3-s-3': {megami: 'innealra', anotherID: 'O3', replace: '26-innealra-o-s-3', name: 'クレーニャ・アンニャ', nameEn: '', nameZh: '‌宙宇·玄奥无明', nameZhG1: '', nameKo: '크레냐·안냐', ruby: '', rubyEn: '', rubyZh: 'cruinne', baseType: 'special', type: 'action', subType: 'reaction', cost: '0', text: '過去の運命をまだ見ぬ運命へと動かしてもよい。\n自オーラ⇔ロスト：1\n【使用済】各ターンの開始フェイズの開始時に攻撃『適正距離0-10、1/1、【常時】この《攻撃》のダメージにより移動する桜花結晶はダストやフレアではなくロストに動かす』を行う。その後、このカードを取り除く。', textZh: '可以将过去的命运移去未知的命运。\n 【已使用】你的准备步骤开始时，可以进行一次“攻击距离X 伤害2/1 不可避 【常时】X等于迷失的值”的攻击。若如此做，将此卡移出游戏。', textZhG1: '', textKo: '과거의 운명을 보지 못한 운명으로 이동시켜도 된다.\n오라(자신)⇔로스트：1\n【사용됨】당신의 개시 페이지의 시작시에 공격『적정거리 0-10, 1/1, 【상시】이 공격으로 이동하는 벚꽃결정은 더스트나 플레어로 이동하지 않고 로스트로 이동한다.』를 수행한다. 그 후, 이 카드를 게임에서 제외한다.', textEn: '', removable: true}, | AU7: =IF($A7<>"", " /** 《"&$E7&"》 */ export const "&SUBSTITUTE(UPPER(IF(MID($A7, 3, 1)="-", RIGHT($A7,LEN($A7)-3), $A7)), "-", "_")&": TCardId = '"&$A7&"';", "") -> /** 《クレーニャ・アンニャ》 */ export const INNEALRA_O3_S_3: TCardId = '26-innealra-o3-s-3'; | AV7: =IF($A7<>"", " | '"&$A7&"'", "") -> | '26-innealra-o3-s-3'
A8: 03-himika-o-n-6 | B8: himika | E8: バックドラフト | G8: 回燃 | H8: 回燃 | I8: Backdraft | J8: 백드래프트 | K8: Backdraft | M8: 通常札 | R8: 行動 | AE8: 相手を畏縮させる。 連火―このカードがこのターンに使用した3枚目以降のカードならば、このターンにあなたが次に行う他のメガミによるオーラへのダメージが3以下の《攻撃》は+1/+1となる。 | AG8: 令对手畏缩。 连火～若此牌是本回合你使用的第3张或更多的牌，则本回合你的下一次其他女神的对装伤害不为「-」的《攻击》得+1/+1。 | AK8: 상대를 위축시킨다。 연화-이 카드가 이 턴에 사용한 3장째 이후의 카드라면, 이 턴 당신이 다음에 행하는 다른 여신에 의한 오라 데미지가 3이하의 《공격》을 +1/+1 한다. | AM8: Flinch your opponent. Inferno - If this is the third or later card you've played this turn, your next attack this turn from a non-Himika Megami that does not have "-" Damage to Aura gains +1/+1. | AT8: =IF(A8="", "","'"&A8&"': {megami: '"&B8&"'"&IF(C8<>"",", anotherID: '"&C8&"', replace: '"&D8&"'","")&", name: '"&SUBSTITUTE(E8,"'","\'")&"', nameEn: '"&SUBSTITUTE(K8,"'","\'")&"', nameZh: '"&SUBSTITUTE(G8,"'","\'")&"', nameZhG1: '"&SUBSTITUTE(H8,"'","\'")&"', nameKo: '"&SUBSTITUTE(J8,"'","\'")&"', ruby: '"&F8&"', rubyEn: '"&L8&IF(I8<>"", "', rubyZh: '"&I8, "")&"', baseType: '"&VLOOKUP(M8,マスタ!$A$1:$B$99,2,0)&"'"&IF(N8="○",", extra: true","")&IF(O8<>"",", extraFrom: '"&O8&"'","")&IF(P8<>"",", exchangableTo: '"&P8&"'","")&IF(Q8="○",", poison: true","")&IF(R8<>"", ", type: '"&VLOOKUP(R8,マスタ!$D$1:$E$99,2,0)&"'", "")&IF(S8<>"",", subType: '"&VLOOKUP(S8,マスタ!$D$1:$E$99,2,0)&"'","")&""&IF(T8<>"",", range: '"&T8&"'","")&IF(V8<>"",", damage: '"&V8&"'","")&IF(X8<>"",", capacity: '"&X8&"'","")&IF(Y8<>"",", growth: "&Y8&"","")&IF(Z8<>"",", cost: '"&Z8&"'","")&", text: '"&SUBSTITUTE(SUBSTITUTE(AE8, CHAR(13), ""),CHAR(10),"\n")&IF(AF8<>"", "', textAdditional: '"&SUBSTITUTE(SUBSTITUTE(AF8, CHAR(13), ""),CHAR(10),"\n"), "")&"', textZh: '"&SUBSTITUTE(SUBSTITUTE(SUBSTITUTE(AG8, CHAR(13), ""),CHAR(10),"\n"),"'","\'")&"', textZhG1: '"&SUBSTITUTE(SUBSTITUTE(SUBSTITUTE(AI8, CHAR(13), ""),CHAR(10),"\n"),"'","\'")&IF(AH8<>"", "', textZhAdditional: '"&SUBSTITUTE(SUBSTITUTE(AH8, CHAR(13), ""),CHAR(10),"\n"), "")&IF(AJ8<>"", "', textZhG1Additional: '"&SUBSTITUTE(SUBSTITUTE(AJ8, CHAR(13), ""),CHAR(10),"\n"), "")&"', textKo: '"&SUBSTITUTE(SUBSTITUTE(SUBSTITUTE(AK8, CHAR(13), ""),CHAR(10),"\n"),"'","\'")&IF(AL8<>"", "', textKoAdditional: '"&SUBSTITUTE(SUBSTITUTE(AL8, CHAR(13), ""),CHAR(10),"\n"), "")&"', textEn: '"&SUBSTITUTE(SUBSTITUTE(SUBSTITUTE(AM8, CHAR(13), ""),CHAR(10),"\n"),"'","\'")&IF(AN8<>"", "', textEnAdditional: '"&SUBSTITUTE(SUBSTITUTE(AN8, CHAR(13), ""),CHAR(10),"\n"), "")&"'"&IF(AB8="○",", sealable: true","")&IF(AC8="○",", removable: true","")&IF(AA8="○",", lie: true","")&IF(AD8="○",", investable: true","")&"},") -> '03-himika-o-n-6': {megami: 'himika', name: 'バックドラフト', nameEn: 'Backdraft', nameZh: '回燃', nameZhG1: '回燃', nameKo: '백드래프트', ruby: '', rubyEn: '', rubyZh: 'Backdraft', baseType: 'normal', type: 'action', text: '相手を畏縮させる。\n連火―このカードがこのターンに使用した3枚目以降のカードならば、このターンにあなたが次に行う他のメガミによるオーラへのダメージが3以下の《攻撃》は+1/+1となる。', textZh: '令对手畏缩。\n连火～若此牌是本回合你使用的第3张或更多的牌，则本回合你的下一次其他女神的对装伤害不为「-」的《攻击》得+1/+1。', textZhG1: '', textKo: '상대를 위축시킨다。\n 연화-이 카드가 이 턴에 사용한 3장째 이후의 카드라면, 이 턴 당신이 다음에 행하는 다른 여신에 의한 오라 데미지가 3이하의 《공격》을 +1/+1 한다.', textEn: 'Flinch your opponent.\n\nInferno - If this is the third or later card you\'ve played this turn, your next attack this turn from a non-Himika Megami that does not have "-" Damage to Aura gains +1/+1.'}, | AU8: =IF($A8<>"", " /** 《"&$E8&"》 */ export const "&SUBSTITUTE(UPPER(IF(MID($A8, 3, 1)="-", RIGHT($A8,LEN($A8)-3), $A8)), "-", "_")&": TCardId = '"&$A8&"';", "") -> /** 《バックドラフト》 */ export const HIMIKA_O_N_6: TCardId = '03-himika-o-n-6'; | AV8: =IF($A8<>"", " | '"&$A8&"'", "") -> | '03-himika-o-n-6'
A9: 22-renri-o-n-6 | B9: renri | E9: 魚吊り | F9: うおつり | G9: 吊魚 | H9: 辜毒谄言 | I9: 钓鱼 | J9: 낚시질 | K9: Motive | M9: 通常札 | R9: 行動 | AA9: ○ | AE9: 偽証 間合→自フレア：1 | AG9: 伪证 距→1→自气 | AK9: 위증 간격→플레어(자신)：1 | AT9: =IF(A9="", "","'"&A9&"': {megami: '"&B9&"'"&IF(C9<>"",", anotherID: '"&C9&"', replace: '"&D9&"'","")&", name: '"&SUBSTITUTE(E9,"'","\'")&"', nameEn: '"&SUBSTITUTE(K9,"'","\'")&"', nameZh: '"&SUBSTITUTE(G9,"'","\'")&"', nameZhG1: '"&SUBSTITUTE(H9,"'","\'")&"', nameKo: '"&SUBSTITUTE(J9,"'","\'")&"', ruby: '"&F9&"', rubyEn: '"&L9&IF(I9<>"", "', rubyZh: '"&I9, "")&"', baseType: '"&VLOOKUP(M9,マスタ!$A$1:$B$99,2,0)&"'"&IF(N9="○",", extra: true","")&IF(O9<>"",", extraFrom: '"&O9&"'","")&IF(P9<>"",", exchangableTo: '"&P9&"'","")&IF(Q9="○",", poison: true","")&IF(R9<>"", ", type: '"&VLOOKUP(R9,マスタ!$D$1:$E$99,2,0)&"'", "")&IF(S9<>"",", subType: '"&VLOOKUP(S9,マスタ!$D$1:$E$99,2,0)&"'","")&""&IF(T9<>"",", range: '"&T9&"'","")&IF(V9<>"",", damage: '"&V9&"'","")&IF(X9<>"",", capacity: '"&X9&"'","")&IF(Y9<>"",", growth: "&Y9&"","")&IF(Z9<>"",", cost: '"&Z9&"'","")&", text: '"&SUBSTITUTE(SUBSTITUTE(AE9, CHAR(13), ""),CHAR(10),"\n")&IF(AF9<>"", "', textAdditional: '"&SUBSTITUTE(SUBSTITUTE(AF9, CHAR(13), ""),CHAR(10),"\n"), "")&"', textZh: '"&SUBSTITUTE(SUBSTITUTE(SUBSTITUTE(AG9, CHAR(13), ""),CHAR(10),"\n"),"'","\'")&"', textZhG1: '"&SUBSTITUTE(SUBSTITUTE(SUBSTITUTE(AI9, CHAR(13), ""),CHAR(10),"\n"),"'","\'")&IF(AH9<>"", "', textZhAdditional: '"&SUBSTITUTE(SUBSTITUTE(AH9, CHAR(13), ""),CHAR(10),"\n"), "")&IF(AJ9<>"", "', textZhG1Additional: '"&SUBSTITUTE(SUBSTITUTE(AJ9, CHAR(13), ""),CHAR(10),"\n"), "")&"', textKo: '"&SUBSTITUTE(SUBSTITUTE(SUBSTITUTE(AK9, CHAR(13), ""),CHAR(10),"\n"),"'","\'")&IF(AL9<>"", "', textKoAdditional: '"&SUBSTITUTE(SUBSTITUTE(AL9, CHAR(13), ""),CHAR(10),"\n"), "")&"', textEn: '"&SUBSTITUTE(SUBSTITUTE(SUBSTITUTE(AM9, CHAR(13), ""),CHAR(10),"\n"),"'","\'")&IF(AN9<>"", "', textEnAdditional: '"&SUBSTITUTE(SUBSTITUTE(AN9, CHAR(13), ""),CHAR(10),"\n"), "")&"'"&IF(AB9="○",", sealable: true","")&IF(AC9="○",", removable: true","")&IF(AA9="○",", lie: true","")&IF(AD9="○",", investable: true","")&"},") -> '22-renri-o-n-6': {megami: 'renri', name: '魚吊り', nameEn: 'Motive', nameZh: '吊魚', nameZhG1: '辜毒谄言', nameKo: '낚시질', ruby: 'うおつり', rubyEn: '', rubyZh: '钓鱼', baseType: 'normal', type: 'action', text: '偽証\n間合→自フレア：1', textZh: '伪证\n距→1→自气', textZhG1: '', textKo: '위증\n간격→플레어(자신)：1', textEn: '', lie: true}, | AU9: =IF($A9<>"", " /** 《"&$E9&"》 */ export const "&SUBSTITUTE(UPPER(IF(MID($A9, 3, 1)="-", RIGHT($A9,LEN($A9)-3), $A9)), "-", "_")&": TCardId = '"&$A9&"';", "") -> /** 《魚吊り》 */ export const RENRI_O_N_6: TCardId = '22-renri-o-n-6'; | AV9: =IF($A9<>"", " | '"&$A9&"'", "") -> | '22-renri-o-n-6'
A10: 18-mizuki-o-s-3 | B10: mizuki | E10: 大手楯無門 | F10: おおてたてなしもん | G10: 大手楯无门 | H10: 大手楯无门 | J10: 대수순무문 | K10: Ōte Gate "Tatenashi" | M10: 切札 | R10: 行動 | Z10: 3 | AE10: 終端 手札のカードを1枚まで選び、それと追加札の「闘神」を兵舎に徴兵済で置く。 【使用済】あなたが兵舎から使用した《攻撃》カードによる《攻撃》は+1/+0となる。 | AG10: 终端 将你的1张手牌和追加牌处的『斗神』以已征兵的状态置入兵营。进行1次征兵。 【已使用】你从兵营使用的《攻击》牌的《攻击》得+1/+0，从兵营使用的《对应》牌失去终端。 | AK10: 종단 손패의 카드를 1장까지 고르고 그것과 추가패의 [투신]과 그것들을 병영의 징병된 상태로 놓는다. 징병을 1회 수행한다. 【사용됨】당신이 병영에서 사용한 《공격》카드에 의한 《공격》은 +1/+0을 얻는다. | AM10: Terminal Put your set aside "Divinity of War" and a card from your hand into your Barracks, conscripted. Conscript a Unit. Devoted: Attack cards you play from your Barracks gain +1/+0. Reaction cards you play from your Barracks lose Terminal. | AT10: =IF(A10="", "","'"&A10&"': {megami: '"&B10&"'"&IF(C10<>"",", anotherID: '"&C10&"', replace: '"&D10&"'","")&", name: '"&SUBSTITUTE(E10,"'","\'")&"', nameEn: '"&SUBSTITUTE(K10,"'","\'")&"', nameZh: '"&SUBSTITUTE(G10,"'","\'")&"', nameZhG1: '"&SUBSTITUTE(H10,"'","\'")&"', nameKo: '"&SUBSTITUTE(J10,"'","\'")&"', ruby: '"&F10&"', rubyEn: '"&L10&IF(I10<>"", "', rubyZh: '"&I10, "")&"', baseType: '"&VLOOKUP(M10,マスタ!$A$1:$B$99,2,0)&"'"&IF(N10="○",", extra: true","")&IF(O10<>"",", extraFrom: '"&O10&"'","")&IF(P10<>"",", exchangableTo: '"&P10&"'","")&IF(Q10="○",", poison: true","")&IF(R10<>"", ", type: '"&VLOOKUP(R10,マスタ!$D$1:$E$99,2,0)&"'", "")&IF(S10<>"",", subType: '"&VLOOKUP(S10,マスタ!$D$1:$E$99,2,0)&"'","")&""&IF(T10<>"",", range: '"&T10&"'","")&IF(V10<>"",", damage: '"&V10&"'","")&IF(X10<>"",", capacity: '"&X10&"'","")&IF(Y10<>"",", growth: "&Y10&"","")&IF(Z10<>"",", cost: '"&Z10&"'","")&", text: '"&SUBSTITUTE(SUBSTITUTE(AE10, CHAR(13), ""),CHAR(10),"\n")&IF(AF10<>"", "', textAdditional: '"&SUBSTITUTE(SUBSTITUTE(AF10, CHAR(13), ""),CHAR(10),"\n"), "")&"', textZh: '"&SUBSTITUTE(SUBSTITUTE(SUBSTITUTE(AG10, CHAR(13), ""),CHAR(10),"\n"),"'","\'")&"', textZhG1: '"&SUBSTITUTE(SUBSTITUTE(SUBSTITUTE(AI10, CHAR(13), ""),CHAR(10),"\n"),"'","\'")&IF(AH10<>"", "', textZhAdditional: '"&SUBSTITUTE(SUBSTITUTE(AH10, CHAR(13), ""),CHAR(10),"\n"), "")&IF(AJ10<>"", "', textZhG1Additional: '"&SUBSTITUTE(SUBSTITUTE(AJ10, CHAR(13), ""),CHAR(10),"\n"), "")&"', textKo: '"&SUBSTITUTE(SUBSTITUTE(SUBSTITUTE(AK10, CHAR(13), ""),CHAR(10),"\n"),"'","\'")&IF(AL10<>"", "', textKoAdditional: '"&SUBSTITUTE(SUBSTITUTE(AL10, CHAR(13), ""),CHAR(10),"\n"), "")&"', textEn: '"&SUBSTITUTE(SUBSTITUTE(SUBSTITUTE(AM10, CHAR(13), ""),CHAR(10),"\n"),"'","\'")&IF(AN10<>"", "', textEnAdditional: '"&SUBSTITUTE(SUBSTITUTE(AN10, CHAR(13), ""),CHAR(10),"\n"), "")&"'"&IF(AB10="○",", sealable: true","")&IF(AC10="○",", removable: true","")&IF(AA10="○",", lie: true","")&IF(AD10="○",", investable: true","")&"},") -> '18-mizuki-o-s-3': {megami: 'mizuki', name: '大手楯無門', nameEn: 'Ōte Gate "Tatenashi"', nameZh: '大手楯无门', nameZhG1: '大手楯无门', nameKo: '대수순무문', ruby: 'おおてたてなしもん', rubyEn: '', baseType: 'special', type: 'action', cost: '3', text: '終端\n手札のカードを1枚まで選び、それと追加札の「闘神」を兵舎に徴兵済で置く。\n【使用済】あなたが兵舎から使用した《攻撃》カードによる《攻撃》は+1/+0となる。', textZh: '终端 \n将你的1张手牌和追加牌处的『斗神』以已征兵的状态置入兵营。进行1次征兵。 \n【已使用】你从兵营使用的《攻击》牌的《攻击》得+1/+0，从兵营使用的《对应》牌失去终端。', textZhG1: '', textKo: '종단\n손패의 카드를 1장까지 고르고 그것과 추가패의 [투신]과 그것들을 병영의 징병된 상태로 놓는다.\n징병을 1회 수행한다.\n【사용됨】당신이 병영에서 사용한 《공격》카드에 의한 《공격》은 +1/+0을 얻는다.', textEn: 'Terminal\n\nPut your set aside "Divinity of War" and a card from your hand into your Barracks, conscripted. Conscript a Unit.\n\nDevoted: Attack cards you play from your Barracks gain +1/+0. Reaction cards you play from your Barracks lose Terminal.'}, | AU10: =IF($A10<>"", " /** 《"&$E10&"》 */ export const "&SUBSTITUTE(UPPER(IF(MID($A10, 3, 1)="-", RIGHT($A10,LEN($A10)-3), $A10)), "-", "_")&": TCardId = '"&$A10&"';", "") -> /** 《大手楯無門》 */ export const MIZUKI_O_S_3: TCardId = '18-mizuki-o-s-3'; | AV10: =IF($A10<>"", " | '"&$A10&"'", "") -> | '18-mizuki-o-s-3'
A11: 26-innealra-o-n-1 | B11: innealra | E11: 槍振るい | F11: やりふるい | G11: 挥枪 | J11: 창 휘두르기 | M11: 通常札 | R11: 攻撃 | T11: 1-5 | V11: 1/1 | AE11: 【攻撃後】共鳴する。 | AG11: 【攻击后】进行共鸣。 | AK11: 【공격후】공명한다 | AT11: =IF(A11="", "","'"&A11&"': {megami: '"&B11&"'"&IF(C11<>"",", anotherID: '"&C11&"', replace: '"&D11&"'","")&", name: '"&SUBSTITUTE(E11,"'","\'")&"', nameEn: '"&SUBSTITUTE(K11,"'","\'")&"', nameZh: '"&SUBSTITUTE(G11,"'","\'")&"', nameZhG1: '"&SUBSTITUTE(H11,"'","\'")&"', nameKo: '"&SUBSTITUTE(J11,"'","\'")&"', ruby: '"&F11&"', rubyEn: '"&L11&IF(I11<>"", "', rubyZh: '"&I11, "")&"', baseType: '"&VLOOKUP(M11,マスタ!$A$1:$B$99,2,0)&"'"&IF(N11="○",", extra: true","")&IF(O11<>"",", extraFrom: '"&O11&"'","")&IF(P11<>"",", exchangableTo: '"&P11&"'","")&IF(Q11="○",", poison: true","")&IF(R11<>"", ", type: '"&VLOOKUP(R11,マスタ!$D$1:$E$99,2,0)&"'", "")&IF(S11<>"",", subType: '"&VLOOKUP(S11,マスタ!$D$1:$E$99,2,0)&"'","")&""&IF(T11<>"",", range: '"&T11&"'","")&IF(V11<>"",", damage: '"&V11&"'","")&IF(X11<>"",", capacity: '"&X11&"'","")&IF(Y11<>"",", growth: "&Y11&"","")&IF(Z11<>"",", cost: '"&Z11&"'","")&", text: '"&SUBSTITUTE(SUBSTITUTE(AE11, CHAR(13), ""),CHAR(10),"\n")&IF(AF11<>"", "', textAdditional: '"&SUBSTITUTE(SUBSTITUTE(AF11, CHAR(13), ""),CHAR(10),"\n"), "")&"', textZh: '"&SUBSTITUTE(SUBSTITUTE(SUBSTITUTE(AG11, CHAR(13), ""),CHAR(10),"\n"),"'","\'")&"', textZhG1: '"&SUBSTITUTE(SUBSTITUTE(SUBSTITUTE(AI11, CHAR(13), ""),CHAR(10),"\n"),"'","\'")&IF(AH11<>"", "', textZhAdditional: '"&SUBSTITUTE(SUBSTITUTE(AH11, CHAR(13), ""),CHAR(10),"\n"), "")&IF(AJ11<>"", "', textZhG1Additional: '"&SUBSTITUTE(SUBSTITUTE(AJ11, CHAR(13), ""),CHAR(10),"\n"), "")&"', textKo: '"&SUBSTITUTE(SUBSTITUTE(SUBSTITUTE(AK11, CHAR(13), ""),CHAR(10),"\n"),"'","\'")&IF(AL11<>"", "', textKoAdditional: '"&SUBSTITUTE(SUBSTITUTE(AL11, CHAR(13), ""),CHAR(10),"\n"), "")&"', textEn: '"&SUBSTITUTE(SUBSTITUTE(SUBSTITUTE(AM11, CHAR(13), ""),CHAR(10),"\n"),"'","\'")&IF(AN11<>"", "', textEnAdditional: '"&SUBSTITUTE(SUBSTITUTE(AN11, CHAR(13), ""),CHAR(10),"\n"), "")&"'"&IF(AB11="○",", sealable: true","")&IF(AC11="○",", removable: true","")&IF(AA11="○",", lie: true","")&IF(AD11="○",", investable: true","")&"},") -> '26-innealra-o-n-1': {megami: 'innealra', name: '槍振るい', nameEn: '', nameZh: '挥枪', nameZhG1: '', nameKo: '창 휘두르기', ruby: 'やりふるい', rubyEn: '', baseType: 'normal', type: 'attack', range: '1-5', damage: '1/1', text: '【攻撃後】共鳴する。', textZh: '【攻击后】进行共鸣。', textZhG1: '', textKo: '【공격후】공명한다', textEn: ''}, | AU11: =IF($A11<>"", " /** 《"&$E11&"》 */ export const "&SUBSTITUTE(UPPER(IF(MID($A11, 3, 1)="-", RIGHT($A11,LEN($A11)-3), $A11)), "-", "_")&": TCardId = '"&$A11&"';", "") -> /** 《槍振るい》 */ export const INNEALRA_O_N_1: TCardId = '26-innealra-o-n-1'; | AV11: =IF($A11<>"", " | '"&$A11&"'", "") -> | '26-innealra-o-n-1'
A12: 26-innealra-o2-s-3 | B12: innealra | C12: O2 | D12: 26-innealra-o-s-3 | E12: シキリス・ホリス | G12: 同受异诛·欲壑难填 | I12: scrios | J12: 시키리스·호리스 | M12: 切札 | R12: 攻撃 | T12: 1-3 | V12: 1/1 | Z12: 1 | AE12: 【常時】この《攻撃》のオーラへのダメージにより移動する桜花結晶はダストでなく間合に動かす。 ---- 【再起】あなたがこのターン中に2回以上共鳴している。 | AG12: 【常时】因此《攻击》造成的伤害将移动的樱花结晶改为移去距。 ---- 【再起】你在本回合进行了至少2次共鸣。 | AK12: 【상시】이 《공격》의 오라 데미지로 이동하는 벚꽃결정은 더스트가 아니라 간격으로 이동시킨다. 【재기】당신이 이번 턴에 2회 이상 공명하였다. | AT12: =IF(A12="", "","'"&A12&"': {megami: '"&B12&"'"&IF(C12<>"",", anotherID: '"&C12&"', replace: '"&D12&"'","")&", name: '"&SUBSTITUTE(E12,"'","\'")&"', nameEn: '"&SUBSTITUTE(K12,"'","\'")&"', nameZh: '"&SUBSTITUTE(G12,"'","\'")&"', nameZhG1: '"&SUBSTITUTE(H12,"'","\'")&"', nameKo: '"&SUBSTITUTE(J12,"'","\'")&"', ruby: '"&F12&"', rubyEn: '"&L12&IF(I12<>"", "', rubyZh: '"&I12, "")&"', baseType: '"&VLOOKUP(M12,マスタ!$A$1:$B$99,2,0)&"'"&IF(N12="○",", extra: true","")&IF(O12<>"",", extraFrom: '"&O12&"'","")&IF(P12<>"",", exchangableTo: '"&P12&"'","")&IF(Q12="○",", poison: true","")&IF(R12<>"", ", type: '"&VLOOKUP(R12,マスタ!$D$1:$E$99,2,0)&"'", "")&IF(S12<>"",", subType: '"&VLOOKUP(S12,マスタ!$D$1:$E$99,2,0)&"'","")&""&IF(T12<>"",", range: '"&T12&"'","")&IF(V12<>"",", damage: '"&V12&"'","")&IF(X12<>"",", capacity: '"&X12&"'","")&IF(Y12<>"",", growth: "&Y12&"","")&IF(Z12<>"",", cost: '"&Z12&"'","")&", text: '"&SUBSTITUTE(SUBSTITUTE(AE12, CHAR(13), ""),CHAR(10),"\n")&IF(AF12<>"", "', textAdditional: '"&SUBSTITUTE(SUBSTITUTE(AF12, CHAR(13), ""),CHAR(10),"\n"), "")&"', textZh: '"&SUBSTITUTE(SUBSTITUTE(SUBSTITUTE(AG12, CHAR(13), ""),CHAR(10),"\n"),"'","\'")&"', textZhG1: '"&SUBSTITUTE(SUBSTITUTE(SUBSTITUTE(AI12, CHAR(13), ""),CHAR(10),"\n"),"'","\'")&IF(AH12<>"", "', textZhAdditional: '"&SUBSTITUTE(SUBSTITUTE(AH12, CHAR(13), ""),CHAR(10),"\n"), "")&IF(AJ12<>"", "', textZhG1Additional: '"&SUBSTITUTE(SUBSTITUTE(AJ12, CHAR(13), ""),CHAR(10),"\n"), "")&"', textKo: '"&SUBSTITUTE(SUBSTITUTE(SUBSTITUTE(AK12, CHAR(13), ""),CHAR(10),"\n"),"'","\'")&IF(AL12<>"", "', textKoAdditional: '"&SUBSTITUTE(SUBSTITUTE(AL12, CHAR(13), ""),CHAR(10),"\n"), "")&"', textEn: '"&SUBSTITUTE(SUBSTITUTE(SUBSTITUTE(AM12, CHAR(13), ""),CHAR(10),"\n"),"'","\'")&IF(AN12<>"", "', textEnAdditional: '"&SUBSTITUTE(SUBSTITUTE(AN12, CHAR(13), ""),CHAR(10),"\n"), "")&"'"&IF(AB12="○",", sealable: true","")&IF(AC12="○",", removable: true","")&IF(AA12="○",", lie: true","")&IF(AD12="○",", investable: true","")&"},") -> '26-innealra-o2-s-3': {megami: 'innealra', anotherID: 'O2', replace: '26-innealra-o-s-3', name: 'シキリス・ホリス', nameEn: '', nameZh: '同受异诛·欲壑难填', nameZhG1: '', nameKo: '시키리스·호리스', ruby: '', rubyEn: '', rubyZh: 'scrios', baseType: 'special', type: 'attack', range: '1-3', damage: '1/1', cost: '1', text: '【常時】この《攻撃》のオーラへのダメージにより移動する桜花結晶はダストでなく間合に動かす。\n----\n【再起】あなたがこのターン中に2回以上共鳴している。', textZh: '【常时】因此《攻击》造成的伤害将移动的樱花结晶改为移去距。\n ----\n 【再起】你在本回合进行了至少2次共鸣。', textZhG1: '', textKo: '【상시】이 《공격》의 오라 데미지로 이동하는 벚꽃결정은 더스트가 아니라 간격으로 이동시킨다.\n【재기】당신이 이번 턴에 2회 이상 공명하였다.', textEn: ''}, | AU12: =IF($A12<>"", " /** 《"&$E12&"》 */ export const "&SUBSTITUTE(UPPER(IF(MID($A12, 3, 1)="-", RIGHT($A12,LEN($A12)-3), $A12)), "-", "_")&": TCardId = '"&$A12&"';", "") -> /** 《シキリス・ホリス》 */ export const INNEALRA_O2_S_3: TCardId = '26-innealra-o2-s-3'; | AV12: =IF($A12<>"", " | '"&$A12&"'", "") -> | '26-innealra-o2-s-3'
A13: 26-innealra-o3-f-1 | B13: innealra | C13: O3 | E13: あこがれ | G13: 憧憬 | J13: 동경하다 | M13: 運命 | AE13: ロスト→ダスト：3 攻撃『適正距離0-3、X/1』を行う。Xはこの矢印（→）で移動した桜花結晶の数に等しい。 | AF13: （クリックでまだ見ぬ運命へと移動） | AG13: 迷失→3→虚 若因此效果移动了3个或更多樱花结晶，进行一次“攻击距离0-3 伤害3/1”的攻击。 | AH13: （点击即可将其移去未知的命运） | AK13: 로스트→더스트:3 공격 『적정거리 0-3, X/1』를 수행한다. X는 이 화살표로 이동한 벚꽃결정의 수와 같다. | AT13: =IF(A13="", "","'"&A13&"': {megami: '"&B13&"'"&IF(C13<>"",", anotherID: '"&C13&"', replace: '"&D13&"'","")&", name: '"&SUBSTITUTE(E13,"'","\'")&"', nameEn: '"&SUBSTITUTE(K13,"'","\'")&"', nameZh: '"&SUBSTITUTE(G13,"'","\'")&"', nameZhG1: '"&SUBSTITUTE(H13,"'","\'")&"', nameKo: '"&SUBSTITUTE(J13,"'","\'")&"', ruby: '"&F13&"', rubyEn: '"&L13&IF(I13<>"", "', rubyZh: '"&I13, "")&"', baseType: '"&VLOOKUP(M13,マスタ!$A$1:$B$99,2,0)&"'"&IF(N13="○",", extra: true","")&IF(O13<>"",", extraFrom: '"&O13&"'","")&IF(P13<>"",", exchangableTo: '"&P13&"'","")&IF(Q13="○",", poison: true","")&IF(R13<>"", ", type: '"&VLOOKUP(R13,マスタ!$D$1:$E$99,2,0)&"'", "")&IF(S13<>"",", subType: '"&VLOOKUP(S13,マスタ!$D$1:$E$99,2,0)&"'","")&""&IF(T13<>"",", range: '"&T13&"'","")&IF(V13<>"",", damage: '"&V13&"'","")&IF(X13<>"",", capacity: '"&X13&"'","")&IF(Y13<>"",", growth: "&Y13&"","")&IF(Z13<>"",", cost: '"&Z13&"'","")&", text: '"&SUBSTITUTE(SUBSTITUTE(AE13, CHAR(13), ""),CHAR(10),"\n")&IF(AF13<>"", "', textAdditional: '"&SUBSTITUTE(SUBSTITUTE(AF13, CHAR(13), ""),CHAR(10),"\n"), "")&"', textZh: '"&SUBSTITUTE(SUBSTITUTE(SUBSTITUTE(AG13, CHAR(13), ""),CHAR(10),"\n"),"'","\'")&"', textZhG1: '"&SUBSTITUTE(SUBSTITUTE(SUBSTITUTE(AI13, CHAR(13), ""),CHAR(10),"\n"),"'","\'")&IF(AH13<>"", "', textZhAdditional: '"&SUBSTITUTE(SUBSTITUTE(AH13, CHAR(13), ""),CHAR(10),"\n"), "")&IF(AJ13<>"", "', textZhG1Additional: '"&SUBSTITUTE(SUBSTITUTE(AJ13, CHAR(13), ""),CHAR(10),"\n"), "")&"', textKo: '"&SUBSTITUTE(SUBSTITUTE(SUBSTITUTE(AK13, CHAR(13), ""),CHAR(10),"\n"),"'","\'")&IF(AL13<>"", "', textKoAdditional: '"&SUBSTITUTE(SUBSTITUTE(AL13, CHAR(13), ""),CHAR(10),"\n"), "")&"', textEn: '"&SUBSTITUTE(SUBSTITUTE(SUBSTITUTE(AM13, CHAR(13), ""),CHAR(10),"\n"),"'","\'")&IF(AN13<>"", "', textEnAdditional: '"&SUBSTITUTE(SUBSTITUTE(AN13, CHAR(13), ""),CHAR(10),"\n"), "")&"'"&IF(AB13="○",", sealable: true","")&IF(AC13="○",", removable: true","")&IF(AA13="○",", lie: true","")&IF(AD13="○",", investable: true","")&"},") -> '26-innealra-o3-f-1': {megami: 'innealra', anotherID: 'O3', replace: '', name: 'あこがれ', nameEn: '', nameZh: '憧憬', nameZhG1: '', nameKo: '동경하다', ruby: '', rubyEn: '', baseType: 'fate', text: 'ロスト→ダスト：3\n攻撃『適正距離0-3、X/1』を行う。Xはこの矢印（→）で移動した桜花結晶の数に等しい。', textAdditional: '（クリックでまだ見ぬ運命へと移動）', textZh: '迷失→3→虚\n 若因此效果移动了3个或更多樱花结晶，进行一次“攻击距离0-3 伤害3/1”的攻击。', textZhG1: '', textZhAdditional: '（点击即可将其移去未知的命运）', textKo: '로스트→더스트:3\n공격 『적정거리 0-3, X/1』를 수행한다. X는 이 화살표로 이동한 벚꽃결정의 수와 같다.', textEn: ''}, | AU13: =IF($A13<>"", " /** 《"&$E13&"》 */ export const "&SUBSTITUTE(UPPER(IF(MID($A13, 3, 1)="-", RIGHT($A13,LEN($A13)-3), $A13)), "-", "_")&": TCardId = '"&$A13&"';", "") -> /** 《あこがれ》 */ export const INNEALRA_O3_F_1: TCardId = '26-innealra-o3-f-1'; | AV13: =IF($A13<>"", " | '"&$A13&"'", "") -> | '26-innealra-o3-f-1'
AT14: =IF(A14="", "","'"&A14&"': {megami: '"&B14&"'"&IF(C14<>"",", anotherID: '"&C14&"', replace: '"&D14&"'","")&", name: '"&SUBSTITUTE(E14,"'","\'")&"', nameEn: '"&SUBSTITUTE(K14,"'","\'")&"', nameZh: '"&SUBSTITUTE(G14,"'","\'")&"', nameZhG1: '"&SUBSTITUTE(H14,"'","\'")&"', nameKo: '"&SUBSTITUTE(J14,"'","\'")&"', ruby: '"&F14&"', rubyEn: '"&L14&IF(I14<>"", "', rubyZh: '"&I14, "")&"', baseType: '"&VLOOKUP(M14,マスタ!$A$1:$B$99,2,0)&"'"&IF(N14="○",", extra: true","")&IF(O14<>"",", extraFrom: '"&O14&"'","")&IF(P14<>"",", exchangableTo: '"&P14&"'","")&IF(Q14="○",", poison: true","")&IF(R14<>"", ", type: '"&VLOOKUP(R14,マスタ!$D$1:$E$99,2,0)&"'", "")&IF(S14<>"",", subType: '"&VLOOKUP(S14,マスタ!$D$1:$E$99,2,0)&"'","")&""&IF(T14<>"",", range: '"&T14&"'","")&IF(V14<>"",", damage: '"&V14&"'","")&IF(X14<>"",", capacity: '"&X14&"'","")&IF(Y14<>"",", growth: "&Y14&"","")&IF(Z14<>"",", cost: '"&Z14&"'","")&", text: '"&SUBSTITUTE(SUBSTITUTE(AE14, CHAR(13), ""),CHAR(10),"\n")&IF(AF14<>"", "', textAdditional: '"&SUBSTITUTE(SUBSTITUTE(AF14, CHAR(13), ""),CHAR(10),"\n"), "")&"', textZh: '"&SUBSTITUTE(SUBSTITUTE(SUBSTITUTE(AG14, CHAR(13), ""),CHAR(10),"\n"),"'","\'")&"', textZhG1: '"&SUBSTITUTE(SUBSTITUTE(SUBSTITUTE(AI14, CHAR(13), ""),CHAR(10),"\n"),"'","\'")&IF(AH14<>"", "', textZhAdditional: '"&SUBSTITUTE(SUBSTITUTE(AH14, CHAR(13), ""),CHAR(10),"\n"), "")&IF(AJ14<>"", "', textZhG1Additional: '"&SUBSTITUTE(SUBSTITUTE(AJ14, CHAR(13), ""),CHAR(10),"\n"), "")&"', textKo: '"&SUBSTITUTE(SUBSTITUTE(SUBSTITUTE(AK14, CHAR(13), ""),CHAR(10),"\n"),"'","\'")&IF(AL14<>"", "', textKoAdditional: '"&SUBSTITUTE(SUBSTITUTE(AL14, CHAR(13), ""),CHAR(10),"\n"), "")&"', textEn: '"&SUBSTITUTE(SUBSTITUTE(SUBSTITUTE(AM14, CHAR(13), ""),CHAR(10),"\n"),"'","\'")&IF(AN14<>"", "', textEnAdditional: '"&SUBSTITUTE(SUBSTITUTE(AN14, CHAR(13), ""),CHAR(10),"\n"), "")&"'"&IF(AB14="○",", sealable: true","")&IF(AC14="○",", removable: true","")&IF(AA14="○",", lie: true","")&IF(AD14="○",", investable: true","")&"},") | AU14: =IF($A14<>"", " /** 《"&$E14&"》 */ export const "&SUBSTITUTE(UPPER(IF(MID($A14, 3, 1)="-", RIGHT($A14,LEN($A14)-3), $A14)), "-", "_")&": TCardId = '"&$A14&"';", "") | AV14: =IF($A15<>"", " | '"&$A15&"'", "")
AT15: =IF(A15="", "","'"&A15&"': {megami: '"&B15&"'"&IF(C15<>"",", anotherID: '"&C15&"', replace: '"&D15&"'","")&", name: '"&SUBSTITUTE(E15,"'","\'")&"', nameEn: '"&SUBSTITUTE(K15,"'","\'")&"', nameZh: '"&SUBSTITUTE(G15,"'","\'")&"', nameZhG1: '"&SUBSTITUTE(H15,"'","\'")&"', nameKo: '"&SUBSTITUTE(J15,"'","\'")&"', ruby: '"&F15&"', rubyEn: '"&L15&IF(I15<>"", "', rubyZh: '"&I15, "")&"', baseType: '"&VLOOKUP(M15,マスタ!$A$1:$B$99,2,0)&"'"&IF(N15="○",", extra: true","")&IF(O15<>"",", extraFrom: '"&O15&"'","")&IF(P15<>"",", exchangableTo: '"&P15&"'","")&IF(Q15="○",", poison: true","")&IF(R15<>"", ", type: '"&VLOOKUP(R15,マスタ!$D$1:$E$99,2,0)&"'", "")&IF(S15<>"",", subType: '"&VLOOKUP(S15,マスタ!$D$1:$E$99,2,0)&"'","")&""&IF(T15<>"",", range: '"&T15&"'","")&IF(V15<>"",", damage: '"&V15&"'","")&IF(X15<>"",", capacity: '"&X15&"'","")&IF(Y15<>"",", growth: "&Y15&"","")&IF(Z15<>"",", cost: '"&Z15&"'","")&", text: '"&SUBSTITUTE(SUBSTITUTE(AE15, CHAR(13), ""),CHAR(10),"\n")&IF(AF15<>"", "', textAdditional: '"&SUBSTITUTE(SUBSTITUTE(AF15, CHAR(13), ""),CHAR(10),"\n"), "")&"', textZh: '"&SUBSTITUTE(SUBSTITUTE(SUBSTITUTE(AG15, CHAR(13), ""),CHAR(10),"\n"),"'","\'")&"', textZhG1: '"&SUBSTITUTE(SUBSTITUTE(SUBSTITUTE(AI15, CHAR(13), ""),CHAR(10),"\n"),"'","\'")&IF(AH15<>"", "', textZhAdditional: '"&SUBSTITUTE(SUBSTITUTE(AH15, CHAR(13), ""),CHAR(10),"\n"), "")&IF(AJ15<>"", "', textZhG1Additional: '"&SUBSTITUTE(SUBSTITUTE(AJ15, CHAR(13), ""),CHAR(10),"\n"), "")&"', textKo: '"&SUBSTITUTE(SUBSTITUTE(SUBSTITUTE(AK15, CHAR(13), ""),CHAR(10),"\n"),"'","\'")&IF(AL15<>"", "', textKoAdditional: '"&SUBSTITUTE(SUBSTITUTE(AL15, CHAR(13), ""),CHAR(10),"\n"), "")&"', textEn: '"&SUBSTITUTE(SUBSTITUTE(SUBSTITUTE(AM15, CHAR(13), ""),CHAR(10),"\n"),"'","\'")&IF(AN15<>"", "', textEnAdditional: '"&SUBSTITUTE(SUBSTITUTE(AN15, CHAR(13), ""),CHAR(10),"\n"), "")&"'"&IF(AB15="○",", sealable: true","")&IF(AC15="○",", removable: true","")&IF(AA15="○",", lie: true","")&IF(AD15="○",", investable: true","")&"},") | AU15: =IF($A15<>"", " /** 《"&$E15&"》 */ export const "&SUBSTITUTE(UPPER(IF(MID($A15, 3, 1)="-", RIGHT($A15,LEN($A15)-3), $A15)), "-", "_")&": TCardId = '"&$A15&"';", "") | AV15: =IF($A16<>"", " | '"&$A16&"'", "")
AT16: =IF(A16="", "","'"&A16&"': {megami: '"&B16&"'"&IF(C16<>"",", anotherID: '"&C16&"', replace: '"&D16&"'","")&", name: '"&SUBSTITUTE(E16,"'","\'")&"', nameEn: '"&SUBSTITUTE(K16,"'","\'")&"', nameZh: '"&SUBSTITUTE(G16,"'","\'")&"', nameZhG1: '"&SUBSTITUTE(H16,"'","\'")&"', nameKo: '"&SUBSTITUTE(J16,"'","\'")&"', ruby: '"&F16&"', rubyEn: '"&L16&IF(I16<>"", "', rubyZh: '"&I16, "")&"', baseType: '"&VLOOKUP(M16,マスタ!$A$1:$B$99,2,0)&"'"&IF(N16="○",", extra: true","")&IF(O16<>"",", extraFrom: '"&O16&"'","")&IF(P16<>"",", exchangableTo: '"&P16&"'","")&IF(Q16="○",", poison: true","")&IF(R16<>"", ", type: '"&VLOOKUP(R16,マスタ!$D$1:$E$99,2,0)&"'", "")&IF(S16<>"",", subType: '"&VLOOKUP(S16,マスタ!$D$1:$E$99,2,0)&"'","")&""&IF(T16<>"",", range: '"&T16&"'","")&IF(V16<>"",", damage: '"&V16&"'","")&IF(X16<>"",", capacity: '"&X16&"'","")&IF(Y16<>"",", growth: "&Y16&"","")&IF(Z16<>"",", cost: '"&Z16&"'","")&", text: '"&SUBSTITUTE(SUBSTITUTE(AE16, CHAR(13), ""),CHAR(10),"\n")&IF(AF16<>"", "', textAdditional: '"&SUBSTITUTE(SUBSTITUTE(AF16, CHAR(13), ""),CHAR(10),"\n"), "")&"', textZh: '"&SUBSTITUTE(SUBSTITUTE(SUBSTITUTE(AG16, CHAR(13), ""),CHAR(10),"\n"),"'","\'")&"', textZhG1: '"&SUBSTITUTE(SUBSTITUTE(SUBSTITUTE(AI16, CHAR(13), ""),CHAR(10),"\n"),"'","\'")&IF(AH16<>"", "', textZhAdditional: '"&SUBSTITUTE(SUBSTITUTE(AH16, CHAR(13), ""),CHAR(10),"\n"), "")&IF(AJ16<>"", "', textZhG1Additional: '"&SUBSTITUTE(SUBSTITUTE(AJ16, CHAR(13), ""),CHAR(10),"\n"), "")&"', textKo: '"&SUBSTITUTE(SUBSTITUTE(SUBSTITUTE(AK16, CHAR(13), ""),CHAR(10),"\n"),"'","\'")&IF(AL16<>"", "', textKoAdditional: '"&SUBSTITUTE(SUBSTITUTE(AL16, CHAR(13), ""),CHAR(10),"\n"), "")&"', textEn: '"&SUBSTITUTE(SUBSTITUTE(SUBSTITUTE(AM16, CHAR(13), ""),CHAR(10),"\n"),"'","\'")&IF(AN16<>"", "', textEnAdditional: '"&SUBSTITUTE(SUBSTITUTE(AN16, CHAR(13), ""),CHAR(10),"\n"), "")&"'"&IF(AB16="○",", sealable: true","")&IF(AC16="○",", removable: true","")&IF(AA16="○",", lie: true","")&IF(AD16="○",", investable: true","")&"},") | AU16: =IF($A16<>"", " /** 《"&$E16&"》 */ export const "&SUBSTITUTE(UPPER(IF(MID($A16, 3, 1)="-", RIGHT($A16,LEN($A16)-3), $A16)), "-", "_")&": TCardId = '"&$A16&"';", "") | AV16: =IF($A17<>"", " | '"&$A17&"'", "")
AT17: =IF(A17="", "","'"&A17&"': {megami: '"&B17&"'"&IF(C17<>"",", anotherID: '"&C17&"', replace: '"&D17&"'","")&", name: '"&SUBSTITUTE(E17,"'","\'")&"', nameEn: '"&SUBSTITUTE(K17,"'","\'")&"', nameZh: '"&SUBSTITUTE(G17,"'","\'")&"', nameZhG1: '"&SUBSTITUTE(H17,"'","\'")&"', nameKo: '"&SUBSTITUTE(J17,"'","\'")&"', ruby: '"&F17&"', rubyEn: '"&L17&IF(I17<>"", "', rubyZh: '"&I17, "")&"', baseType: '"&VLOOKUP(M17,マスタ!$A$1:$B$99,2,0)&"'"&IF(N17="○",", extra: true","")&IF(O17<>"",", extraFrom: '"&O17&"'","")&IF(P17<>"",", exchangableTo: '"&P17&"'","")&IF(Q17="○",", poison: true","")&IF(R17<>"", ", type: '"&VLOOKUP(R17,マスタ!$D$1:$E$99,2,0)&"'", "")&IF(S17<>"",", subType: '"&VLOOKUP(S17,マスタ!$D$1:$E$99,2,0)&"'","")&""&IF(T17<>"",", range: '"&T17&"'","")&IF(V17<>"",", damage: '"&V17&"'","")&IF(X17<>"",", capacity: '"&X17&"'","")&IF(Y17<>"",", growth: "&Y17&"","")&IF(Z17<>"",", cost: '"&Z17&"'","")&", text: '"&SUBSTITUTE(SUBSTITUTE(AE17, CHAR(13), ""),CHAR(10),"\n")&IF(AF17<>"", "', textAdditional: '"&SUBSTITUTE(SUBSTITUTE(AF17, CHAR(13), ""),CHAR(10),"\n"), "")&"', textZh: '"&SUBSTITUTE(SUBSTITUTE(SUBSTITUTE(AG17, CHAR(13), ""),CHAR(10),"\n"),"'","\'")&"', textZhG1: '"&SUBSTITUTE(SUBSTITUTE(SUBSTITUTE(AI17, CHAR(13), ""),CHAR(10),"\n"),"'","\'")&IF(AH17<>"", "', textZhAdditional: '"&SUBSTITUTE(SUBSTITUTE(AH17, CHAR(13), ""),CHAR(10),"\n"), "")&IF(AJ17<>"", "', textZhG1Additional: '"&SUBSTITUTE(SUBSTITUTE(AJ17, CHAR(13), ""),CHAR(10),"\n"), "")&"', textKo: '"&SUBSTITUTE(SUBSTITUTE(SUBSTITUTE(AK17, CHAR(13), ""),CHAR(10),"\n"),"'","\'")&IF(AL17<>"", "', textKoAdditional: '"&SUBSTITUTE(SUBSTITUTE(AL17, CHAR(13), ""),CHAR(10),"\n"), "")&"', textEn: '"&SUBSTITUTE(SUBSTITUTE(SUBSTITUTE(AM17, CHAR(13), ""),CHAR(10),"\n"),"'","\'")&IF(AN17<>"", "', textEnAdditional: '"&SUBSTITUTE(SUBSTITUTE(AN17, CHAR(13), ""),CHAR(10),"\n"), "")&"'"&IF(AB17="○",", sealable: true","")&IF(AC17="○",", removable: true","")&IF(AA17="○",", lie: true","")&IF(AD17="○",", investable: true","")&"},") | AU17: =IF($A17<>"", " /** 《"&$E17&"》 */ export const "&SUBSTITUTE(UPPER(IF(MID($A17, 3, 1)="-", RIGHT($A17,LEN($A17)-3), $A17)), "-", "_")&": TCardId = '"&$A17&"';", "") | AV17: =IF($A18<>"", " | '"&$A18&"'", "")
AT18: =IF(A18="", "","'"&A18&"': {megami: '"&B18&"'"&IF(C18<>"",", anotherID: '"&C18&"', replace: '"&D18&"'","")&", name: '"&SUBSTITUTE(E18,"'","\'")&"', nameEn: '"&SUBSTITUTE(K18,"'","\'")&"', nameZh: '"&SUBSTITUTE(G18,"'","\'")&"', nameZhG1: '"&SUBSTITUTE(H18,"'","\'")&"', nameKo: '"&SUBSTITUTE(J18,"'","\'")&"', ruby: '"&F18&"', rubyEn: '"&L18&IF(I18<>"", "', rubyZh: '"&I18, "")&"', baseType: '"&VLOOKUP(M18,マスタ!$A$1:$B$99,2,0)&"'"&IF(N18="○",", extra: true","")&IF(O18<>"",", extraFrom: '"&O18&"'","")&IF(P18<>"",", exchangableTo: '"&P18&"'","")&IF(Q18="○",", poison: true","")&IF(R18<>"", ", type: '"&VLOOKUP(R18,マスタ!$D$1:$E$99,2,0)&"'", "")&IF(S18<>"",", subType: '"&VLOOKUP(S18,マスタ!$D$1:$E$99,2,0)&"'","")&""&IF(T18<>"",", range: '"&T18&"'","")&IF(V18<>"",", damage: '"&V18&"'","")&IF(X18<>"",", capacity: '"&X18&"'","")&IF(Y18<>"",", growth: "&Y18&"","")&IF(Z18<>"",", cost: '"&Z18&"'","")&", text: '"&SUBSTITUTE(SUBSTITUTE(AE18, CHAR(13), ""),CHAR(10),"\n")&IF(AF18<>"", "', textAdditional: '"&SUBSTITUTE(SUBSTITUTE(AF18, CHAR(13), ""),CHAR(10),"\n"), "")&"', textZh: '"&SUBSTITUTE(SUBSTITUTE(SUBSTITUTE(AG18, CHAR(13), ""),CHAR(10),"\n"),"'","\'")&"', textZhG1: '"&SUBSTITUTE(SUBSTITUTE(SUBSTITUTE(AI18, CHAR(13), ""),CHAR(10),"\n"),"'","\'")&IF(AH18<>"", "', textZhAdditional: '"&SUBSTITUTE(SUBSTITUTE(AH18, CHAR(13), ""),CHAR(10),"\n"), "")&IF(AJ18<>"", "', textZhG1Additional: '"&SUBSTITUTE(SUBSTITUTE(AJ18, CHAR(13), ""),CHAR(10),"\n"), "")&"', textKo: '"&SUBSTITUTE(SUBSTITUTE(SUBSTITUTE(AK18, CHAR(13), ""),CHAR(10),"\n"),"'","\'")&IF(AL18<>"", "', textKoAdditional: '"&SUBSTITUTE(SUBSTITUTE(AL18, CHAR(13), ""),CHAR(10),"\n"), "")&"', textEn: '"&SUBSTITUTE(SUBSTITUTE(SUBSTITUTE(AM18, CHAR(13), ""),CHAR(10),"\n"),"'","\'")&IF(AN18<>"", "', textEnAdditional: '"&SUBSTITUTE(SUBSTITUTE(AN18, CHAR(13), ""),CHAR(10),"\n"), "")&"'"&IF(AB18="○",", sealable: true","")&IF(AC18="○",", removable: true","")&IF(AA18="○",", lie: true","")&IF(AD18="○",", investable: true","")&"},") | AU18: =IF($A18<>"", " /** 《"&$E18&"》 */ export const "&SUBSTITUTE(UPPER(IF(MID($A18, 3, 1)="-", RIGHT($A18,LEN($A18)-3), $A18)), "-", "_")&": TCardId = '"&$A18&"';", "") | AV18: =IF($A19<>"", " | '"&$A19&"'", "")
AT19: =IF(A19="", "","'"&A19&"': {megami: '"&B19&"'"&IF(C19<>"",", anotherID: '"&C19&"', replace: '"&D19&"'","")&", name: '"&SUBSTITUTE(E19,"'","\'")&"', nameEn: '"&SUBSTITUTE(K19,"'","\'")&"', nameZh: '"&SUBSTITUTE(G19,"'","\'")&"', nameZhG1: '"&SUBSTITUTE(H19,"'","\'")&"', nameKo: '"&SUBSTITUTE(J19,"'","\'")&"', ruby: '"&F19&"', rubyEn: '"&L19&IF(I19<>"", "', rubyZh: '"&I19, "")&"', baseType: '"&VLOOKUP(M19,マスタ!$A$1:$B$99,2,0)&"'"&IF(N19="○",", extra: true","")&IF(O19<>"",", extraFrom: '"&O19&"'","")&IF(P19<>"",", exchangableTo: '"&P19&"'","")&IF(Q19="○",", poison: true","")&IF(R19<>"", ", type: '"&VLOOKUP(R19,マスタ!$D$1:$E$99,2,0)&"'", "")&IF(S19<>"",", subType: '"&VLOOKUP(S19,マスタ!$D$1:$E$99,2,0)&"'","")&""&IF(T19<>"",", range: '"&T19&"'","")&IF(V19<>"",", damage: '"&V19&"'","")&IF(X19<>"",", capacity: '"&X19&"'","")&IF(Y19<>"",", growth: "&Y19&"","")&IF(Z19<>"",", cost: '"&Z19&"'","")&", text: '"&SUBSTITUTE(SUBSTITUTE(AE19, CHAR(13), ""),CHAR(10),"\n")&IF(AF19<>"", "', textAdditional: '"&SUBSTITUTE(SUBSTITUTE(AF19, CHAR(13), ""),CHAR(10),"\n"), "")&"', textZh: '"&SUBSTITUTE(SUBSTITUTE(SUBSTITUTE(AG19, CHAR(13), ""),CHAR(10),"\n"),"'","\'")&"', textZhG1: '"&SUBSTITUTE(SUBSTITUTE(SUBSTITUTE(AI19, CHAR(13), ""),CHAR(10),"\n"),"'","\'")&IF(AH19<>"", "', textZhAdditional: '"&SUBSTITUTE(SUBSTITUTE(AH19, CHAR(13), ""),CHAR(10),"\n"), "")&IF(AJ19<>"", "', textZhG1Additional: '"&SUBSTITUTE(SUBSTITUTE(AJ19, CHAR(13), ""),CHAR(10),"\n"), "")&"', textKo: '"&SUBSTITUTE(SUBSTITUTE(SUBSTITUTE(AK19, CHAR(13), ""),CHAR(10),"\n"),"'","\'")&IF(AL19<>"", "', textKoAdditional: '"&SUBSTITUTE(SUBSTITUTE(AL19, CHAR(13), ""),CHAR(10),"\n"), "")&"', textEn: '"&SUBSTITUTE(SUBSTITUTE(SUBSTITUTE(AM19, CHAR(13), ""),CHAR(10),"\n"),"'","\'")&IF(AN19<>"", "', textEnAdditional: '"&SUBSTITUTE(SUBSTITUTE(AN19, CHAR(13), ""),CHAR(10),"\n"), "")&"'"&IF(AB19="○",", sealable: true","")&IF(AC19="○",", removable: true","")&IF(AA19="○",", lie: true","")&IF(AD19="○",", investable: true","")&"},") | AU19: =IF($A19<>"", " /** 《"&$E19&"》 */ export const "&SUBSTITUTE(UPPER(IF(MID($A19, 3, 1)="-", RIGHT($A19,LEN($A19)-3), $A19)), "-", "_")&": TCardId = '"&$A19&"';", "") | AV19: =IF($A20<>"", " | '"&$A20&"'", "")
AT20: =IF(A20="", "","'"&A20&"': {megami: '"&B20&"'"&IF(C20<>"",", anotherID: '"&C20&"', replace: '"&D20&"'","")&", name: '"&SUBSTITUTE(E20,"'","\'")&"', nameEn: '"&SUBSTITUTE(K20,"'","\'")&"', nameZh: '"&SUBSTITUTE(G20,"'","\'")&"', nameZhG1: '"&SUBSTITUTE(H20,"'","\'")&"', nameKo: '"&SUBSTITUTE(J20,"'","\'")&"', ruby: '"&F20&"', rubyEn: '"&L20&IF(I20<>"", "', rubyZh: '"&I20, "")&"', baseType: '"&VLOOKUP(M20,マスタ!$A$1:$B$99,2,0)&"'"&IF(N20="○",", extra: true","")&IF(O20<>"",", extraFrom: '"&O20&"'","")&IF(P20<>"",", exchangableTo: '"&P20&"'","")&IF(Q20="○",", poison: true","")&IF(R20<>"", ", type: '"&VLOOKUP(R20,マスタ!$D$1:$E$99,2,0)&"'", "")&IF(S20<>"",", subType: '"&VLOOKUP(S20,マスタ!$D$1:$E$99,2,0)&"'","")&""&IF(T20<>"",", range: '"&T20&"'","")&IF(V20<>"",", damage: '"&V20&"'","")&IF(X20<>"",", capacity: '"&X20&"'","")&IF(Y20<>"",", growth: "&Y20&"","")&IF(Z20<>"",", cost: '"&Z20&"'","")&", text: '"&SUBSTITUTE(SUBSTITUTE(AE20, CHAR(13), ""),CHAR(10),"\n")&IF(AF20<>"", "', textAdditional: '"&SUBSTITUTE(SUBSTITUTE(AF20, CHAR(13), ""),CHAR(10),"\n"), "")&"', textZh: '"&SUBSTITUTE(SUBSTITUTE(SUBSTITUTE(AG20, CHAR(13), ""),CHAR(10),"\n"),"'","\'")&"', textZhG1: '"&SUBSTITUTE(SUBSTITUTE(SUBSTITUTE(AI20, CHAR(13), ""),CHAR(10),"\n"),"'","\'")&IF(AH20<>"", "', textZhAdditional: '"&SUBSTITUTE(SUBSTITUTE(AH20, CHAR(13), ""),CHAR(10),"\n"), "")&IF(AJ20<>"", "', textZhG1Additional: '"&SUBSTITUTE(SUBSTITUTE(AJ20, CHAR(13), ""),CHAR(10),"\n"), "")&"', textKo: '"&SUBSTITUTE(SUBSTITUTE(SUBSTITUTE(AK20, CHAR(13), ""),CHAR(10),"\n"),"'","\'")&IF(AL20<>"", "', textKoAdditional: '"&SUBSTITUTE(SUBSTITUTE(AL20, CHAR(13), ""),CHAR(10),"\n"), "")&"', textEn: '"&SUBSTITUTE(SUBSTITUTE(SUBSTITUTE(AM20, CHAR(13), ""),CHAR(10),"\n"),"'","\'")&IF(AN20<>"", "', textEnAdditional: '"&SUBSTITUTE(SUBSTITUTE(AN20, CHAR(13), ""),CHAR(10),"\n"), "")&"'"&IF(AB20="○",", sealable: true","")&IF(AC20="○",", removable: true","")&IF(AA20="○",", lie: true","")&IF(AD20="○",", investable: true","")&"},") | AU20: =IF($A20<>"", " /** 《"&$E20&"》 */ export const "&SUBSTITUTE(UPPER(IF(MID($A20, 3, 1)="-", RIGHT($A20,LEN($A20)-3), $A20)), "-", "_")&": TCardId = '"&$A20&"';", "") | AV20: =IF($A21<>"", " | '"&$A21&"'", "")
AT21: =IF(A21="", "","'"&A21&"': {megami: '"&B21&"'"&IF(C21<>"",", anotherID: '"&C21&"', replace: '"&D21&"'","")&", name: '"&SUBSTITUTE(E21,"'","\'")&"', nameEn: '"&SUBSTITUTE(K21,"'","\'")&"', nameZh: '"&SUBSTITUTE(G21,"'","\'")&"', nameZhG1: '"&SUBSTITUTE(H21,"'","\'")&"', nameKo: '"&SUBSTITUTE(J21,"'","\'")&"', ruby: '"&F21&"', rubyEn: '"&L21&IF(I21<>"", "', rubyZh: '"&I21, "")&"', baseType: '"&VLOOKUP(M21,マスタ!$A$1:$B$99,2,0)&"'"&IF(N21="○",", extra: true","")&IF(O21<>"",", extraFrom: '"&O21&"'","")&IF(P21<>"",", exchangableTo: '"&P21&"'","")&IF(Q21="○",", poison: true","")&IF(R21<>"", ", type: '"&VLOOKUP(R21,マスタ!$D$1:$E$99,2,0)&"'", "")&IF(S21<>"",", subType: '"&VLOOKUP(S21,マスタ!$D$1:$E$99,2,0)&"'","")&""&IF(T21<>"",", range: '"&T21&"'","")&IF(V21<>"",", damage: '"&V21&"'","")&IF(X21<>"",", capacity: '"&X21&"'","")&IF(Y21<>"",", growth: "&Y21&"","")&IF(Z21<>"",", cost: '"&Z21&"'","")&", text: '"&SUBSTITUTE(SUBSTITUTE(AE21, CHAR(13), ""),CHAR(10),"\n")&IF(AF21<>"", "', textAdditional: '"&SUBSTITUTE(SUBSTITUTE(AF21, CHAR(13), ""),CHAR(10),"\n"), "")&"', textZh: '"&SUBSTITUTE(SUBSTITUTE(SUBSTITUTE(AG21, CHAR(13), ""),CHAR(10),"\n"),"'","\'")&"', textZhG1: '"&SUBSTITUTE(SUBSTITUTE(SUBSTITUTE(AI21, CHAR(13), ""),CHAR(10),"\n"),"'","\'")&IF(AH21<>"", "', textZhAdditional: '"&SUBSTITUTE(SUBSTITUTE(AH21, CHAR(13), ""),CHAR(10),"\n"), "")&IF(AJ21<>"", "', textZhG1Additional: '"&SUBSTITUTE(SUBSTITUTE(AJ21, CHAR(13), ""),CHAR(10),"\n"), "")&"', textKo: '"&SUBSTITUTE(SUBSTITUTE(SUBSTITUTE(AK21, CHAR(13), ""),CHAR(10),"\n"),"'","\'")&IF(AL21<>"", "', textKoAdditional: '"&SUBSTITUTE(SUBSTITUTE(AL21, CHAR(13), ""),CHAR(10),"\n"), "")&"', textEn: '"&SUBSTITUTE(SUBSTITUTE(SUBSTITUTE(AM21, CHAR(13), ""),CHAR(10),"\n"),"'","\'")&IF(AN21<>"", "', textEnAdditional: '"&SUBSTITUTE(SUBSTITUTE(AN21, CHAR(13), ""),CHAR(10),"\n"), "")&"'"&IF(AB21="○",", sealable: true","")&IF(AC21="○",", removable: true","")&IF(AA21="○",", lie: true","")&IF(AD21="○",", investable: true","")&"},") | AU21: =IF($A21<>"", " /** 《"&$E21&"》 */ export const "&SUBSTITUTE(UPPER(IF(MID($A21, 3, 1)="-", RIGHT($A21,LEN($A21)-3), $A21)), "-", "_")&": TCardId = '"&$A21&"';", "") | AV21: =IF($A22<>"", " | '"&$A22&"'", "")
