Workbook

Sheet 新幕シーズン2
A1: カードID | B1: メガミ | C1: アナザーID | D1: 置換元カード | E1: 名前 | F1: ふりがな | G1: 名前（中国語） | H1: 名前（中国語G1） | I1: ふりがな（中国語） | J1: 名前（韓国語） | K1: 名前（英語） | L1: ふりがな（英語） | M1: 種別 | N1: 追加札 | O1: 追加元カード | P1: 交換先 | Q1: 毒 | R1: タイプ | S1: サブタイプ | T1: 適正距離 | U1: （開） | V1: ダメージ | W1: （開） | X1: 納 | Y1: 消費 | Z1: 封印 | AA1: 取り除く | AB1: テキスト | AC1: テキスト補足 | AD1: テキスト（中国語） | AE1: テキスト補足（中国語） | AF1: テキスト（中国語G1） | AG1: テキスト（韓国語） | AH1: テキスト（英語） | AI1: （開） | AJ1: （開）（中国語） | AK1: （開）（中国語G1） | AL1: （開）（韓国語） | AM1: （開）（英語）
A2: 01-yurina-o-n-1 | B2: yurina | E2: 斬 | F2: ざん | G2: 斩 | H2: 斩 | J2: 참 | K2: Slash | M2: 通常札 | R2: 攻撃 | T2: 3-4 | V2: 3/1 | AN2: =IF(A2="", "", IF(ROW()>=3, ", ", "")&"'"&A2&"': {megami: '"&B2&"'"&IF(C2<>"",", anotherID: '"&C2&"', replace: '"&D2&"'","")&", name: '"&SUBSTITUTE(E2,"'","\'")&"', nameEn: '"&SUBSTITUTE(K2,"'","\'")&"', nameZh: '"&SUBSTITUTE(G2,"'","\'")&"', nameZhG1: '"&SUBSTITUTE(H2,"'","\'")&"', nameKo: '"&SUBSTITUTE(J2,"'","\'")&"', ruby: '"&F2&"', rubyEn: '"&L2&IF(I2<>"", "', rubyZh: '"&I2, "")&"', baseType: '"&VLOOKUP(M2,マスタ!$A$1:$B$99,2,0)&"'"&IF(N2="○",", extra: true","")&IF(O2<>"",", extraFrom: '"&O2&"'","")&IF(P2<>"",", exchangableTo: '"&P2&"'","")&IF(Q2="○",", poison: true","")&IF(R2<>"", ", type: '"&VLOOKUP(R2,マスタ!$D$1:$E$99,2,0)&"'", "")&IF(S2<>"",", subType: '"&VLOOKUP(S2,マスタ!$D$1:$E$99,2,0)&"'","")&IF(T2<>"",", range: '"&T2&"'","")&IF(V2<>"",", damage: '"&V2&"'","")&IF(X2<>"",", capacity: '"&X2&"'","")&IF(Y2<>"",", cost: '"&Y2&"'","")&", text: '"&SUBSTITUTE(SUBSTITUTE(AB2, CHAR(13), ""),CHAR(10),"\n")&IF(AC2<>"", "', textAdditional: '"&SUBSTITUTE(SUBSTITUTE(AC2, CHAR(13), ""),CHAR(10),"\n"), "")&"', textZh: '"&SUBSTITUTE(SUBSTITUTE(SUBSTITUTE(AD2, CHAR(13), ""),CHAR(10),"\n"),"'","\'")&"', textZhG1: '"&SUBSTITUTE(SUBSTITUTE(SUBSTITUTE(AF2, CHAR(13), ""),CHAR(10),"\n"),"'","\'")&IF(AE2<>"", "', textZhAdditional: '"&SUBSTITUTE(SUBSTITUTE(AE2, CHAR(13), ""),CHAR(10),"\n"), "")&"', textKo: '"&SUBSTITUTE(SUBSTITUTE(SUBSTITUTE(AG2, CHAR(13), ""),CHAR(10),"\n"),"'","\'")&"', textEn: '"&SUBSTITUTE(SUBSTITUTE(SUBSTITUTE(AH2, CHAR(13), ""),CHAR(10),"\n"),"'","\'")&"'"&IF(Z2="○",", sealable: true","")&IF(AA2="○",", removable: true","")&"}") -> '01-yurina-o-n-1': {megami: 'yurina', name: '斬', nameEn: 'Slash', nameZh: '斩', nameZhG1: '斩', nameKo: '참', ruby: 'ざん', rubyEn: '', baseType: 'normal', type: 'attack', range: '3-4', damage: '3/1', text: '', textZh: '', textZhG1: '', textKo: '', textEn: ''} | AO2: =IF($A2<>"", " /** 《"&$E2&"》 */ export const "&SUBSTITUTE(UPPER(IF(MID($A2, 3, 1)="-", RIGHT($A2,LEN($A2)-3), $A2)), "-", "_")&": TCardId = '"&$A2&"';", "") -> /** 《斬》 */ export const YURINA_O_N_1: TCardId = '01-yurina-o-n-1'; | AP2: =IF($A2<>"", " | '"&$A2&"'", "") -> | '01-yurina-o-n-1'
A3: 01-yurina-A1-n-1 | B3: yurina | C3: A1 | D3: 01-yurina-o-n-1 | E3: 乱打 | F3: らんだ | G3: 乱打 | H3: 乱打 | J3: 난타 | K3: Wild Swing | M3: 通常札 | R3: 攻撃 | T3: 2 | V3: 2/1 | AB3: 【常時】決死-あなたのライフが3以下ならば、この《攻撃》は+0/+2となり、対応不可を得る。 | AD3: 【常时】决死～若自命中的樱花结晶数小于等于3，则此《攻击》得+0/+2和不可被对应。 | AF3: 【常时】决死-若自命中的樱花结晶的数目小于3，则此《攻击》得+0/+2和不可被对应。 | AG3: 【상시】결사-당신의 라이프가 3 이하라면, 이 《공격》은 +0/+2가 되고, 대응불가를 얻는다. | AH3: Forced: Resolve - If your Life is 3 or less, this attack gains +0/+2 and No Reactions. | AN3: =IF(A3="", "", IF(ROW()>=3, ", ", "")&"'"&A3&"': {megami: '"&B3&"'"&IF(C3<>"",", anotherID: '"&C3&"', replace: '"&D3&"'","")&", name: '"&SUBSTITUTE(E3,"'","\'")&"', nameEn: '"&SUBSTITUTE(K3,"'","\'")&"', nameZh: '"&SUBSTITUTE(G3,"'","\'")&"', nameZhG1: '"&SUBSTITUTE(H3,"'","\'")&"', nameKo: '"&SUBSTITUTE(J3,"'","\'")&"', ruby: '"&F3&"', rubyEn: '"&L3&IF(I3<>"", "', rubyZh: '"&I3, "")&"', baseType: '"&VLOOKUP(M3,マスタ!$A$1:$B$99,2,0)&"'"&IF(N3="○",", extra: true","")&IF(O3<>"",", extraFrom: '"&O3&"'","")&IF(P3<>"",", exchangableTo: '"&P3&"'","")&IF(Q3="○",", poison: true","")&IF(R3<>"", ", type: '"&VLOOKUP(R3,マスタ!$D$1:$E$99,2,0)&"'", "")&IF(S3<>"",", subType: '"&VLOOKUP(S3,マスタ!$D$1:$E$99,2,0)&"'","")&IF(T3<>"",", range: '"&T3&"'","")&IF(V3<>"",", damage: '"&V3&"'","")&IF(X3<>"",", capacity: '"&X3&"'","")&IF(Y3<>"",", cost: '"&Y3&"'","")&", text: '"&SUBSTITUTE(SUBSTITUTE(AB3, CHAR(13), ""),CHAR(10),"\n")&IF(AC3<>"", "', textAdditional: '"&SUBSTITUTE(SUBSTITUTE(AC3, CHAR(13), ""),CHAR(10),"\n"), "")&"', textZh: '"&SUBSTITUTE(SUBSTITUTE(SUBSTITUTE(AD3, CHAR(13), ""),CHAR(10),"\n"),"'","\'")&"', textZhG1: '"&SUBSTITUTE(SUBSTITUTE(SUBSTITUTE(AF3, CHAR(13), ""),CHAR(10),"\n"),"'","\'")&IF(AE3<>"", "', textZhAdditional: '"&SUBSTITUTE(SUBSTITUTE(AE3, CHAR(13), ""),CHAR(10),"\n"), "")&"', textKo: '"&SUBSTITUTE(SUBSTITUTE(SUBSTITUTE(AG3, CHAR(13), ""),CHAR(10),"\n"),"'","\'")&"', textEn: '"&SUBSTITUTE(SUBSTITUTE(SUBSTITUTE(AH3, CHAR(13), ""),CHAR(10),"\n"),"'","\'")&"'"&IF(Z3="○",", sealable: true","")&IF(AA3="○",", removable: true","")&"}") -> , '01-yurina-A1-n-1': {megami: 'yurina', anotherID: 'A1', replace: '01-yurina-o-n-1', name: '乱打', nameEn: 'Wild Swing', nameZh: '乱打', nameZhG1: '乱打', nameKo: '난타', ruby: 'らんだ', rubyEn: '', baseType: 'normal', type: 'attack', range: '2', damage: '2/1', text: '【常時】決死-あなたのライフが3以下ならば、この《攻撃》は+0/+2となり、対応不可を得る。', textZh: '【常时】决死～若自命中的樱花结晶数小于等于3，则此《攻击》得+0/+2和不可被对应。', textZhG1: '【常时】决死-若自命中的樱花结晶的数目小于3，则此《攻击》得+0/+2和不可被对应。', textKo: '【상시】결사-당신의 라이프가 3 이하라면, 이 《공격》은 +0/+2가 되고, 대응불가를 얻는다.', textEn: 'Forced: Resolve - If your Life is 3 or less, this attack gains +0/+2 and No Reactions.'} | AO3: =IF($A3<>"", " /** 《"&$E3&"》 */ export const "&SUBSTITUTE(UPPER(IF(MID($A3, 3, 1)="-", RIGHT($A3,LEN($A3)-3), $A3)), "-", "_")&": TCardId = '"&$A3&"';", "") -> /** 《乱打》 */ export const YURINA_A1_N_1: TCardId = '01-yurina-A1-n-1'; | AP3: =IF($A3<>"", " | '"&$A3&"'", "") -> | '01-yurina-A1-n-1'
A4: 01-yurina-o-n-2 | B4: yurina | E4: 一閃 | F4: いっせん | G4: 一闪 | H4: 一闪 | J4: 일섬 | K4: Brandish | M4: 通常札 | R4: 攻撃 | T4: 3 | V4: 2/2 | AB4: 【常時】決死-あなたのライフが3以下ならば、この《攻撃》は+1/+0となる。 | AD4: 【常时】决死～若自命中的樱花结晶数小于等于3，则此《攻击》得+1/+0。 | AF4: 【常时】决死-若自命中的樱花结晶的数目小于3，则此《攻击》得+1/+0。 | AG4: 【상시】결사-당신의 라이프가 3 이하라면, 이 《공격》은 +1/+0이 된다. | AH4: Forced: Resolve - This attack gains +1/+0 if your Life is 3 or less. | AN4: =IF(A4="", "", IF(ROW()>=3, ", ", "")&"'"&A4&"': {megami: '"&B4&"'"&IF(C4<>"",", anotherID: '"&C4&"', replace: '"&D4&"'","")&", name: '"&SUBSTITUTE(E4,"'","\'")&"', nameEn: '"&SUBSTITUTE(K4,"'","\'")&"', nameZh: '"&SUBSTITUTE(G4,"'","\'")&"', nameZhG1: '"&SUBSTITUTE(H4,"'","\'")&"', nameKo: '"&SUBSTITUTE(J4,"'","\'")&"', ruby: '"&F4&"', rubyEn: '"&L4&IF(I4<>"", "', rubyZh: '"&I4, "")&"', baseType: '"&VLOOKUP(M4,マスタ!$A$1:$B$99,2,0)&"'"&IF(N4="○",", extra: true","")&IF(O4<>"",", extraFrom: '"&O4&"'","")&IF(P4<>"",", exchangableTo: '"&P4&"'","")&IF(Q4="○",", poison: true","")&IF(R4<>"", ", type: '"&VLOOKUP(R4,マスタ!$D$1:$E$99,2,0)&"'", "")&IF(S4<>"",", subType: '"&VLOOKUP(S4,マスタ!$D$1:$E$99,2,0)&"'","")&IF(T4<>"",", range: '"&T4&"'","")&IF(V4<>"",", damage: '"&V4&"'","")&IF(X4<>"",", capacity: '"&X4&"'","")&IF(Y4<>"",", cost: '"&Y4&"'","")&", text: '"&SUBSTITUTE(SUBSTITUTE(AB4, CHAR(13), ""),CHAR(10),"\n")&IF(AC4<>"", "', textAdditional: '"&SUBSTITUTE(SUBSTITUTE(AC4, CHAR(13), ""),CHAR(10),"\n"), "")&"', textZh: '"&SUBSTITUTE(SUBSTITUTE(SUBSTITUTE(AD4, CHAR(13), ""),CHAR(10),"\n"),"'","\'")&"', textZhG1: '"&SUBSTITUTE(SUBSTITUTE(SUBSTITUTE(AF4, CHAR(13), ""),CHAR(10),"\n"),"'","\'")&IF(AE4<>"", "', textZhAdditional: '"&SUBSTITUTE(SUBSTITUTE(AE4, CHAR(13), ""),CHAR(10),"\n"), "")&"', textKo: '"&SUBSTITUTE(SUBSTITUTE(SUBSTITUTE(AG4, CHAR(13), ""),CHAR(10),"\n"),"'","\'")&"', textEn: '"&SUBSTITUTE(SUBSTITUTE(SUBSTITUTE(AH4, CHAR(13), ""),CHAR(10),"\n"),"'","\'")&"'"&IF(Z4="○",", sealable: true","")&IF(AA4="○",", removable: true","")&"}") -> , '01-yurina-o-n-2': {megami: 'yurina', name: '一閃', nameEn: 'Brandish', nameZh: '一闪', nameZhG1: '一闪', nameKo: '일섬', ruby: 'いっせん', rubyEn: '', baseType: 'normal', type: 'attack', range: '3', damage: '2/2', text: '【常時】決死-あなたのライフが3以下ならば、この《攻撃》は+1/+0となる。', textZh: '【常时】决死～若自命中的樱花结晶数小于等于3，则此《攻击》得+1/+0。', textZhG1: '【常时】决死-若自命中的樱花结晶的数目小于3，则此《攻击》得+1/+0。', textKo: '【상시】결사-당신의 라이프가 3 이하라면, 이 《공격》은 +1/+0이 된다.', textEn: 'Forced: Resolve - This attack gains +1/+0 if your Life is 3 or less.'} | AO4: =IF($A4<>"", " /** 《"&$E4&"》 */ export const "&SUBSTITUTE(UPPER(IF(MID($A4, 3, 1)="-", RIGHT($A4,LEN($A4)-3), $A4)), "-", "_")&": TCardId = '"&$A4&"';", "") -> /** 《一閃》 */ export const YURINA_O_N_2: TCardId = '01-yurina-o-n-2'; | AP4: =IF($A4<>"", " | '"&$A4&"'", "") -> | '01-yurina-o-n-2'
A5: 01-yurina-o-n-3 | B5: yurina | E5: 柄打ち | F5: つかうち | G5: 柄击 | H5: 柄击 | J5: 자루치기 | K5: Hilt Strike | M5: 通常札 | R5: 攻撃 | T5: 1-2 | V5: 2/1 | AB5: 【攻撃後】決死-あなたのライフが3以下ならば、このターンにあなたが次に行う《攻撃》は+1/+0となる。 | AD5: 【攻击后】决死～若自命中的樱花结晶数小于等于3，则本回合你的下一次《攻击》得+1/+0。 | AF5: 【攻击后】决死-若自命中的樱花结晶的数目小于3，则本回合你的下一次《攻击》得+1/+0。 | AG5: 【공격후】결사-당신의 라이프가 3 이하라면, 이 턴에 당신이 다음에 행하는 《공격》은 +1/+0이 된다. | AH5: After Attack: Resolve - The next attack you make this turn gains +1/+0 if your Life is 3 or less. | AN5: =IF(A5="", "", IF(ROW()>=3, ", ", "")&"'"&A5&"': {megami: '"&B5&"'"&IF(C5<>"",", anotherID: '"&C5&"', replace: '"&D5&"'","")&", name: '"&SUBSTITUTE(E5,"'","\'")&"', nameEn: '"&SUBSTITUTE(K5,"'","\'")&"', nameZh: '"&SUBSTITUTE(G5,"'","\'")&"', nameZhG1: '"&SUBSTITUTE(H5,"'","\'")&"', nameKo: '"&SUBSTITUTE(J5,"'","\'")&"', ruby: '"&F5&"', rubyEn: '"&L5&IF(I5<>"", "', rubyZh: '"&I5, "")&"', baseType: '"&VLOOKUP(M5,マスタ!$A$1:$B$99,2,0)&"'"&IF(N5="○",", extra: true","")&IF(O5<>"",", extraFrom: '"&O5&"'","")&IF(P5<>"",", exchangableTo: '"&P5&"'","")&IF(Q5="○",", poison: true","")&IF(R5<>"", ", type: '"&VLOOKUP(R5,マスタ!$D$1:$E$99,2,0)&"'", "")&IF(S5<>"",", subType: '"&VLOOKUP(S5,マスタ!$D$1:$E$99,2,0)&"'","")&IF(T5<>"",", range: '"&T5&"'","")&IF(V5<>"",", damage: '"&V5&"'","")&IF(X5<>"",", capacity: '"&X5&"'","")&IF(Y5<>"",", cost: '"&Y5&"'","")&", text: '"&SUBSTITUTE(SUBSTITUTE(AB5, CHAR(13), ""),CHAR(10),"\n")&IF(AC5<>"", "', textAdditional: '"&SUBSTITUTE(SUBSTITUTE(AC5, CHAR(13), ""),CHAR(10),"\n"), "")&"', textZh: '"&SUBSTITUTE(SUBSTITUTE(SUBSTITUTE(AD5, CHAR(13), ""),CHAR(10),"\n"),"'","\'")&"', textZhG1: '"&SUBSTITUTE(SUBSTITUTE(SUBSTITUTE(AF5, CHAR(13), ""),CHAR(10),"\n"),"'","\'")&IF(AE5<>"", "', textZhAdditional: '"&SUBSTITUTE(SUBSTITUTE(AE5, CHAR(13), ""),CHAR(10),"\n"), "")&"', textKo: '"&SUBSTITUTE(SUBSTITUTE(SUBSTITUTE(AG5, CHAR(13), ""),CHAR(10),"\n"),"'","\'")&"', textEn: '"&SUBSTITUTE(SUBSTITUTE(SUBSTITUTE(AH5, CHAR(13), ""),CHAR(10),"\n"),"'","\'")&"'"&IF(Z5="○",", sealable: true","")&IF(AA5="○",", removable: true","")&"}") -> , '01-yurina-o-n-3': {megami: 'yurina', name: '柄打ち', nameEn: 'Hilt Strike', nameZh: '柄击', nameZhG1: '柄击', nameKo: '자루치기', ruby: 'つかうち', rubyEn: '', baseType: 'normal', type: 'attack', range: '1-2', damage: '2/1', text: '【攻撃後】決死-あなたのライフが3以下ならば、このターンにあなたが次に行う《攻撃》は+1/+0となる。', textZh: '【攻击后】决死～若自命中的樱花结晶数小于等于3，则本回合你的下一次《攻击》得+1/+0。', textZhG1: '【攻击后】决死-若自命中的樱花结晶的数目小于3，则本回合你的下一次《攻击》得+1/+0。', textKo: '【공격후】결사-당신의 라이프가 3 이하라면, 이 턴에 당신이 다음에 행하는 《공격》은 +1/+0이 된다.', textEn: 'After Attack: Resolve - The next attack you make this turn gains +1/+0 if your Life is 3 or less.'} | AO5: =IF($A5<>"", " /** 《"&$E5&"》 */ export const "&SUBSTITUTE(UPPER(IF(MID($A5, 3, 1)="-", RIGHT($A5,LEN($A5)-3), $A5)), "-", "_")&": TCardId = '"&$A5&"';", "") -> /** 《柄打ち》 */ export const YURINA_O_N_3: TCardId = '01-yurina-o-n-3'; | AP5: =IF($A5<>"", " | '"&$A5&"'", "") -> | '01-yurina-o-n-3'
A6: 01-yurina-o-n-4 | B6: yurina | E6: 居合 | F6: いあい | G6: 居合 | H6: 居合斩 | J6: 거합 | K6: Art of Drawing | M6: 通常札 | R6: 攻撃 | S6: 全力 | T6: 2-4 | V6: 4/3 | AB6: 【常時】現在の間合が2以下ならば、この攻撃は-1/-1となる。 | AD6: 【常时】若当前距离小于等于2，则此《攻击》得-1/-1。 | AF6: 【常时】若当前距离小于2，则此《攻击》得-1/-1。 | AG6: 【상시】현재 간격이 2 이하라면, 이 공격은 -1/-1이 된다. | AH6: Forced: If the current Distance is 2 or less, this attack gets -1/-1. | AN6: =IF(A6="", "", IF(ROW()>=3, ", ", "")&"'"&A6&"': {megami: '"&B6&"'"&IF(C6<>"",", anotherID: '"&C6&"', replace: '"&D6&"'","")&", name: '"&SUBSTITUTE(E6,"'","\'")&"', nameEn: '"&SUBSTITUTE(K6,"'","\'")&"', nameZh: '"&SUBSTITUTE(G6,"'","\'")&"', nameZhG1: '"&SUBSTITUTE(H6,"'","\'")&"', nameKo: '"&SUBSTITUTE(J6,"'","\'")&"', ruby: '"&F6&"', rubyEn: '"&L6&IF(I6<>"", "', rubyZh: '"&I6, "")&"', baseType: '"&VLOOKUP(M6,マスタ!$A$1:$B$99,2,0)&"'"&IF(N6="○",", extra: true","")&IF(O6<>"",", extraFrom: '"&O6&"'","")&IF(P6<>"",", exchangableTo: '"&P6&"'","")&IF(Q6="○",", poison: true","")&IF(R6<>"", ", type: '"&VLOOKUP(R6,マスタ!$D$1:$E$99,2,0)&"'", "")&IF(S6<>"",", subType: '"&VLOOKUP(S6,マスタ!$D$1:$E$99,2,0)&"'","")&IF(T6<>"",", range: '"&T6&"'","")&IF(V6<>"",", damage: '"&V6&"'","")&IF(X6<>"",", capacity: '"&X6&"'","")&IF(Y6<>"",", cost: '"&Y6&"'","")&", text: '"&SUBSTITUTE(SUBSTITUTE(AB6, CHAR(13), ""),CHAR(10),"\n")&IF(AC6<>"", "', textAdditional: '"&SUBSTITUTE(SUBSTITUTE(AC6, CHAR(13), ""),CHAR(10),"\n"), "")&"', textZh: '"&SUBSTITUTE(SUBSTITUTE(SUBSTITUTE(AD6, CHAR(13), ""),CHAR(10),"\n"),"'","\'")&"', textZhG1: '"&SUBSTITUTE(SUBSTITUTE(SUBSTITUTE(AF6, CHAR(13), ""),CHAR(10),"\n"),"'","\'")&IF(AE6<>"", "', textZhAdditional: '"&SUBSTITUTE(SUBSTITUTE(AE6, CHAR(13), ""),CHAR(10),"\n"), "")&"', textKo: '"&SUBSTITUTE(SUBSTITUTE(SUBSTITUTE(AG6, CHAR(13), ""),CHAR(10),"\n"),"'","\'")&"', textEn: '"&SUBSTITUTE(SUBSTITUTE(SUBSTITUTE(AH6, CHAR(13), ""),CHAR(10),"\n"),"'","\'")&"'"&IF(Z6="○",", sealable: true","")&IF(AA6="○",", removable: true","")&"}") -> , '01-yurina-o-n-4': {megami: 'yurina', name: '居合', nameEn: 'Art of Drawing', nameZh: '居合', nameZhG1: '居合斩', nameKo: '거합', ruby: 'いあい', rubyEn: '', baseType: 'normal', type: 'attack', subType: 'fullpower', range: '2-4', damage: '4/3', text: '【常時】現在の間合が2以下ならば、この攻撃は-1/-1となる。', textZh: '【常时】若当前距离小于等于2，则此《攻击》得-1/-1。', textZhG1: '【常时】若当前距离小于2，则此《攻击》得-1/-1。', textKo: '【상시】현재 간격이 2 이하라면, 이 공격은 -1/-1이 된다.', textEn: 'Forced: If the current Distance is 2 or less, this attack gets -1/-1.'} | AO6: =IF($A6<>"", " /** 《"&$E6&"》 */ export const "&SUBSTITUTE(UPPER(IF(MID($A6, 3, 1)="-", RIGHT($A6,LEN($A6)-3), $A6)), "-", "_")&": TCardId = '"&$A6&"';", "") -> /** 《居合》 */ export const YURINA_O_N_4: TCardId = '01-yurina-o-n-4'; | AP6: =IF($A6<>"", " | '"&$A6&"'", "") -> | '01-yurina-o-n-4'
A7: 01-yurina-o-n-5 | B7: yurina | E7: 足捌き | F7: あしさばき | G7: 运足 | H7: 疾跑 | J7: 발놀림 | K7: Footwork | M7: 通常札 | R7: 行動 | AB7: 現在の間合が4以上ならば、間合→ダスト：2 現在の間合が1以下ならば、ダスト→間合：2 | AD7: 若当前距离大于等于4，则：距→2→虚。 若当前距离小于等于1，则：虚→2→距。 | AF7: 若当前距离大于4，则距（2）→虚。 若当前距离小于1，则虚（2）→距。 | AG7: 현재 간격이 4 이상이라면、간격→더스트：2 현재 간격이 1이하라면, 더스트→간격：2 | AH7: If the current Distance is 4 or more: Distance (2)→ Shadow If the current Distance is 1 or less: Shadow (2)→ Distance | AN7: =IF(A7="", "", IF(ROW()>=3, ", ", "")&"'"&A7&"': {megami: '"&B7&"'"&IF(C7<>"",", anotherID: '"&C7&"', replace: '"&D7&"'","")&", name: '"&SUBSTITUTE(E7,"'","\'")&"', nameEn: '"&SUBSTITUTE(K7,"'","\'")&"', nameZh: '"&SUBSTITUTE(G7,"'","\'")&"', nameZhG1: '"&SUBSTITUTE(H7,"'","\'")&"', nameKo: '"&SUBSTITUTE(J7,"'","\'")&"', ruby: '"&F7&"', rubyEn: '"&L7&IF(I7<>"", "', rubyZh: '"&I7, "")&"', baseType: '"&VLOOKUP(M7,マスタ!$A$1:$B$99,2,0)&"'"&IF(N7="○",", extra: true","")&IF(O7<>"",", extraFrom: '"&O7&"'","")&IF(P7<>"",", exchangableTo: '"&P7&"'","")&IF(Q7="○",", poison: true","")&IF(R7<>"", ", type: '"&VLOOKUP(R7,マスタ!$D$1:$E$99,2,0)&"'", "")&IF(S7<>"",", subType: '"&VLOOKUP(S7,マスタ!$D$1:$E$99,2,0)&"'","")&IF(T7<>"",", range: '"&T7&"'","")&IF(V7<>"",", damage: '"&V7&"'","")&IF(X7<>"",", capacity: '"&X7&"'","")&IF(Y7<>"",", cost: '"&Y7&"'","")&", text: '"&SUBSTITUTE(SUBSTITUTE(AB7, CHAR(13), ""),CHAR(10),"\n")&IF(AC7<>"", "', textAdditional: '"&SUBSTITUTE(SUBSTITUTE(AC7, CHAR(13), ""),CHAR(10),"\n"), "")&"', textZh: '"&SUBSTITUTE(SUBSTITUTE(SUBSTITUTE(AD7, CHAR(13), ""),CHAR(10),"\n"),"'","\'")&"', textZhG1: '"&SUBSTITUTE(SUBSTITUTE(SUBSTITUTE(AF7, CHAR(13), ""),CHAR(10),"\n"),"'","\'")&IF(AE7<>"", "', textZhAdditional: '"&SUBSTITUTE(SUBSTITUTE(AE7, CHAR(13), ""),CHAR(10),"\n"), "")&"', textKo: '"&SUBSTITUTE(SUBSTITUTE(SUBSTITUTE(AG7, CHAR(13), ""),CHAR(10),"\n"),"'","\'")&"', textEn: '"&SUBSTITUTE(SUBSTITUTE(SUBSTITUTE(AH7, CHAR(13), ""),CHAR(10),"\n"),"'","\'")&"'"&IF(Z7="○",", sealable: true","")&IF(AA7="○",", removable: true","")&"}") -> , '01-yurina-o-n-5': {megami: 'yurina', name: '足捌き', nameEn: 'Footwork', nameZh: '运足', nameZhG1: '疾跑', nameKo: '발놀림', ruby: 'あしさばき', rubyEn: '', baseType: 'normal', type: 'action', text: '現在の間合が4以上ならば、間合→ダスト：2\n現在の間合が1以下ならば、ダスト→間合：2', textZh: '若当前距离大于等于4，则：距→2→虚。 \n若当前距离小于等于1，则：虚→2→距。', textZhG1: '若当前距离大于4，则距（2）→虚。 \n若当前距离小于1，则虚（2）→距。', textKo: '현재 간격이 4 이상이라면、간격→더스트：2\n현재 간격이 1이하라면, 더스트→간격：2', textEn: 'If the current Distance is 4 or more:\nDistance (2)→ Shadow\n\nIf the current Distance is 1 or less:\nShadow (2)→ Distance'} | AO7: =IF($A7<>"", " /** 《"&$E7&"》 */ export const "&SUBSTITUTE(UPPER(IF(MID($A7, 3, 1)="-", RIGHT($A7,LEN($A7)-3), $A7)), "-", "_")&": TCardId = '"&$A7&"';", "") -> /** 《足捌き》 */ export const YURINA_O_N_5: TCardId = '01-yurina-o-n-5'; | AP7: =IF($A7<>"", " | '"&$A7&"'", "") -> | '01-yurina-o-n-5'
A8: 01-yurina-o-n-6 | B8: yurina | E8: 圧気 | F8: あっき | G8: 威压 | H8: 气合斩 | J8: 압기 | K8: Overawe | M8: 通常札 | R8: 付与 | X8: 2 | AB8: 隙 【破棄時】攻撃『適正距離1-4、3/-』を行う。 | AD8: 破绽 【破弃时】进行一次“攻击距离1-4、伤害3/-”的攻击。 | AF8: 破绽 【破弃时】进行一次“攻击距离1-4 伤害3/-”的攻击。 | AG8: 빈틈 【파기시】공격『적정거리1-4、3/-』을 행한다. | AH8: Unguarded Disenchant: You attack with "Range: 1-4, Damage: 3/-". | AN8: =IF(A8="", "", IF(ROW()>=3, ", ", "")&"'"&A8&"': {megami: '"&B8&"'"&IF(C8<>"",", anotherID: '"&C8&"', replace: '"&D8&"'","")&", name: '"&SUBSTITUTE(E8,"'","\'")&"', nameEn: '"&SUBSTITUTE(K8,"'","\'")&"', nameZh: '"&SUBSTITUTE(G8,"'","\'")&"', nameZhG1: '"&SUBSTITUTE(H8,"'","\'")&"', nameKo: '"&SUBSTITUTE(J8,"'","\'")&"', ruby: '"&F8&"', rubyEn: '"&L8&IF(I8<>"", "', rubyZh: '"&I8, "")&"', baseType: '"&VLOOKUP(M8,マスタ!$A$1:$B$99,2,0)&"'"&IF(N8="○",", extra: true","")&IF(O8<>"",", extraFrom: '"&O8&"'","")&IF(P8<>"",", exchangableTo: '"&P8&"'","")&IF(Q8="○",", poison: true","")&IF(R8<>"", ", type: '"&VLOOKUP(R8,マスタ!$D$1:$E$99,2,0)&"'", "")&IF(S8<>"",", subType: '"&VLOOKUP(S8,マスタ!$D$1:$E$99,2,0)&"'","")&IF(T8<>"",", range: '"&T8&"'","")&IF(V8<>"",", damage: '"&V8&"'","")&IF(X8<>"",", capacity: '"&X8&"'","")&IF(Y8<>"",", cost: '"&Y8&"'","")&", text: '"&SUBSTITUTE(SUBSTITUTE(AB8, CHAR(13), ""),CHAR(10),"\n")&IF(AC8<>"", "', textAdditional: '"&SUBSTITUTE(SUBSTITUTE(AC8, CHAR(13), ""),CHAR(10),"\n"), "")&"', textZh: '"&SUBSTITUTE(SUBSTITUTE(SUBSTITUTE(AD8, CHAR(13), ""),CHAR(10),"\n"),"'","\'")&"', textZhG1: '"&SUBSTITUTE(SUBSTITUTE(SUBSTITUTE(AF8, CHAR(13), ""),CHAR(10),"\n"),"'","\'")&IF(AE8<>"", "', textZhAdditional: '"&SUBSTITUTE(SUBSTITUTE(AE8, CHAR(13), ""),CHAR(10),"\n"), "")&"', textKo: '"&SUBSTITUTE(SUBSTITUTE(SUBSTITUTE(AG8, CHAR(13), ""),CHAR(10),"\n"),"'","\'")&"', textEn: '"&SUBSTITUTE(SUBSTITUTE(SUBSTITUTE(AH8, CHAR(13), ""),CHAR(10),"\n"),"'","\'")&"'"&IF(Z8="○",", sealable: true","")&IF(AA8="○",", removable: true","")&"}") -> , '01-yurina-o-n-6': {megami: 'yurina', name: '圧気', nameEn: 'Overawe', nameZh: '威压', nameZhG1: '气合斩', nameKo: '압기', ruby: 'あっき', rubyEn: '', baseType: 'normal', type: 'enhance', capacity: '2', text: '隙\n【破棄時】攻撃『適正距離1-4、3/-』を行う。', textZh: '破绽\n【破弃时】进行一次“攻击距离1-4、伤害3/-”的攻击。', textZhG1: '破绽\n【破弃时】进行一次“攻击距离1-4 伤害3/-”的攻击。', textKo: '빈틈\n 【파기시】공격『적정거리1-4、3/-』을 행한다.', textEn: 'Unguarded\nDisenchant: You attack with "Range: 1-4, Damage: 3/-".'} | AO8: =IF($A8<>"", " /** 《"&$E8&"》 */ export const "&SUBSTITUTE(UPPER(IF(MID($A8, 3, 1)="-", RIGHT($A8,LEN($A8)-3), $A8)), "-", "_")&": TCardId = '"&$A8&"';", "") -> /** 《圧気》 */ export const YURINA_O_N_6: TCardId = '01-yurina-o-n-6'; | AP8: =IF($A8<>"", " | '"&$A8&"'", "") -> | '01-yurina-o-n-6'
A9: 01-yurina-A1-n-6 | B9: yurina | C9: A1 | D9: 01-yurina-o-n-6 | E9: 癇癪玉 | F9: かんしゃくだま | G9: 掌心雷 | H9: 暴砂雷 | J9: 콩알탄 | K9: Outrage | M9: 通常札 | R9: 付与 | S9: 対応 | X9: １ | AB9: 【破棄時】攻撃『適正距離0-4、1/-、対応不可、【攻撃後】相手を畏縮させる』を行う。 | AD9: 【破弃时】进行一次“攻击距离0-4、伤害1/-、不可被对应、【攻击后】令对手畏缩”的攻击。 | AF9: 【破弃时】进行一次“攻击距离0-4 伤害1/- 不可被对应，【攻击后】对手畏缩”的攻击。 | AG9: 【파기시】공격『적정거리0-4、1/-、대응불가、【공격후】상대를 위축시킨다』를 행한다. | AH9: Disenchant: You attack with "Range: 0-4, Damage: 1/-, No Reactions, After Attack: Flinch your opponent." | AN9: =IF(A9="", "", IF(ROW()>=3, ", ", "")&"'"&A9&"': {megami: '"&B9&"'"&IF(C9<>"",", anotherID: '"&C9&"', replace: '"&D9&"'","")&", name: '"&SUBSTITUTE(E9,"'","\'")&"', nameEn: '"&SUBSTITUTE(K9,"'","\'")&"', nameZh: '"&SUBSTITUTE(G9,"'","\'")&"', nameZhG1: '"&SUBSTITUTE(H9,"'","\'")&"', nameKo: '"&SUBSTITUTE(J9,"'","\'")&"', ruby: '"&F9&"', rubyEn: '"&L9&IF(I9<>"", "', rubyZh: '"&I9, "")&"', baseType: '"&VLOOKUP(M9,マスタ!$A$1:$B$99,2,0)&"'"&IF(N9="○",", extra: true","")&IF(O9<>"",", extraFrom: '"&O9&"'","")&IF(P9<>"",", exchangableTo: '"&P9&"'","")&IF(Q9="○",", poison: true","")&IF(R9<>"", ", type: '"&VLOOKUP(R9,マスタ!$D$1:$E$99,2,0)&"'", "")&IF(S9<>"",", subType: '"&VLOOKUP(S9,マスタ!$D$1:$E$99,2,0)&"'","")&IF(T9<>"",", range: '"&T9&"'","")&IF(V9<>"",", damage: '"&V9&"'","")&IF(X9<>"",", capacity: '"&X9&"'","")&IF(Y9<>"",", cost: '"&Y9&"'","")&", text: '"&SUBSTITUTE(SUBSTITUTE(AB9, CHAR(13), ""),CHAR(10),"\n")&IF(AC9<>"", "', textAdditional: '"&SUBSTITUTE(SUBSTITUTE(AC9, CHAR(13), ""),CHAR(10),"\n"), "")&"', textZh: '"&SUBSTITUTE(SUBSTITUTE(SUBSTITUTE(AD9, CHAR(13), ""),CHAR(10),"\n"),"'","\'")&"', textZhG1: '"&SUBSTITUTE(SUBSTITUTE(SUBSTITUTE(AF9, CHAR(13), ""),CHAR(10),"\n"),"'","\'")&IF(AE9<>"", "', textZhAdditional: '"&SUBSTITUTE(SUBSTITUTE(AE9, CHAR(13), ""),CHAR(10),"\n"), "")&"', textKo: '"&SUBSTITUTE(SUBSTITUTE(SUBSTITUTE(AG9, CHAR(13), ""),CHAR(10),"\n"),"'","\'")&"', textEn: '"&SUBSTITUTE(SUBSTITUTE(SUBSTITUTE(AH9, CHAR(13), ""),CHAR(10),"\n"),"'","\'")&"'"&IF(Z9="○",", sealable: true","")&IF(AA9="○",", removable: true","")&"}") -> , '01-yurina-A1-n-6': {megami: 'yurina', anotherID: 'A1', replace: '01-yurina-o-n-6', name: '癇癪玉', nameEn: 'Outrage', nameZh: '掌心雷', nameZhG1: '暴砂雷', nameKo: '콩알탄', ruby: 'かんしゃくだま ', rubyEn: '', baseType: 'normal', type: 'enhance', subType: 'reaction', capacity: '１', text: '【破棄時】攻撃『適正距離0-4、1/-、対応不可、【攻撃後】相手を畏縮させる』を行う。', textZh: '【破弃时】进行一次“攻击距离0-4、伤害1/-、不可被对应、【攻击后】令对手畏缩”的攻击。', textZhG1: '【破弃时】进行一次“攻击距离0-4 伤害1/- 不可被对应，【攻击后】对手畏缩”的攻击。', textKo: '【파기시】공격『적정거리0-4、1/-、대응불가、【공격후】상대를 위축시킨다』를 행한다.', textEn: 'Disenchant: You attack with "Range: 0-4, Damage: 1/-, No Reactions, After Attack: Flinch your opponent."'} | AO9: =IF($A9<>"", " /** 《"&$E9&"》 */ export const "&SUBSTITUTE(UPPER(IF(MID($A9, 3, 1)="-", RIGHT($A9,LEN($A9)-3), $A9)), "-", "_")&": TCardId = '"&$A9&"';", "") -> /** 《癇癪玉》 */ export const YURINA_A1_N_6: TCardId = '01-yurina-A1-n-6'; | AP9: =IF($A9<>"", " | '"&$A9&"'", "") -> | '01-yurina-A1-n-6'
A10: 01-yurina-o-n-7 | B10: yurina | E10: 気炎万丈 | F10: きえんばんじょう | G10: 气焰万丈 | H10: 气焰万丈 | J10: 기염만장 | K10: Spirit of Fire | M10: 通常札 | R10: 付与 | S10: 全力 | X10: 4 | AB10: 【展開中】決死-あなたのライフが3以下ならば、あなたの他のメガミによる《攻撃》は+1/+1となるとともに超克を得る。 | AD10: 【展开中】决死～若自命中的樱花结晶数小于等于3，则你的另一柱女神的《攻击》得+1/+1和超克。 | AF10: 【展开中】决死-若自命中的樱花结晶的数目小于3，则你的另一柱女武神的《攻击》得+1/+1和超克。 | AG10: 【전개중】결사-당신의 라이프가 3 이하라면, 당신의 다른 여신에 의한 《공격》은 +1/+1이 되며 초극을 얻는다. | AH10: Ongoing: Resolve - All your other Megami's attacks gain +1/+1 and Overwhelm if your Life is 3 or less. | AN10: =IF(A10="", "", IF(ROW()>=3, ", ", "")&"'"&A10&"': {megami: '"&B10&"'"&IF(C10<>"",", anotherID: '"&C10&"', replace: '"&D10&"'","")&", name: '"&SUBSTITUTE(E10,"'","\'")&"', nameEn: '"&SUBSTITUTE(K10,"'","\'")&"', nameZh: '"&SUBSTITUTE(G10,"'","\'")&"', nameZhG1: '"&SUBSTITUTE(H10,"'","\'")&"', nameKo: '"&SUBSTITUTE(J10,"'","\'")&"', ruby: '"&F10&"', rubyEn: '"&L10&IF(I10<>"", "', rubyZh: '"&I10, "")&"', baseType: '"&VLOOKUP(M10,マスタ!$A$1:$B$99,2,0)&"'"&IF(N10="○",", extra: true","")&IF(O10<>"",", extraFrom: '"&O10&"'","")&IF(P10<>"",", exchangableTo: '"&P10&"'","")&IF(Q10="○",", poison: true","")&IF(R10<>"", ", type: '"&VLOOKUP(R10,マスタ!$D$1:$E$99,2,0)&"'", "")&IF(S10<>"",", subType: '"&VLOOKUP(S10,マスタ!$D$1:$E$99,2,0)&"'","")&IF(T10<>"",", range: '"&T10&"'","")&IF(V10<>"",", damage: '"&V10&"'","")&IF(X10<>"",", capacity: '"&X10&"'","")&IF(Y10<>"",", cost: '"&Y10&"'","")&", text: '"&SUBSTITUTE(SUBSTITUTE(AB10, CHAR(13), ""),CHAR(10),"\n")&IF(AC10<>"", "', textAdditional: '"&SUBSTITUTE(SUBSTITUTE(AC10, CHAR(13), ""),CHAR(10),"\n"), "")&"', textZh: '"&SUBSTITUTE(SUBSTITUTE(SUBSTITUTE(AD10, CHAR(13), ""),CHAR(10),"\n"),"'","\'")&"', textZhG1: '"&SUBSTITUTE(SUBSTITUTE(SUBSTITUTE(AF10, CHAR(13), ""),CHAR(10),"\n"),"'","\'")&IF(AE10<>"", "', textZhAdditional: '"&SUBSTITUTE(SUBSTITUTE(AE10, CHAR(13), ""),CHAR(10),"\n"), "")&"', textKo: '"&SUBSTITUTE(SUBSTITUTE(SUBSTITUTE(AG10, CHAR(13), ""),CHAR(10),"\n"),"'","\'")&"', textEn: '"&SUBSTITUTE(SUBSTITUTE(SUBSTITUTE(AH10, CHAR(13), ""),CHAR(10),"\n"),"'","\'")&"'"&IF(Z10="○",", sealable: true","")&IF(AA10="○",", removable: true","")&"}") -> , '01-yurina-o-n-7': {megami: 'yurina', name: '気炎万丈', nameEn: 'Spirit of Fire', nameZh: '气焰万丈', nameZhG1: '气焰万丈', nameKo: '기염만장', ruby: 'きえんばんじょう', rubyEn: '', baseType: 'normal', type: 'enhance', subType: 'fullpower', capacity: '4', text: '【展開中】決死-あなたのライフが3以下ならば、あなたの他のメガミによる《攻撃》は+1/+1となるとともに超克を得る。', textZh: '【展开中】决死～若自命中的樱花结晶数小于等于3，则你的另一柱女神的《攻击》得+1/+1和超克。', textZhG1: '【展开中】决死-若自命中的樱花结晶的数目小于3，则你的另一柱女武神的《攻击》得+1/+1和超克。', textKo: '【전개중】결사-당신의 라이프가 3 이하라면, 당신의 다른 여신에 의한 《공격》은 +1/+1이 되며 초극을 얻는다.', textEn: 'Ongoing: Resolve - All your other Megami\'s attacks gain +1/+1 and Overwhelm if your Life is 3 or less.'} | AO10: =IF($A10<>"", " /** 《"&$E10&"》 */ export const "&SUBSTITUTE(UPPER(IF(MID($A10, 3, 1)="-", RIGHT($A10,LEN($A10)-3), $A10)), "-", "_")&": TCardId = '"&$A10&"';", "") -> /** 《気炎万丈》 */ export const YURINA_O_N_7: TCardId = '01-yurina-o-n-7'; | AP10: =IF($A10<>"", " | '"&$A10&"'", "") -> | '01-yurina-o-n-7'
A11: 01-yurina-o-s-1 | B11: yurina | E11: 月影落 | F11: つきかげおとし | G11: 月影落 | H11: 月影落 | J11: 달그림자 떨어지니 | K11: Tsukikage Crush | M11: 切札 | R11: 攻撃 | T11: 3-4 | V11: 4/4 | Y11: 7 | AN11: =IF(A11="", "", IF(ROW()>=3, ", ", "")&"'"&A11&"': {megami: '"&B11&"'"&IF(C11<>"",", anotherID: '"&C11&"', replace: '"&D11&"'","")&", name: '"&SUBSTITUTE(E11,"'","\'")&"', nameEn: '"&SUBSTITUTE(K11,"'","\'")&"', nameZh: '"&SUBSTITUTE(G11,"'","\'")&"', nameZhG1: '"&SUBSTITUTE(H11,"'","\'")&"', nameKo: '"&SUBSTITUTE(J11,"'","\'")&"', ruby: '"&F11&"', rubyEn: '"&L11&IF(I11<>"", "', rubyZh: '"&I11, "")&"', baseType: '"&VLOOKUP(M11,マスタ!$A$1:$B$99,2,0)&"'"&IF(N11="○",", extra: true","")&IF(O11<>"",", extraFrom: '"&O11&"'","")&IF(P11<>"",", exchangableTo: '"&P11&"'","")&IF(Q11="○",", poison: true","")&IF(R11<>"", ", type: '"&VLOOKUP(R11,マスタ!$D$1:$E$99,2,0)&"'", "")&IF(S11<>"",", subType: '"&VLOOKUP(S11,マスタ!$D$1:$E$99,2,0)&"'","")&IF(T11<>"",", range: '"&T11&"'","")&IF(V11<>"",", damage: '"&V11&"'","")&IF(X11<>"",", capacity: '"&X11&"'","")&IF(Y11<>"",", cost: '"&Y11&"'","")&", text: '"&SUBSTITUTE(SUBSTITUTE(AB11, CHAR(13), ""),CHAR(10),"\n")&IF(AC11<>"", "', textAdditional: '"&SUBSTITUTE(SUBSTITUTE(AC11, CHAR(13), ""),CHAR(10),"\n"), "")&"', textZh: '"&SUBSTITUTE(SUBSTITUTE(SUBSTITUTE(AD11, CHAR(13), ""),CHAR(10),"\n"),"'","\'")&"', textZhG1: '"&SUBSTITUTE(SUBSTITUTE(SUBSTITUTE(AF11, CHAR(13), ""),CHAR(10),"\n"),"'","\'")&IF(AE11<>"", "', textZhAdditional: '"&SUBSTITUTE(SUBSTITUTE(AE11, CHAR(13), ""),CHAR(10),"\n"), "")&"', textKo: '"&SUBSTITUTE(SUBSTITUTE(SUBSTITUTE(AG11, CHAR(13), ""),CHAR(10),"\n"),"'","\'")&"', textEn: '"&SUBSTITUTE(SUBSTITUTE(SUBSTITUTE(AH11, CHAR(13), ""),CHAR(10),"\n"),"'","\'")&"'"&IF(Z11="○",", sealable: true","")&IF(AA11="○",", removable: true","")&"}") -> , '01-yurina-o-s-1': {megami: 'yurina', name: '月影落', nameEn: 'Tsukikage Crush', nameZh: '月影落', nameZhG1: '月影落', nameKo: '달그림자 떨어지니', ruby: 'つきかげおとし', rubyEn: '', baseType: 'special', type: 'attack', range: '3-4', damage: '4/4', cost: '7', text: '', textZh: '', textZhG1: '', textKo: '', textEn: ''} | AO11: =IF($A11<>"", " /** 《"&$E11&"》 */ export const "&SUBSTITUTE(UPPER(IF(MID($A11, 3, 1)="-", RIGHT($A11,LEN($A11)-3), $A11)), "-", "_")&": TCardId = '"&$A11&"';", "") -> /** 《月影落》 */ export const YURINA_O_S_1: TCardId = '01-yurina-o-s-1'; | AP11: =IF($A11<>"", " | '"&$A11&"'", "") -> | '01-yurina-o-s-1'
A12: 01-yurina-o-s-2 | B12: yurina | E12: 浦波嵐 | F12: うらなみあらし | G12: 浦波岚 | H12: 浦波岚 | J12: 해안에 파랑 일며 | K12: Uranami Storm | M12: 切札 | R12: 攻撃 | S12: 対応 | T12: 0-10 | V12: 2/- | Y12: 3 | AB12: 【攻撃後】対応した《攻撃》は-2/+0となる。 | AD12: 【攻击后】被对应的《攻击》得-2/+0。 | AF12: 【攻击后】被对应的《攻击》得-2/-0。 | AG12: 【공격후】대응한 《공격》은 -2/+0이 된다. | AH12: After Attack: The attack this card was played as a Reaction to gets -2/+0. | AN12: =IF(A12="", "", IF(ROW()>=3, ", ", "")&"'"&A12&"': {megami: '"&B12&"'"&IF(C12<>"",", anotherID: '"&C12&"', replace: '"&D12&"'","")&", name: '"&SUBSTITUTE(E12,"'","\'")&"', nameEn: '"&SUBSTITUTE(K12,"'","\'")&"', nameZh: '"&SUBSTITUTE(G12,"'","\'")&"', nameZhG1: '"&SUBSTITUTE(H12,"'","\'")&"', nameKo: '"&SUBSTITUTE(J12,"'","\'")&"', ruby: '"&F12&"', rubyEn: '"&L12&IF(I12<>"", "', rubyZh: '"&I12, "")&"', baseType: '"&VLOOKUP(M12,マスタ!$A$1:$B$99,2,0)&"'"&IF(N12="○",", extra: true","")&IF(O12<>"",", extraFrom: '"&O12&"'","")&IF(P12<>"",", exchangableTo: '"&P12&"'","")&IF(Q12="○",", poison: true","")&IF(R12<>"", ", type: '"&VLOOKUP(R12,マスタ!$D$1:$E$99,2,0)&"'", "")&IF(S12<>"",", subType: '"&VLOOKUP(S12,マスタ!$D$1:$E$99,2,0)&"'","")&IF(T12<>"",", range: '"&T12&"'","")&IF(V12<>"",", damage: '"&V12&"'","")&IF(X12<>"",", capacity: '"&X12&"'","")&IF(Y12<>"",", cost: '"&Y12&"'","")&", text: '"&SUBSTITUTE(SUBSTITUTE(AB12, CHAR(13), ""),CHAR(10),"\n")&IF(AC12<>"", "', textAdditional: '"&SUBSTITUTE(SUBSTITUTE(AC12, CHAR(13), ""),CHAR(10),"\n"), "")&"', textZh: '"&SUBSTITUTE(SUBSTITUTE(SUBSTITUTE(AD12, CHAR(13), ""),CHAR(10),"\n"),"'","\'")&"', textZhG1: '"&SUBSTITUTE(SUBSTITUTE(SUBSTITUTE(AF12, CHAR(13), ""),CHAR(10),"\n"),"'","\'")&IF(AE12<>"", "', textZhAdditional: '"&SUBSTITUTE(SUBSTITUTE(AE12, CHAR(13), ""),CHAR(10),"\n"), "")&"', textKo: '"&SUBSTITUTE(SUBSTITUTE(SUBSTITUTE(AG12, CHAR(13), ""),CHAR(10),"\n"),"'","\'")&"', textEn: '"&SUBSTITUTE(SUBSTITUTE(SUBSTITUTE(AH12, CHAR(13), ""),CHAR(10),"\n"),"'","\'")&"'"&IF(Z12="○",", sealable: true","")&IF(AA12="○",", removable: true","")&"}") -> , '01-yurina-o-s-2': {megami: 'yurina', name: '浦波嵐', nameEn: 'Uranami Storm', nameZh: '浦波岚', nameZhG1: '浦波岚', nameKo: '해안에 파랑 일며', ruby: 'うらなみあらし', rubyEn: '', baseType: 'special', type: 'attack', subType: 'reaction', range: '0-10', damage: '2/-', cost: '3', text: '【攻撃後】対応した《攻撃》は-2/+0となる。', textZh: '【攻击后】被对应的《攻击》得-2/+0。', textZhG1: '【攻击后】被对应的《攻击》得-2/-0。', textKo: '【공격후】대응한 《공격》은 -2/+0이 된다.', textEn: 'After Attack: The attack this card was played as a Reaction to gets -2/+0.'} | AO12: =IF($A12<>"", " /** 《"&$E12&"》 */ export const "&SUBSTITUTE(UPPER(IF(MID($A12, 3, 1)="-", RIGHT($A12,LEN($A12)-3), $A12)), "-", "_")&": TCardId = '"&$A12&"';", "") -> /** 《浦波嵐》 */ export const YURINA_O_S_2: TCardId = '01-yurina-o-s-2'; | AP12: =IF($A12<>"", " | '"&$A12&"'", "") -> | '01-yurina-o-s-2'
A13: 01-yurina-A1-s-2 | B13: yurina | C13: A1 | D13: 01-yurina-o-s-2 | E13: 不完全浦波嵐 | F13: ふかんぜんうらなみあらし | G13: 不完全浦波岚 | H13: 不完全浦波岚 | J13: 불완전 해안에 파랑 일며 | K13: Imperfect Uranami Storm | M13: 切札 | R13: 攻撃 | S13: 対応 | T13: 0-10 | V13: 3/- | Y13: 5 | AB13: 【攻撃後】対応した《攻撃》は-3/+0となる。 | AD13: 【攻击后】被对应的《攻击》得-3/+0。 | AF13: 【攻击后】被对应的《攻击》得-3/-0。 | AG13: 【공격후】대응한 《공격》은 -3/+0이 된다. | AH13: After Attack: The attack this card was played as a Reaction to gets -3/+0. | AN13: =IF(A13="", "", IF(ROW()>=3, ", ", "")&"'"&A13&"': {megami: '"&B13&"'"&IF(C13<>"",", anotherID: '"&C13&"', replace: '"&D13&"'","")&", name: '"&SUBSTITUTE(E13,"'","\'")&"', nameEn: '"&SUBSTITUTE(K13,"'","\'")&"', nameZh: '"&SUBSTITUTE(G13,"'","\'")&"', nameZhG1: '"&SUBSTITUTE(H13,"'","\'")&"', nameKo: '"&SUBSTITUTE(J13,"'","\'")&"', ruby: '"&F13&"', rubyEn: '"&L13&IF(I13<>"", "', rubyZh: '"&I13, "")&"', baseType: '"&VLOOKUP(M13,マスタ!$A$1:$B$99,2,0)&"'"&IF(N13="○",", extra: true","")&IF(O13<>"",", extraFrom: '"&O13&"'","")&IF(P13<>"",", exchangableTo: '"&P13&"'","")&IF(Q13="○",", poison: true","")&IF(R13<>"", ", type: '"&VLOOKUP(R13,マスタ!$D$1:$E$99,2,0)&"'", "")&IF(S13<>"",", subType: '"&VLOOKUP(S13,マスタ!$D$1:$E$99,2,0)&"'","")&IF(T13<>"",", range: '"&T13&"'","")&IF(V13<>"",", damage: '"&V13&"'","")&IF(X13<>"",", capacity: '"&X13&"'","")&IF(Y13<>"",", cost: '"&Y13&"'","")&", text: '"&SUBSTITUTE(SUBSTITUTE(AB13, CHAR(13), ""),CHAR(10),"\n")&IF(AC13<>"", "', textAdditional: '"&SUBSTITUTE(SUBSTITUTE(AC13, CHAR(13), ""),CHAR(10),"\n"), "")&"', textZh: '"&SUBSTITUTE(SUBSTITUTE(SUBSTITUTE(AD13, CHAR(13), ""),CHAR(10),"\n"),"'","\'")&"', textZhG1: '"&SUBSTITUTE(SUBSTITUTE(SUBSTITUTE(AF13, CHAR(13), ""),CHAR(10),"\n"),"'","\'")&IF(AE13<>"", "', textZhAdditional: '"&SUBSTITUTE(SUBSTITUTE(AE13, CHAR(13), ""),CHAR(10),"\n"), "")&"', textKo: '"&SUBSTITUTE(SUBSTITUTE(SUBSTITUTE(AG13, CHAR(13), ""),CHAR(10),"\n"),"'","\'")&"', textEn: '"&SUBSTITUTE(SUBSTITUTE(SUBSTITUTE(AH13, CHAR(13), ""),CHAR(10),"\n"),"'","\'")&"'"&IF(Z13="○",", sealable: true","")&IF(AA13="○",", removable: true","")&"}") -> , '01-yurina-A1-s-2': {megami: 'yurina', anotherID: 'A1', replace: '01-yurina-o-s-2', name: '不完全浦波嵐', nameEn: 'Imperfect Uranami Storm', nameZh: '不完全浦波岚', nameZhG1: '不完全浦波岚', nameKo: '불완전 해안에 파랑 일며', ruby: 'ふかんぜんうらなみあらし', rubyEn: '', baseType: 'special', type: 'attack', subType: 'reaction', range: '0-10', damage: '3/-', cost: '5', text: '【攻撃後】対応した《攻撃》は-3/+0となる。', textZh: '【攻击后】被对应的《攻击》得-3/+0。', textZhG1: '【攻击后】被对应的《攻击》得-3/-0。', textKo: '【공격후】대응한 《공격》은 -3/+0이 된다.', textEn: 'After Attack: The attack this card was played as a Reaction to gets -3/+0.'} | AO13: =IF($A13<>"", " /** 《"&$E13&"》 */ export const "&SUBSTITUTE(UPPER(IF(MID($A13, 3, 1)="-", RIGHT($A13,LEN($A13)-3), $A13)), "-", "_")&": TCardId = '"&$A13&"';", "") -> /** 《不完全浦波嵐》 */ export const YURINA_A1_S_2: TCardId = '01-yurina-A1-s-2'; | AP13: =IF($A13<>"", " | '"&$A13&"'", "") -> | '01-yurina-A1-s-2'
A14: 01-yurina-o-s-3 | B14: yurina | E14: 浮舟宿 | F14: うきふねやどし | G14: 浮舟宿 | H14: 浮舟宿 | J14: 쪽배에서 쉬노니 | K14: Ukifune Serene | M14: 切札 | R14: 行動 | Y14: 2 | AB14: ダスト→自オーラ：5 ---- 【即再起】決死-あなたのライフが3以下になる。 | AD14: 虚→5→自装 ---- 【即再起】决死～自命中的樱花结晶数小于等于3。 | AF14: 虚（5）→自装 ---- 【即再起】：决死-自命中的樱花结晶的数目小于3。 | AG14: 더스트→자신 오라：5 ---- 【즉재기】결사-당신의 라이프가 3 이하가 된다. | AH14: Shadow (5)→ Your Aura ---- Immediate Resurgence: Resolve - Your Life becomes 3 or less (from 4 or more). | AN14: =IF(A14="", "", IF(ROW()>=3, ", ", "")&"'"&A14&"': {megami: '"&B14&"'"&IF(C14<>"",", anotherID: '"&C14&"', replace: '"&D14&"'","")&", name: '"&SUBSTITUTE(E14,"'","\'")&"', nameEn: '"&SUBSTITUTE(K14,"'","\'")&"', nameZh: '"&SUBSTITUTE(G14,"'","\'")&"', nameZhG1: '"&SUBSTITUTE(H14,"'","\'")&"', nameKo: '"&SUBSTITUTE(J14,"'","\'")&"', ruby: '"&F14&"', rubyEn: '"&L14&IF(I14<>"", "', rubyZh: '"&I14, "")&"', baseType: '"&VLOOKUP(M14,マスタ!$A$1:$B$99,2,0)&"'"&IF(N14="○",", extra: true","")&IF(O14<>"",", extraFrom: '"&O14&"'","")&IF(P14<>"",", exchangableTo: '"&P14&"'","")&IF(Q14="○",", poison: true","")&IF(R14<>"", ", type: '"&VLOOKUP(R14,マスタ!$D$1:$E$99,2,0)&"'", "")&IF(S14<>"",", subType: '"&VLOOKUP(S14,マスタ!$D$1:$E$99,2,0)&"'","")&IF(T14<>"",", range: '"&T14&"'","")&IF(V14<>"",", damage: '"&V14&"'","")&IF(X14<>"",", capacity: '"&X14&"'","")&IF(Y14<>"",", cost: '"&Y14&"'","")&", text: '"&SUBSTITUTE(SUBSTITUTE(AB14, CHAR(13), ""),CHAR(10),"\n")&IF(AC14<>"", "', textAdditional: '"&SUBSTITUTE(SUBSTITUTE(AC14, CHAR(13), ""),CHAR(10),"\n"), "")&"', textZh: '"&SUBSTITUTE(SUBSTITUTE(SUBSTITUTE(AD14, CHAR(13), ""),CHAR(10),"\n"),"'","\'")&"', textZhG1: '"&SUBSTITUTE(SUBSTITUTE(SUBSTITUTE(AF14, CHAR(13), ""),CHAR(10),"\n"),"'","\'")&IF(AE14<>"", "', textZhAdditional: '"&SUBSTITUTE(SUBSTITUTE(AE14, CHAR(13), ""),CHAR(10),"\n"), "")&"', textKo: '"&SUBSTITUTE(SUBSTITUTE(SUBSTITUTE(AG14, CHAR(13), ""),CHAR(10),"\n"),"'","\'")&"', textEn: '"&SUBSTITUTE(SUBSTITUTE(SUBSTITUTE(AH14, CHAR(13), ""),CHAR(10),"\n"),"'","\'")&"'"&IF(Z14="○",", sealable: true","")&IF(AA14="○",", removable: true","")&"}") -> , '01-yurina-o-s-3': {megami: 'yurina', name: '浮舟宿', nameEn: 'Ukifune Serene', nameZh: '浮舟宿', nameZhG1: '浮舟宿', nameKo: '쪽배에서 쉬노니', ruby: 'うきふねやどし', rubyEn: '', baseType: 'special', type: 'action', cost: '2', text: 'ダスト→自オーラ：5 \n----\n【即再起】決死-あなたのライフが3以下になる。', textZh: '虚→5→自装 \n----\n【即再起】决死～自命中的樱花结晶数小于等于3。', textZhG1: '虚（5）→自装 \n----\n【即再起】：决死-自命中的樱花结晶的数目小于3。', textKo: '더스트→자신 오라：5 \n---- \n【즉재기】결사-당신의 라이프가 3 이하가 된다.', textEn: 'Shadow (5)→ Your Aura\n----\nImmediate Resurgence: Resolve - Your Life becomes 3 or less (from 4 or more).'} | AO14: =IF($A14<>"", " /** 《"&$E14&"》 */ export const "&SUBSTITUTE(UPPER(IF(MID($A14, 3, 1)="-", RIGHT($A14,LEN($A14)-3), $A14)), "-", "_")&": TCardId = '"&$A14&"';", "") -> /** 《浮舟宿》 */ export const YURINA_O_S_3: TCardId = '01-yurina-o-s-3'; | AP14: =IF($A14<>"", " | '"&$A14&"'", "") -> | '01-yurina-o-s-3'
A15: 01-yurina-o-s-4 | B15: yurina | E15: 天音揺波の底力 | F15: あまねゆりなのそこぢから | G15: 天音摇波的底力 | H15: 天音摇波的底力 | J15: 아마네 유리나의 저력 | K15: Yurina's Final Blow | M15: 切札 | R15: 攻撃 | S15: 全力 | T15: 1-4 | V15: 5/5 | Y15: 5 | AB15: 【常時】決死-あなたのライフが3以下でないと、このカードは使用できない。 | AD15: 【常时】决死～仅当自命中的樱花结晶数小于等于3时，才可以使用此牌。 | AF15: 【常时】决死-只能当自命中的樱花结晶的数目小于3时使用此牌。 | AG15: 【상시】결사-당신의 라이프가 3 이하가 아니면, 이 카드는 사용 할 수 없다. | AH15: Forced: Resolve - You can't play this card unless your Life is 3 or less. | AN15: =IF(A15="", "", IF(ROW()>=3, ", ", "")&"'"&A15&"': {megami: '"&B15&"'"&IF(C15<>"",", anotherID: '"&C15&"', replace: '"&D15&"'","")&", name: '"&SUBSTITUTE(E15,"'","\'")&"', nameEn: '"&SUBSTITUTE(K15,"'","\'")&"', nameZh: '"&SUBSTITUTE(G15,"'","\'")&"', nameZhG1: '"&SUBSTITUTE(H15,"'","\'")&"', nameKo: '"&SUBSTITUTE(J15,"'","\'")&"', ruby: '"&F15&"', rubyEn: '"&L15&IF(I15<>"", "', rubyZh: '"&I15, "")&"', baseType: '"&VLOOKUP(M15,マスタ!$A$1:$B$99,2,0)&"'"&IF(N15="○",", extra: true","")&IF(O15<>"",", extraFrom: '"&O15&"'","")&IF(P15<>"",", exchangableTo: '"&P15&"'","")&IF(Q15="○",", poison: true","")&IF(R15<>"", ", type: '"&VLOOKUP(R15,マスタ!$D$1:$E$99,2,0)&"'", "")&IF(S15<>"",", subType: '"&VLOOKUP(S15,マスタ!$D$1:$E$99,2,0)&"'","")&IF(T15<>"",", range: '"&T15&"'","")&IF(V15<>"",", damage: '"&V15&"'","")&IF(X15<>"",", capacity: '"&X15&"'","")&IF(Y15<>"",", cost: '"&Y15&"'","")&", text: '"&SUBSTITUTE(SUBSTITUTE(AB15, CHAR(13), ""),CHAR(10),"\n")&IF(AC15<>"", "', textAdditional: '"&SUBSTITUTE(SUBSTITUTE(AC15, CHAR(13), ""),CHAR(10),"\n"), "")&"', textZh: '"&SUBSTITUTE(SUBSTITUTE(SUBSTITUTE(AD15, CHAR(13), ""),CHAR(10),"\n"),"'","\'")&"', textZhG1: '"&SUBSTITUTE(SUBSTITUTE(SUBSTITUTE(AF15, CHAR(13), ""),CHAR(10),"\n"),"'","\'")&IF(AE15<>"", "', textZhAdditional: '"&SUBSTITUTE(SUBSTITUTE(AE15, CHAR(13), ""),CHAR(10),"\n"), "")&"', textKo: '"&SUBSTITUTE(SUBSTITUTE(SUBSTITUTE(AG15, CHAR(13), ""),CHAR(10),"\n"),"'","\'")&"', textEn: '"&SUBSTITUTE(SUBSTITUTE(SUBSTITUTE(AH15, CHAR(13), ""),CHAR(10),"\n"),"'","\'")&"'"&IF(Z15="○",", sealable: true","")&IF(AA15="○",", removable: true","")&"}") -> , '01-yurina-o-s-4': {megami: 'yurina', name: '天音揺波の底力', nameEn: 'Yurina\'s Final Blow', nameZh: '天音摇波的底力', nameZhG1: '天音摇波的底力', nameKo: '아마네 유리나의 저력', ruby: 'あまねゆりなのそこぢから', rubyEn: '', baseType: 'special', type: 'attack', subType: 'fullpower', range: '1-4', damage: '5/5', cost: '5', text: '【常時】決死-あなたのライフが3以下でないと、このカードは使用できない。', textZh: '【常时】决死～仅当自命中的樱花结晶数小于等于3时，才可以使用此牌。', textZhG1: '【常时】决死-只能当自命中的樱花结晶的数目小于3时使用此牌。', textKo: '【상시】결사-당신의 라이프가 3 이하가 아니면, 이 카드는 사용 할 수 없다.', textEn: 'Forced: Resolve - You can\'t play this card unless your Life is 3 or less.'} | AO15: =IF($A15<>"", " /** 《"&$E15&"》 */ export const "&SUBSTITUTE(UPPER(IF(MID($A15, 3, 1)="-", RIGHT($A15,LEN($A15)-3), $A15)), "-", "_")&": TCardId = '"&$A15&"';", "") -> /** 《天音揺波の底力》 */ export const YURINA_O_S_4: TCardId = '01-yurina-o-s-4'; | AP15: =IF($A15<>"", " | '"&$A15&"'", "") -> | '01-yurina-o-s-4'
AN16: =IF(A16="", "", IF(ROW()>=3, ", ", "")&"'"&A16&"': {megami: '"&B16&"'"&IF(C16<>"",", anotherID: '"&C16&"', replace: '"&D16&"'","")&", name: '"&SUBSTITUTE(E16,"'","\'")&"', nameEn: '"&SUBSTITUTE(K16,"'","\'")&"', nameZh: '"&SUBSTITUTE(G16,"'","\'")&"', nameZhG1: '"&SUBSTITUTE(H16,"'","\'")&"', nameKo: '"&SUBSTITUTE(J16,"'","\'")&"', ruby: '"&F16&"', rubyEn: '"&L16&IF(I16<>"", "', rubyZh: '"&I16, "")&"', baseType: '"&VLOOKUP(M16,マスタ!$A$1:$B$99,2,0)&"'"&IF(N16="○",", extra: true","")&IF(O16<>"",", extraFrom: '"&O16&"'","")&IF(P16<>"",", exchangableTo: '"&P16&"'","")&IF(Q16="○",", poison: true","")&IF(R16<>"", ", type: '"&VLOOKUP(R16,マスタ!$D$1:$E$99,2,0)&"'", "")&IF(S16<>"",", subType: '"&VLOOKUP(S16,マスタ!$D$1:$E$99,2,0)&"'","")&IF(T16<>"",", range: '"&T16&"'","")&IF(V16<>"",", damage: '"&V16&"'","")&IF(X16<>"",", capacity: '"&X16&"'","")&IF(Y16<>"",", cost: '"&Y16&"'","")&", text: '"&SUBSTITUTE(SUBSTITUTE(AB16, CHAR(13), ""),CHAR(10),"\n")&IF(AC16<>"", "', textAdditional: '"&SUBSTITUTE(SUBSTITUTE(AC16, CHAR(13), ""),CHAR(10),"\n"), "")&"', textZh: '"&SUBSTITUTE(SUBSTITUTE(SUBSTITUTE(AD16, CHAR(13), ""),CHAR(10),"\n"),"'","\'")&"', textZhG1: '"&SUBSTITUTE(SUBSTITUTE(SUBSTITUTE(AF16, CHAR(13), ""),CHAR(10),"\n"),"'","\'")&IF(AE16<>"", "', textZhAdditional: '"&SUBSTITUTE(SUBSTITUTE(AE16, CHAR(13), ""),CHAR(10),"\n"), "")&"', textKo: '"&SUBSTITUTE(SUBSTITUTE(SUBSTITUTE(AG16, CHAR(13), ""),CHAR(10),"\n"),"'","\'")&"', textEn: '"&SUBSTITUTE(SUBSTITUTE(SUBSTITUTE(AH16, CHAR(13), ""),CHAR(10),"\n"),"'","\'")&"'"&IF(Z16="○",", sealable: true","")&IF(AA16="○",", removable: true","")&"}") | AO16: =IF($A16<>"", " /** 《"&$E16&"》 */ export const "&SUBSTITUTE(UPPER(IF(MID($A16, 3, 1)="-", RIGHT($A16,LEN($A16)-3), $A16)), "-", "_")&": TCardId = '"&$A16&"';", "") | AP16: =IF($A16<>"", " | '"&$A16&"'", "")
A17: 02-saine-o-n-1 | B17: saine | E17: 八方振り | F17: はっぽうぶり | G17: 八方斩 | H17: 八面斩 | J17: 팔방 휘두르기 | K17: Swing Rush | M17: 通常札 | R17: 攻撃 | T17: 4-5 | V17: 2/1 | AB17: 【攻撃後】八相-あなたのオーラが0ならば、攻撃『適正距離4-5、2/1』を行う。 | AD17: 【攻击后】八相～若自装中没有樱花结晶，则进行一次“攻击距离4-5、伤害2/1”的攻击。 | AF17: 【攻击后】八相-若自装中没有樱花结晶，则进行一次“攻击距离4-5 伤害2/1”的攻击。 | AG17: 【공격후】팔상-당신의 오라가 0이라면, 공격『적정거리4-5、2/1』을 행한다. | AH17: After Attack: Idea - You attack with "Range: 4-5, Damage: 2/1" if you have no Sakura tokens on your Aura. | AN17: =IF(A17="", "", IF(ROW()>=3, ", ", "")&"'"&A17&"': {megami: '"&B17&"'"&IF(C17<>"",", anotherID: '"&C17&"', replace: '"&D17&"'","")&", name: '"&SUBSTITUTE(E17,"'","\'")&"', nameEn: '"&SUBSTITUTE(K17,"'","\'")&"', nameZh: '"&SUBSTITUTE(G17,"'","\'")&"', nameZhG1: '"&SUBSTITUTE(H17,"'","\'")&"', nameKo: '"&SUBSTITUTE(J17,"'","\'")&"', ruby: '"&F17&"', rubyEn: '"&L17&IF(I17<>"", "', rubyZh: '"&I17, "")&"', baseType: '"&VLOOKUP(M17,マスタ!$A$1:$B$99,2,0)&"'"&IF(N17="○",", extra: true","")&IF(O17<>"",", extraFrom: '"&O17&"'","")&IF(P17<>"",", exchangableTo: '"&P17&"'","")&IF(Q17="○",", poison: true","")&IF(R17<>"", ", type: '"&VLOOKUP(R17,マスタ!$D$1:$E$99,2,0)&"'", "")&IF(S17<>"",", subType: '"&VLOOKUP(S17,マスタ!$D$1:$E$99,2,0)&"'","")&IF(T17<>"",", range: '"&T17&"'","")&IF(V17<>"",", damage: '"&V17&"'","")&IF(X17<>"",", capacity: '"&X17&"'","")&IF(Y17<>"",", cost: '"&Y17&"'","")&", text: '"&SUBSTITUTE(SUBSTITUTE(AB17, CHAR(13), ""),CHAR(10),"\n")&IF(AC17<>"", "', textAdditional: '"&SUBSTITUTE(SUBSTITUTE(AC17, CHAR(13), ""),CHAR(10),"\n"), "")&"', textZh: '"&SUBSTITUTE(SUBSTITUTE(SUBSTITUTE(AD17, CHAR(13), ""),CHAR(10),"\n"),"'","\'")&"', textZhG1: '"&SUBSTITUTE(SUBSTITUTE(SUBSTITUTE(AF17, CHAR(13), ""),CHAR(10),"\n"),"'","\'")&IF(AE17<>"", "', textZhAdditional: '"&SUBSTITUTE(SUBSTITUTE(AE17, CHAR(13), ""),CHAR(10),"\n"), "")&"', textKo: '"&SUBSTITUTE(SUBSTITUTE(SUBSTITUTE(AG17, CHAR(13), ""),CHAR(10),"\n"),"'","\'")&"', textEn: '"&SUBSTITUTE(SUBSTITUTE(SUBSTITUTE(AH17, CHAR(13), ""),CHAR(10),"\n"),"'","\'")&"'"&IF(Z17="○",", sealable: true","")&IF(AA17="○",", removable: true","")&"}") -> , '02-saine-o-n-1': {megami: 'saine', name: '八方振り', nameEn: 'Swing Rush', nameZh: '八方斩', nameZhG1: '八面斩', nameKo: '팔방 휘두르기', ruby: 'はっぽうぶり', rubyEn: '', baseType: 'normal', type: 'attack', range: '4-5', damage: '2/1', text: '【攻撃後】八相-あなたのオーラが0ならば、攻撃『適正距離4-5、2/1』を行う。', textZh: '【攻击后】八相～若自装中没有樱花结晶，则进行一次“攻击距离4-5、伤害2/1”的攻击。', textZhG1: '【攻击后】八相-若自装中没有樱花结晶，则进行一次“攻击距离4-5 伤害2/1”的攻击。', textKo: '【공격후】팔상-당신의 오라가 0이라면, 공격『적정거리4-5、2/1』을 행한다.', textEn: 'After Attack: Idea - You attack with "Range: 4-5, Damage: 2/1" if you have no Sakura tokens on your Aura.'} | AO17: =IF($A17<>"", " /** 《"&$E17&"》 */ export const "&SUBSTITUTE(UPPER(IF(MID($A17, 3, 1)="-", RIGHT($A17,LEN($A17)-3), $A17)), "-", "_")&": TCardId = '"&$A17&"';", "") -> /** 《八方振り》 */ export const SAINE_O_N_1: TCardId = '02-saine-o-n-1'; | AP17: =IF($A17<>"", " | '"&$A17&"'", "") -> | '02-saine-o-n-1'
A18: 02-saine-o-n-2 | B18: saine | E18: 薙斬り | F18: なぎぎり | G18: 薙刀斩 | H18: 薙刀斩 | J18: 후려베기 | K18: Cut Down | M18: 通常札 | R18: 攻撃 | S18: 対応 | T18: 4-5 | V18: 3/1 | AN18: =IF(A18="", "", IF(ROW()>=3, ", ", "")&"'"&A18&"': {megami: '"&B18&"'"&IF(C18<>"",", anotherID: '"&C18&"', replace: '"&D18&"'","")&", name: '"&SUBSTITUTE(E18,"'","\'")&"', nameEn: '"&SUBSTITUTE(K18,"'","\'")&"', nameZh: '"&SUBSTITUTE(G18,"'","\'")&"', nameZhG1: '"&SUBSTITUTE(H18,"'","\'")&"', nameKo: '"&SUBSTITUTE(J18,"'","\'")&"', ruby: '"&F18&"', rubyEn: '"&L18&IF(I18<>"", "', rubyZh: '"&I18, "")&"', baseType: '"&VLOOKUP(M18,マスタ!$A$1:$B$99,2,0)&"'"&IF(N18="○",", extra: true","")&IF(O18<>"",", extraFrom: '"&O18&"'","")&IF(P18<>"",", exchangableTo: '"&P18&"'","")&IF(Q18="○",", poison: true","")&IF(R18<>"", ", type: '"&VLOOKUP(R18,マスタ!$D$1:$E$99,2,0)&"'", "")&IF(S18<>"",", subType: '"&VLOOKUP(S18,マスタ!$D$1:$E$99,2,0)&"'","")&IF(T18<>"",", range: '"&T18&"'","")&IF(V18<>"",", damage: '"&V18&"'","")&IF(X18<>"",", capacity: '"&X18&"'","")&IF(Y18<>"",", cost: '"&Y18&"'","")&", text: '"&SUBSTITUTE(SUBSTITUTE(AB18, CHAR(13), ""),CHAR(10),"\n")&IF(AC18<>"", "', textAdditional: '"&SUBSTITUTE(SUBSTITUTE(AC18, CHAR(13), ""),CHAR(10),"\n"), "")&"', textZh: '"&SUBSTITUTE(SUBSTITUTE(SUBSTITUTE(AD18, CHAR(13), ""),CHAR(10),"\n"),"'","\'")&"', textZhG1: '"&SUBSTITUTE(SUBSTITUTE(SUBSTITUTE(AF18, CHAR(13), ""),CHAR(10),"\n"),"'","\'")&IF(AE18<>"", "', textZhAdditional: '"&SUBSTITUTE(SUBSTITUTE(AE18, CHAR(13), ""),CHAR(10),"\n"), "")&"', textKo: '"&SUBSTITUTE(SUBSTITUTE(SUBSTITUTE(AG18, CHAR(13), ""),CHAR(10),"\n"),"'","\'")&"', textEn: '"&SUBSTITUTE(SUBSTITUTE(SUBSTITUTE(AH18, CHAR(13), ""),CHAR(10),"\n"),"'","\'")&"'"&IF(Z18="○",", sealable: true","")&IF(AA18="○",", removable: true","")&"}") -> , '02-saine-o-n-2': {megami: 'saine', name: '薙斬り', nameEn: 'Cut Down', nameZh: '薙刀斩', nameZhG1: '薙刀斩', nameKo: '후려베기', ruby: 'なぎぎり', rubyEn: '', baseType: 'normal', type: 'attack', subType: 'reaction', range: '4-5', damage: '3/1', text: '', textZh: '', textZhG1: '', textKo: '', textEn: ''} | AO18: =IF($A18<>"", " /** 《"&$E18&"》 */ export const "&SUBSTITUTE(UPPER(IF(MID($A18, 3, 1)="-", RIGHT($A18,LEN($A18)-3), $A18)), "-", "_")&": TCardId = '"&$A18&"';", "") -> /** 《薙斬り》 */ export const SAINE_O_N_2: TCardId = '02-saine-o-n-2'; | AP18: =IF($A18<>"", " | '"&$A18&"'", "") -> | '02-saine-o-n-2'
A19: 02-saine-o-n-3 | B19: saine | E19: 返し刃 | F19: かえしやいば | G19: 回马斩 | H19: 反身斩 | J19: 칼날 반환 | K19: Cut In | M19: 通常札 | R19: 攻撃 | S19: 対応 | T19: 3-5 | V19: 1/1 | AB19: 【攻撃後】このカードを対応で使用したならば、攻撃『適正距離3-5、2/1、対応不可』を行う。 | AD19: 【攻击后】若此牌作为对应使用，则进行一次“攻击距离3-5、伤害2/1、不可被对应”的攻击。 | AF19: 【攻击后】若此牌作为对应使用，则进行一次“攻击距离3-5 伤害2/1 不可被对应”的攻击。 | AG19: 【공격후】이 카드를 대응으로 사용했다면, 공격『적정거리3-5、2/1、대응불가』를 행한다. | AH19: After Attack: If this card was played as a Reaction, you attack with "Range: 3-5, Damage: 2/1, No Reactions". | AN19: =IF(A19="", "", IF(ROW()>=3, ", ", "")&"'"&A19&"': {megami: '"&B19&"'"&IF(C19<>"",", anotherID: '"&C19&"', replace: '"&D19&"'","")&", name: '"&SUBSTITUTE(E19,"'","\'")&"', nameEn: '"&SUBSTITUTE(K19,"'","\'")&"', nameZh: '"&SUBSTITUTE(G19,"'","\'")&"', nameZhG1: '"&SUBSTITUTE(H19,"'","\'")&"', nameKo: '"&SUBSTITUTE(J19,"'","\'")&"', ruby: '"&F19&"', rubyEn: '"&L19&IF(I19<>"", "', rubyZh: '"&I19, "")&"', baseType: '"&VLOOKUP(M19,マスタ!$A$1:$B$99,2,0)&"'"&IF(N19="○",", extra: true","")&IF(O19<>"",", extraFrom: '"&O19&"'","")&IF(P19<>"",", exchangableTo: '"&P19&"'","")&IF(Q19="○",", poison: true","")&IF(R19<>"", ", type: '"&VLOOKUP(R19,マスタ!$D$1:$E$99,2,0)&"'", "")&IF(S19<>"",", subType: '"&VLOOKUP(S19,マスタ!$D$1:$E$99,2,0)&"'","")&IF(T19<>"",", range: '"&T19&"'","")&IF(V19<>"",", damage: '"&V19&"'","")&IF(X19<>"",", capacity: '"&X19&"'","")&IF(Y19<>"",", cost: '"&Y19&"'","")&", text: '"&SUBSTITUTE(SUBSTITUTE(AB19, CHAR(13), ""),CHAR(10),"\n")&IF(AC19<>"", "', textAdditional: '"&SUBSTITUTE(SUBSTITUTE(AC19, CHAR(13), ""),CHAR(10),"\n"), "")&"', textZh: '"&SUBSTITUTE(SUBSTITUTE(SUBSTITUTE(AD19, CHAR(13), ""),CHAR(10),"\n"),"'","\'")&"', textZhG1: '"&SUBSTITUTE(SUBSTITUTE(SUBSTITUTE(AF19, CHAR(13), ""),CHAR(10),"\n"),"'","\'")&IF(AE19<>"", "', textZhAdditional: '"&SUBSTITUTE(SUBSTITUTE(AE19, CHAR(13), ""),CHAR(10),"\n"), "")&"', textKo: '"&SUBSTITUTE(SUBSTITUTE(SUBSTITUTE(AG19, CHAR(13), ""),CHAR(10),"\n"),"'","\'")&"', textEn: '"&SUBSTITUTE(SUBSTITUTE(SUBSTITUTE(AH19, CHAR(13), ""),CHAR(10),"\n"),"'","\'")&"'"&IF(Z19="○",", sealable: true","")&IF(AA19="○",", removable: true","")&"}") -> , '02-saine-o-n-3': {megami: 'saine', name: '返し刃', nameEn: 'Cut In', nameZh: '回马斩', nameZhG1: '反身斩', nameKo: '칼날 반환', ruby: 'かえしやいば', rubyEn: '', baseType: 'normal', type: 'attack', subType: 'reaction', range: '3-5', damage: '1/1', text: '【攻撃後】このカードを対応で使用したならば、攻撃『適正距離3-5、2/1、対応不可』を行う。', textZh: '【攻击后】若此牌作为对应使用，则进行一次“攻击距离3-5、伤害2/1、不可被对应”的攻击。', textZhG1: '【攻击后】若此牌作为对应使用，则进行一次“攻击距离3-5 伤害2/1 不可被对应”的攻击。', textKo: '【공격후】이 카드를 대응으로 사용했다면, 공격『적정거리3-5、2/1、대응불가』를 행한다.', textEn: 'After Attack: If this card was played as a Reaction, you attack with "Range: 3-5, Damage: 2/1, No Reactions".'} | AO19: =IF($A19<>"", " /** 《"&$E19&"》 */ export const "&SUBSTITUTE(UPPER(IF(MID($A19, 3, 1)="-", RIGHT($A19,LEN($A19)-3), $A19)), "-", "_")&": TCardId = '"&$A19&"';", "") -> /** 《返し刃》 */ export const SAINE_O_N_3: TCardId = '02-saine-o-n-3'; | AP19: =IF($A19<>"", " | '"&$A19&"'", "") -> | '02-saine-o-n-3'
A20: 02-saine-A1-n-3 | B20: saine | C20: A1 | D20: 02-saine-o-n-3 | E20: 氷の音 | F20: ひのね | G20: 冰之音 | H20: 冰之音 | J20: 얼음의 소리 | K20: Sound of Ice | M20: 通常札 | R20: 行動 | S20: 対応 | AB20: 相オーラ→ダスト：1 このカードを対応で使用したならば、さらに 相オーラ→ダスト：1 | AD20: 敌装→1→虚 若此牌作为《对应》使用，则：敌装→1→虚 | AF20: 敌装（1）→虚 若此牌作为《对应》使用，则敌装（1）→虚。 | AG20: 상대 오라→더스트：1 이 카드를 대응으로 사용했다면, 추가로 상대 오라→더스트：1 | AH20: Opponent's Aura (1)→ Shadow If this card was played as a Reaction: Opponent's Aura (1)→ Shadow (again) | AN20: =IF(A20="", "", IF(ROW()>=3, ", ", "")&"'"&A20&"': {megami: '"&B20&"'"&IF(C20<>"",", anotherID: '"&C20&"', replace: '"&D20&"'","")&", name: '"&SUBSTITUTE(E20,"'","\'")&"', nameEn: '"&SUBSTITUTE(K20,"'","\'")&"', nameZh: '"&SUBSTITUTE(G20,"'","\'")&"', nameZhG1: '"&SUBSTITUTE(H20,"'","\'")&"', nameKo: '"&SUBSTITUTE(J20,"'","\'")&"', ruby: '"&F20&"', rubyEn: '"&L20&IF(I20<>"", "', rubyZh: '"&I20, "")&"', baseType: '"&VLOOKUP(M20,マスタ!$A$1:$B$99,2,0)&"'"&IF(N20="○",", extra: true","")&IF(O20<>"",", extraFrom: '"&O20&"'","")&IF(P20<>"",", exchangableTo: '"&P20&"'","")&IF(Q20="○",", poison: true","")&IF(R20<>"", ", type: '"&VLOOKUP(R20,マスタ!$D$1:$E$99,2,0)&"'", "")&IF(S20<>"",", subType: '"&VLOOKUP(S20,マスタ!$D$1:$E$99,2,0)&"'","")&IF(T20<>"",", range: '"&T20&"'","")&IF(V20<>"",", damage: '"&V20&"'","")&IF(X20<>"",", capacity: '"&X20&"'","")&IF(Y20<>"",", cost: '"&Y20&"'","")&", text: '"&SUBSTITUTE(SUBSTITUTE(AB20, CHAR(13), ""),CHAR(10),"\n")&IF(AC20<>"", "', textAdditional: '"&SUBSTITUTE(SUBSTITUTE(AC20, CHAR(13), ""),CHAR(10),"\n"), "")&"', textZh: '"&SUBSTITUTE(SUBSTITUTE(SUBSTITUTE(AD20, CHAR(13), ""),CHAR(10),"\n"),"'","\'")&"', textZhG1: '"&SUBSTITUTE(SUBSTITUTE(SUBSTITUTE(AF20, CHAR(13), ""),CHAR(10),"\n"),"'","\'")&IF(AE20<>"", "', textZhAdditional: '"&SUBSTITUTE(SUBSTITUTE(AE20, CHAR(13), ""),CHAR(10),"\n"), "")&"', textKo: '"&SUBSTITUTE(SUBSTITUTE(SUBSTITUTE(AG20, CHAR(13), ""),CHAR(10),"\n"),"'","\'")&"', textEn: '"&SUBSTITUTE(SUBSTITUTE(SUBSTITUTE(AH20, CHAR(13), ""),CHAR(10),"\n"),"'","\'")&"'"&IF(Z20="○",", sealable: true","")&IF(AA20="○",", removable: true","")&"}") -> , '02-saine-A1-n-3': {megami: 'saine', anotherID: 'A1', replace: '02-saine-o-n-3', name: '氷の音', nameEn: 'Sound of Ice', nameZh: '冰之音', nameZhG1: '冰之音', nameKo: '얼음의 소리', ruby: 'ひのね', rubyEn: '', baseType: 'normal', type: 'action', subType: 'reaction', text: '相オーラ→ダスト：1\nこのカードを対応で使用したならば、さらに\n相オーラ→ダスト：1', textZh: '敌装→1→虚\n若此牌作为《对应》使用，则：敌装→1→虚', textZhG1: '敌装（1）→虚\n若此牌作为《对应》使用，则敌装（1）→虚。', textKo: '상대 오라→더스트：1 \n이 카드를 대응으로 사용했다면, 추가로 \n상대 오라→더스트：1', textEn: 'Opponent\'s Aura (1)→ Shadow\nIf this card was played as a Reaction:\nOpponent\'s Aura (1)→ Shadow (again)'} | AO20: =IF($A20<>"", " /** 《"&$E20&"》 */ export const "&SUBSTITUTE(UPPER(IF(MID($A20, 3, 1)="-", RIGHT($A20,LEN($A20)-3), $A20)), "-", "_")&": TCardId = '"&$A20&"';", "") -> /** 《氷の音》 */ export const SAINE_A1_N_3: TCardId = '02-saine-A1-n-3'; | AP20: =IF($A20<>"", " | '"&$A20&"'", "") -> | '02-saine-A1-n-3'
A21: 02-saine-o-n-4 | B21: saine | E21: 見切り | F21: みきり | G21: 识破 | H21: 识破 | J21: 간파 | K21: Outclass | M21: 通常札 | R21: 行動 | AB21: 【常時】八相-あなたのオーラが0ならば、このカードを《対応》を持つかのように相手の《攻撃》に割り込んで使用できる。 間合⇔ダスト：1 | AD21: 【常时】八相～若自装中没有樱花结晶，则此牌可以如《对应》牌一样对应《攻击》使用。 距↔1↔虚 | AF21: 【常时】八相-若自装中没有樱花结晶，则此牌额外具有《对应》副类别。 距（1） ⇔ 虚 | AG21: 【상시】팔상-당신의 오라가 0이라면, 이 카드를 《대응》을 갖는것과 같이 상대의 《공격》 에 끼어들어 사용 가능하다. 간격⇔더스트：1 | AH21: Forced: Idea - You may play this card as if it were a Reaction if you have no Sakura tokens on your Aura. Distance (1)⇔ Shadow | AN21: =IF(A21="", "", IF(ROW()>=3, ", ", "")&"'"&A21&"': {megami: '"&B21&"'"&IF(C21<>"",", anotherID: '"&C21&"', replace: '"&D21&"'","")&", name: '"&SUBSTITUTE(E21,"'","\'")&"', nameEn: '"&SUBSTITUTE(K21,"'","\'")&"', nameZh: '"&SUBSTITUTE(G21,"'","\'")&"', nameZhG1: '"&SUBSTITUTE(H21,"'","\'")&"', nameKo: '"&SUBSTITUTE(J21,"'","\'")&"', ruby: '"&F21&"', rubyEn: '"&L21&IF(I21<>"", "', rubyZh: '"&I21, "")&"', baseType: '"&VLOOKUP(M21,マスタ!$A$1:$B$99,2,0)&"'"&IF(N21="○",", extra: true","")&IF(O21<>"",", extraFrom: '"&O21&"'","")&IF(P21<>"",", exchangableTo: '"&P21&"'","")&IF(Q21="○",", poison: true","")&IF(R21<>"", ", type: '"&VLOOKUP(R21,マスタ!$D$1:$E$99,2,0)&"'", "")&IF(S21<>"",", subType: '"&VLOOKUP(S21,マスタ!$D$1:$E$99,2,0)&"'","")&IF(T21<>"",", range: '"&T21&"'","")&IF(V21<>"",", damage: '"&V21&"'","")&IF(X21<>"",", capacity: '"&X21&"'","")&IF(Y21<>"",", cost: '"&Y21&"'","")&", text: '"&SUBSTITUTE(SUBSTITUTE(AB21, CHAR(13), ""),CHAR(10),"\n")&IF(AC21<>"", "', textAdditional: '"&SUBSTITUTE(SUBSTITUTE(AC21, CHAR(13), ""),CHAR(10),"\n"), "")&"', textZh: '"&SUBSTITUTE(SUBSTITUTE(SUBSTITUTE(AD21, CHAR(13), ""),CHAR(10),"\n"),"'","\'")&"', textZhG1: '"&SUBSTITUTE(SUBSTITUTE(SUBSTITUTE(AF21, CHAR(13), ""),CHAR(10),"\n"),"'","\'")&IF(AE21<>"", "', textZhAdditional: '"&SUBSTITUTE(SUBSTITUTE(AE21, CHAR(13), ""),CHAR(10),"\n"), "")&"', textKo: '"&SUBSTITUTE(SUBSTITUTE(SUBSTITUTE(AG21, CHAR(13), ""),CHAR(10),"\n"),"'","\'")&"', textEn: '"&SUBSTITUTE(SUBSTITUTE(SUBSTITUTE(AH21, CHAR(13), ""),CHAR(10),"\n"),"'","\'")&"'"&IF(Z21="○",", sealable: true","")&IF(AA21="○",", removable: true","")&"}") -> , '02-saine-o-n-4': {megami: 'saine', name: '見切り', nameEn: 'Outclass', nameZh: '识破', nameZhG1: '识破', nameKo: '간파', ruby: 'みきり', rubyEn: '', baseType: 'normal', type: 'action', text: '【常時】八相-あなたのオーラが0ならば、このカードを《対応》を持つかのように相手の《攻撃》に割り込んで使用できる。\n間合⇔ダスト：1', textZh: '【常时】八相～若自装中没有樱花结晶，则此牌可以如《对应》牌一样对应《攻击》使用。\n距↔1↔虚', textZhG1: '【常时】八相-若自装中没有樱花结晶，则此牌额外具有《对应》副类别。\n距（1） ⇔ 虚', textKo: '【상시】팔상-당신의 오라가 0이라면, 이 카드를 《대응》을 갖는것과 같이 상대의 《공격》 에 끼어들어 사용 가능하다. \n간격⇔더스트：1', textEn: 'Forced: Idea - You may play this card as if it were a Reaction if you have no Sakura tokens on your Aura.\n\nDistance (1)⇔ Shadow'} | AO21: =IF($A21<>"", " /** 《"&$E21&"》 */ export const "&SUBSTITUTE(UPPER(IF(MID($A21, 3, 1)="-", RIGHT($A21,LEN($A21)-3), $A21)), "-", "_")&": TCardId = '"&$A21&"';", "") -> /** 《見切り》 */ export const SAINE_O_N_4: TCardId = '02-saine-o-n-4'; | AP21: =IF($A21<>"", " | '"&$A21&"'", "") -> | '02-saine-o-n-4'
A22: 02-saine-o-n-5 | B22: saine | E22: 圏域 | F22: けんいき | G22: 圈域 | H22: 圈域 | J22: 권역 | K22: Space for Master | M22: 通常札 | R22: 付与 | X22: 3 | AB22: 【展開時】ダスト→間合：1 【展開中】達人の間合は2大きくなる。 | AD22: 【展开时】虚→1→距 【展开中】达人距离的值增大2。 | AF22: 【展开时】虚（1）→距 【展开中】达人距离的值增大2。 | AG22: 【전개시】더스트→간격：1 【전개중】달인의 간격은 2 크게 된다. | AH22: Initialize: Shadow (1)→ Distance. Ongoing: Increase the size of the Mastery Zone by 2. | AN22: =IF(A22="", "", IF(ROW()>=3, ", ", "")&"'"&A22&"': {megami: '"&B22&"'"&IF(C22<>"",", anotherID: '"&C22&"', replace: '"&D22&"'","")&", name: '"&SUBSTITUTE(E22,"'","\'")&"', nameEn: '"&SUBSTITUTE(K22,"'","\'")&"', nameZh: '"&SUBSTITUTE(G22,"'","\'")&"', nameZhG1: '"&SUBSTITUTE(H22,"'","\'")&"', nameKo: '"&SUBSTITUTE(J22,"'","\'")&"', ruby: '"&F22&"', rubyEn: '"&L22&IF(I22<>"", "', rubyZh: '"&I22, "")&"', baseType: '"&VLOOKUP(M22,マスタ!$A$1:$B$99,2,0)&"'"&IF(N22="○",", extra: true","")&IF(O22<>"",", extraFrom: '"&O22&"'","")&IF(P22<>"",", exchangableTo: '"&P22&"'","")&IF(Q22="○",", poison: true","")&IF(R22<>"", ", type: '"&VLOOKUP(R22,マスタ!$D$1:$E$99,2,0)&"'", "")&IF(S22<>"",", subType: '"&VLOOKUP(S22,マスタ!$D$1:$E$99,2,0)&"'","")&IF(T22<>"",", range: '"&T22&"'","")&IF(V22<>"",", damage: '"&V22&"'","")&IF(X22<>"",", capacity: '"&X22&"'","")&IF(Y22<>"",", cost: '"&Y22&"'","")&", text: '"&SUBSTITUTE(SUBSTITUTE(AB22, CHAR(13), ""),CHAR(10),"\n")&IF(AC22<>"", "', textAdditional: '"&SUBSTITUTE(SUBSTITUTE(AC22, CHAR(13), ""),CHAR(10),"\n"), "")&"', textZh: '"&SUBSTITUTE(SUBSTITUTE(SUBSTITUTE(AD22, CHAR(13), ""),CHAR(10),"\n"),"'","\'")&"', textZhG1: '"&SUBSTITUTE(SUBSTITUTE(SUBSTITUTE(AF22, CHAR(13), ""),CHAR(10),"\n"),"'","\'")&IF(AE22<>"", "', textZhAdditional: '"&SUBSTITUTE(SUBSTITUTE(AE22, CHAR(13), ""),CHAR(10),"\n"), "")&"', textKo: '"&SUBSTITUTE(SUBSTITUTE(SUBSTITUTE(AG22, CHAR(13), ""),CHAR(10),"\n"),"'","\'")&"', textEn: '"&SUBSTITUTE(SUBSTITUTE(SUBSTITUTE(AH22, CHAR(13), ""),CHAR(10),"\n"),"'","\'")&"'"&IF(Z22="○",", sealable: true","")&IF(AA22="○",", removable: true","")&"}") -> , '02-saine-o-n-5': {megami: 'saine', name: '圏域', nameEn: 'Space for Master', nameZh: '圈域', nameZhG1: '圈域', nameKo: '권역', ruby: 'けんいき', rubyEn: '', baseType: 'normal', type: 'enhance', capacity: '3', text: '【展開時】ダスト→間合：1\n【展開中】達人の間合は2大きくなる。', textZh: '【展开时】虚→1→距 \n【展开中】达人距离的值增大2。', textZhG1: '【展开时】虚（1）→距 \n【展开中】达人距离的值增大2。', textKo: '【전개시】더스트→간격：1 \n【전개중】달인의 간격은 2 크게 된다. ', textEn: 'Initialize: Shadow (1)→ Distance.\n\nOngoing: Increase the size of the Mastery Zone by 2.'} | AO22: =IF($A22<>"", " /** 《"&$E22&"》 */ export const "&SUBSTITUTE(UPPER(IF(MID($A22, 3, 1)="-", RIGHT($A22,LEN($A22)-3), $A22)), "-", "_")&": TCardId = '"&$A22&"';", "") -> /** 《圏域》 */ export const SAINE_O_N_5: TCardId = '02-saine-o-n-5'; | AP22: =IF($A22<>"", " | '"&$A22&"'", "") -> | '02-saine-o-n-5'
